Workbook

Sheet cover
B6: JRC-IDEES-2021 - Integrated Database of the European Energy System
C10: Greece
C15: Transport sector
L28: Prepared by JRC C.6
L30: 45432.784
L31: v2021-1.00
B33: Legal Notice
B35: The information made available is property of the Joint Research Centre of the European Commission.
B36: Neither the European Commission nor any person acting on behalf of the Commission is responsible for the use which might be made of this information.
B38: Use conditions
B39: This work is licensed under
B40: CC BY 4.0

Sheet index
A1: EL | B1: Greece
B3: Click on the link to jump to the sheet
B4: =HYPERLINK("#"&CELL("address",Transport!$B$2),MID(CELL("filename",Transport!$B$2),FIND("]",CELL("filename",Transport!$B$2))+1,256)) -> Transport | D4: Overview: Transport sectors
B6: =HYPERLINK("#"&CELL("address",TrRoad_act!$B$2),MID(CELL("filename",TrRoad_act!$B$2),FIND("]",CELL("filename",TrRoad_act!$B$2))+1,256)) -> TrRoad_act | D6: Road transport - activity related data
B7: =HYPERLINK("#"&CELL("address",TrRoad_ene!$B$2),MID(CELL("filename",TrRoad_ene!$B$2),FIND("]",CELL("filename",TrRoad_ene!$B$2))+1,256)) -> TrRoad_ene | D7: energy consumption
B8: =HYPERLINK("#"&CELL("address",TrRoad_emi!$B$2),MID(CELL("filename",TrRoad_emi!$B$2),FIND("]",CELL("filename",TrRoad_emi!$B$2))+1,256)) -> TrRoad_emi | D8: CO2 emissions
B9: =HYPERLINK("#"&CELL("address",TrRoad_tech!$B$2),MID(CELL("filename",TrRoad_tech!$B$2),FIND("]",CELL("filename",TrRoad_tech!$B$2))+1,256)) -> TrRoad_tech | D9: technology data
B11: =HYPERLINK("#"&CELL("address",TrRail_act!$B$2),MID(CELL("filename",TrRail_act!$B$2),FIND("]",CELL("filename",TrRail_act!$B$2))+1,256)) -> TrRail_act | D11: Rail, metro and tram - activity related data
B12: =HYPERLINK("#"&CELL("address",TrRail_ene!$B$2),MID(CELL("filename",TrRail_ene!$B$2),FIND("]",CELL("filename",TrRail_ene!$B$2))+1,256)) -> TrRail_ene | D12: energy consumption
B13: =HYPERLINK("#"&CELL("address",TrRail_emi!$B$2),MID(CELL("filename",TrRail_emi!$B$2),FIND("]",CELL("filename",TrRail_emi!$B$2))+1,256)) -> TrRail_emi | D13: CO2 emissions
B15: =HYPERLINK("#"&CELL("address",TrAvia_act!$B$2),MID(CELL("filename",TrAvia_act!$B$2),FIND("]",CELL("filename",TrAvia_act!$B$2))+1,256)) -> TrAvia_act | D15: Aviation - activity related data
B16: =HYPERLINK("#"&CELL("address",TrAvia_ene!$B$2),MID(CELL("filename",TrAvia_ene!$B$2),FIND("]",CELL("filename",TrAvia_ene!$B$2))+1,256)) -> TrAvia_ene | D16: energy consumption
B17: =HYPERLINK("#"&CELL("address",TrAvia_emi!$B$2),MID(CELL("filename",TrAvia_emi!$B$2),FIND("]",CELL("filename",TrAvia_emi!$B$2))+1,256)) -> TrAvia_emi | D17: CO2 emissions
B18: =HYPERLINK("#"&CELL("address",TrAvia_png!$B$2),MID(CELL("filename",TrAvia_png!$B$2),FIND("]",CELL("filename",TrAvia_png!$B$2))+1,256)) -> TrAvia_png | D18: passenger transport specific data
B20: =HYPERLINK("#"&CELL("address",TrNavi_act!$B$2),MID(CELL("filename",TrNavi_act!$B$2),FIND("]",CELL("filename",TrNavi_act!$B$2))+1,256)) -> TrNavi_act | D20: Coastal shipping and inland waterways - activity related data
B21: =HYPERLINK("#"&CELL("address",TrNavi_ene!$B$2),MID(CELL("filename",TrNavi_ene!$B$2),FIND("]",CELL("filename",TrNavi_ene!$B$2))+1,256)) -> TrNavi_ene | D21: energy consumption
B22: =HYPERLINK("#"&CELL("address",TrNavi_emi!$B$2),MID(CELL("filename",TrNavi_emi!$B$2),FIND("]",CELL("filename",TrNavi_emi!$B$2))+1,256)) -> TrNavi_emi | D22: CO2 emissions
B24: =HYPERLINK("#"&CELL("address",MBunk_act!$B$2),MID(CELL("filename",MBunk_act!$B$2),FIND("]",CELL("filename",MBunk_act!$B$2))+1,256)) -> MBunk_act | D24: International maritime bunkers - activity related data
B25: =HYPERLINK("#"&CELL("address",MBunk_ene!$B$2),MID(CELL("filename",MBunk_ene!$B$2),FIND("]",CELL("filename",MBunk_ene!$B$2))+1,256)) -> MBunk_ene | D25: energy consumption
B26: =HYPERLINK("#"&CELL("address",MBunk_emi!$B$2),MID(CELL("filename",MBunk_emi!$B$2),FIND("]",CELL("filename",MBunk_emi!$B$2))+1,256)) -> MBunk_emi | D26: CO2 emissions

Sheet Transport
A1: Transport overview - EL - Greece | B1: 2000 | C1: 2001 | D1: 2002 | E1: 2003 | F1: 2004 | G1: 2005 | H1: 2006 | I1: 2007 | J1: 2008 | K1: 2009 | L1: 2010 | M1: 2011 | N1: 2012 | O1: 2013 | P1: 2014 | Q1: 2015 | R1: 2016 | S1: 2017 | T1: 2018 | U1: 2019 | V1: 2020 | W1: 2021 | DA1: Code
A3: Transport activity
A4: Passenger transport (mio pkm) | B4: =B5+B9+B13 -> 125669.83 | C4: =C5+C9+C13 -> 128774.48 | D4: =D5+D9+D13 -> 133198.98 | E4: =E5+E9+E13 -> 137689.2 | F4: =F5+F9+F13 -> 143894.79 | G4: =G5+G9+G13 -> 150194.54 | H4: =H5+H9+H13 -> 156532.57 | I4: =I5+I9+I13 -> 162778.34 | ... W4: =W5+W9+W13 -> 151196.97 | DA4: Activity.Mpkm.EL.Tr
A5: Road transport | B5: =B6+B7+B8 -> 89081.034 | C5: =C6+C7+C8 -> 94433.617 | D5: =D6+D7+D8 -> 99135.28 | E5: =E6+E7+E8 -> 103397.51 | F5: =F6+F7+F8 -> 107255.69 | G5: =G6+G7+G8 -> 112483.57 | H5: =H6+H7+H8 -> 117284.74 | I5: =I6+I7+I8 -> 122620.7 | ... W5: =W6+W7+W8 -> 119011.03 | DA5: Activity.Mpkm.EL.Tr.Road.Passenger
A6: =TrRoad_act!$A$5 -> Powered two-wheelers | B6: =TrRoad_act!B$5 -> 4381.0337 | C6: =TrRoad_act!C$5 -> 4633.6165 | D6: =TrRoad_act!D$5 -> 5135.2801 | E6: =TrRoad_act!E$5 -> 5447.5095 | F6: =TrRoad_act!F$5 -> 5655.6905 | G6: =TrRoad_act!G$5 -> 5783.5689 | H6: =TrRoad_act!H$5 -> 5484.7376 | I6: =TrRoad_act!I$5 -> 5620.6996 | ... W6: =TrRoad_act!W$5 -> 7595.5854 | DA6: Activity.Mpkm.EL.Tr.Road.Passenger.P2W
A7: =TrRoad_act!$A$6 -> Passenger cars | B7: =TrRoad_act!B$6 -> 63000 | C7: =TrRoad_act!C$6 -> 68000 | D7: =TrRoad_act!D$6 -> 72000 | E7: =TrRoad_act!E$6 -> 76000 | F7: =TrRoad_act!F$6 -> 80000 | G7: =TrRoad_act!G$6 -> 85000 | H7: =TrRoad_act!H$6 -> 90000 | I7: =TrRoad_act!I$6 -> 95000 | ... W7: =TrRoad_act!W$6 -> 97646.142 | DA7: Activity.Mpkm.EL.Tr.Road.Passenger.Car
A8: =TrRoad_act!$A$13 -> Motor coaches, buses and trolley buses | B8: =TrRoad_act!B$13 -> 21700 | C8: =TrRoad_act!C$13 -> 21800 | D8: =TrRoad_act!D$13 -> 22000 | E8: =TrRoad_act!E$13 -> 21950 | F8: =TrRoad_act!F$13 -> 21600 | G8: =TrRoad_act!G$13 -> 21700 | H8: =TrRoad_act!H$13 -> 21800 | I8: =TrRoad_act!I$13 -> 22000 | ... W8: =TrRoad_act!W$13 -> 13769.303 | DA8: Activity.Mpkm.EL.Tr.Road.Passenger.Bus
A9: Rail, metro and tram | B9: =B10+B11+B12 -> 3076 | C9: =C10+C11+C12 -> 3077 | D9: =D10+D11+D12 -> 3186 | E9: =E10+E11+E12 -> 2974 | F9: =F10+F11+F12 -> 3168 | G9: =G10+G11+G12 -> 3354 | H9: =H10+H11+H12 -> 3361 | I9: =I10+I11+I12 -> 3530 | ... W9: =W10+W11+W12 -> 1778.78 | DA9: Activity.Mpkm.EL.Tr.Rail.Passenger
A10: =TrRail_act!$A$5 -> Metro and tram, urban light rail | B10: =TrRail_act!B$5 -> 1190 | C10: =TrRail_act!C$5 -> 1330 | D10: =TrRail_act!D$5 -> 1350 | E10: =TrRail_act!E$5 -> 1400 | F10: =TrRail_act!F$5 -> 1500 | G10: =TrRail_act!G$5 -> 1500 | H10: =TrRail_act!H$5 -> 1550 | I10: =TrRail_act!I$5 -> 1600 | ... W10: =TrRail_act!W$5 -> 1125.78 | DA10: Activity.Mpkm.EL.Tr.Rail.Passenger.MTU
A11: =TrRail_act!$A$6 -> Conventional passenger trains | B11: =TrRail_act!B$6 -> 1886 | C11: =TrRail_act!C$6 -> 1747 | D11: =TrRail_act!D$6 -> 1836 | E11: =TrRail_act!E$6 -> 1574 | F11: =TrRail_act!F$6 -> 1668 | G11: =TrRail_act!G$6 -> 1854 | H11: =TrRail_act!H$6 -> 1811 | I11: =TrRail_act!I$6 -> 1930 | ... W11: =TrRail_act!W$6 -> 653 | DA11: Activity.Mpkm.EL.Tr.Rail.Passenger.CPT
A12: =TrRail_act!$A$9 -> High speed passenger trains | B12: =TrRail_act!B$9 -> 0 | C12: =TrRail_act!C$9 -> 0 | D12: =TrRail_act!D$9 -> 0 | E12: =TrRail_act!E$9 -> 0 | F12: =TrRail_act!F$9 -> 0 | G12: =TrRail_act!G$9 -> 0 | H12: =TrRail_act!H$9 -> 0 | I12: =TrRail_act!I$9 -> 0 | ... W12: =TrRail_act!W$9 -> 0 | DA12: Activity.Mpkm.EL.Tr.Rail.Passenger.HST
A13: Aviation | B13: =B14+B15+B16 -> 33512.801 | C13: =C14+C15+C16 -> 31263.863 | D13: =D14+D15+D16 -> 30877.703 | E13: =E14+E15+E16 -> 31317.687 | F13: =F14+F15+F16 -> 33471.097 | G13: =G14+G15+G16 -> 34356.967 | H13: =H14+H15+H16 -> 35886.831 | I13: =I14+I15+I16 -> 36627.638 | ... W13: =W14+W15+W16 -> 30407.164 | DA13: Activity.Mpkm.EL.Tr.Avia.Passenger
A14: Domestic | B14: =TrAvia_act!B$5 -> 2488.4994 | C14: =TrAvia_act!C$5 -> 2371.6997 | D14: =TrAvia_act!D$5 -> 2186.3135 | E14: =TrAvia_act!E$5 -> 2103.3316 | F14: =TrAvia_act!F$5 -> 2447.2823 | G14: =TrAvia_act!G$5 -> 2500.1987 | H14: =TrAvia_act!H$5 -> 2628.2753 | I14: =TrAvia_act!I$5 -> 2814.9848 | ... W14: =TrAvia_act!W$5 -> 2002.2976 | DA14: Activity.Mpkm.EL.Tr.Avia.Passenger.Domestic
A15: International - Intra-EEAwUK | B15: =TrAvia_act!B$6 -> 27566.526 | C15: =TrAvia_act!C$6 -> 25651.465 | D15: =TrAvia_act!D$6 -> 25417.928 | E15: =TrAvia_act!E$6 -> 25798.425 | F15: =TrAvia_act!F$6 -> 27120.571 | G15: =TrAvia_act!G$6 -> 27604.906 | H15: =TrAvia_act!H$6 -> 28073.165 | I15: =TrAvia_act!I$6 -> 27774.001 | ... W15: =TrAvia_act!W$6 -> 22613.231 | DA15: Activity.Mpkm.EL.Tr.Avia.Passenger.IntraEEAwUK
A16: International - Extra-EEAwUK | B16: =TrAvia_act!B$7 -> 3457.7755 | C16: =TrAvia_act!C$7 -> 3240.6983 | D16: =TrAvia_act!D$7 -> 3273.4617 | E16: =TrAvia_act!E$7 -> 3415.93 | F16: =TrAvia_act!F$7 -> 3903.2443 | G16: =TrAvia_act!G$7 -> 4251.8622 | H16: =TrAvia_act!H$7 -> 5185.391 | I16: =TrAvia_act!I$7 -> 6038.6524 | ... W16: =TrAvia_act!W$7 -> 5791.6356 | DA16: Activity.Mpkm.EL.Tr.Avia.Passenger.ExtraEEAwUK
A17: Freight transport (mio tkm) | B17: =B18+B21+B22+B26 -> 37659.935 | C17: =C18+C21+C22+C26 -> 31693.886 | D17: =D18+D21+D22+D26 -> 33616.059 | E17: =E18+E21+E22+E26 -> 26266.235 | F17: =F18+F21+F22+F26 -> 42969.151 | G17: =G18+G21+G22+G26 -> 30468.149 | H17: =H18+H21+H22+H26 -> 37867.777 | I17: =I18+I21+I22+I26 -> 33518.432 | ... W17: =W18+W21+W22+W26 -> 27227.384 | DA17: Activity.Mtkm.EL.Tr
A18: Road transport | B18: =B19+B20 -> 25980.033 | C18: =C19+C20 -> 26665.249 | D18: =D19+D20 -> 27360.15 | E18: =E19+E20 -> 18787.848 | F18: =F19+F20 -> 35600.57 | G18: =G19+G20 -> 23589.425 | H18: =H19+H20 -> 30749.178 | I18: =I19+I20 -> 26102.111 | ... W18: =W19+W20 -> 21706.016 | DA18: Activity.Mtkm.EL.Tr.Road.Freight
A19: =TrRoad_act!$A$20 -> Light commercial vehicles | B19: =TrRoad_act!B$20 -> 1312.1663 | C19: =TrRoad_act!C$20 -> 1378.8971 | D19: =TrRoad_act!D$20 -> 1468.7122 | E19: =TrRoad_act!E$20 -> 1591.2658 | F19: =TrRoad_act!F$20 -> 1624.682 | G19: =TrRoad_act!G$20 -> 1672.8259 | H19: =TrRoad_act!H$20 -> 1778.2383 | I19: =TrRoad_act!I$20 -> 1958.9205 | ... W19: =TrRoad_act!W$20 -> 2009.0158 | DA19: Activity.Mtkm.EL.Tr.Road.Freight.LCV
A20: =TrRoad_act!$A$26 -> Heavy goods vehicles | B20: =TrRoad_act!B$26 -> 24667.867 | C20: =TrRoad_act!C$26 -> 25286.352 | D20: =TrRoad_act!D$26 -> 25891.438 | E20: =TrRoad_act!E$26 -> 17196.582 | F20: =TrRoad_act!F$26 -> 33975.888 | G20: =TrRoad_act!G$26 -> 21916.599 | H20: =TrRoad_act!H$26 -> 28970.94 | I20: =TrRoad_act!I$26 -> 24143.19 | ... W20: =TrRoad_act!W$26 -> 19697 | DA20: Activity.Mtkm.EL.Tr.Road.Freight.HGV
A21: Rail transport | B21: =TrRail_act!B$10 -> 427 | C21: =TrRail_act!C$10 -> 380 | D21: =TrRail_act!D$10 -> 327 | E21: =TrRail_act!E$10 -> 456 | F21: =TrRail_act!F$10 -> 592 | G21: =TrRail_act!G$10 -> 613 | H21: =TrRail_act!H$10 -> 662 | I21: =TrRail_act!I$10 -> 835 | ... W21: =TrRail_act!W$10 -> 578 | DA21: Activity.Mtkm.EL.Tr.Rail.Freight
A22: Aviation | B22: =B23+B24+B25 -> 147.93978 | C22: =C23+C24+C25 -> 172.35289 | D22: =D23+D24+D25 -> 160.85504 | E22: =E23+E24+E25 -> 142.20694 | F22: =F23+F24+F25 -> 99.751011 | G22: =G23+G24+G25 -> 94.860693 | H22: =H23+H24+H25 -> 97.016062 | I22: =I23+I24+I25 -> 90.617282 | ... W22: =W23+W24+W25 -> 105.01781 | DA22: Activity.Mtkm.EL.Tr.Avia.Freight
A23: Domestic | B23: =TrAvia_act!B$9 -> 14.195742 | C23: =TrAvia_act!C$9 -> 16.572043 | D23: =TrAvia_act!D$9 -> 16.242013 | E23: =TrAvia_act!E$9 -> 14.258366 | F23: =TrAvia_act!F$9 -> 8.0384951 | G23: =TrAvia_act!G$9 -> 7.4111826 | H23: =TrAvia_act!H$9 -> 7.3494469 | I23: =TrAvia_act!I$9 -> 6.0370837 | ... W23: =TrAvia_act!W$9 -> 1.725079 | DA23: Activity.Mtkm.EL.Tr.Avia.Freight.Domestic
A24: International - Intra-EEAwUK | B24: =TrAvia_act!B$10 -> 98.971288 | C24: =TrAvia_act!C$10 -> 120.46911 | D24: =TrAvia_act!D$10 -> 110.79579 | E24: =TrAvia_act!E$10 -> 94.238846 | F24: =TrAvia_act!F$10 -> 67.145661 | G24: =TrAvia_act!G$10 -> 64.783534 | H24: =TrAvia_act!H$10 -> 64.873289 | I24: =TrAvia_act!I$10 -> 59.969212 | ... W24: =TrAvia_act!W$10 -> 46.671744 | DA24: Activity.Mtkm.EL.Tr.Avia.Freight.IntraEEAwUK
A25: International - Extra-EEAwUK | B25: =TrAvia_act!B$11 -> 34.772746 | C25: =TrAvia_act!C$11 -> 35.311738 | D25: =TrAvia_act!D$11 -> 33.817236 | E25: =TrAvia_act!E$11 -> 33.70973 | F25: =TrAvia_act!F$11 -> 24.566855 | G25: =TrAvia_act!G$11 -> 22.665977 | H25: =TrAvia_act!H$11 -> 24.793327 | I25: =TrAvia_act!I$11 -> 24.610987 | ... W25: =TrAvia_act!W$11 -> 56.620988 | DA25: Activity.Mtkm.EL.Tr.Avia.Freight.ExtraEEAwUK
A26: Domestic navigation | B26: =B27+B28 -> 11104.962 | C26: =C27+C28 -> 4476.284 | D26: =D27+D28 -> 5768.054 | E26: =E27+E28 -> 6880.18 | F26: =F27+F28 -> 6676.83 | G26: =G27+G28 -> 6170.864 | H26: =H27+H28 -> 6359.583 | I26: =I27+I28 -> 6490.704 | ... W26: =W27+W28 -> 4838.35 | DA26: Activity.Mtkm.EL.Tr.DNavi.Freight
A27: =TrNavi_act!$A$4 -> Domestic coastal shipping | B27: =TrNavi_act!B4 -> 11104.962 | C27: =TrNavi_act!C4 -> 4476.284 | D27: =TrNavi_act!D4 -> 5768.054 | E27: =TrNavi_act!E4 -> 6880.18 | F27: =TrNavi_act!F4 -> 6676.83 | G27: =TrNavi_act!G4 -> 6170.864 | H27: =TrNavi_act!H4 -> 6359.583 | I27: =TrNavi_act!I4 -> 6490.704 | ... W27: =TrNavi_act!W4 -> 4838.35 | DA27: Activity.Mtkm.EL.Tr.DNavi.Freight.DCS
A28: =TrNavi_act!$A$5 -> Inland waterways | B28: =TrNavi_act!B5 -> 0 | C28: =TrNavi_act!C5 -> 0 | D28: =TrNavi_act!D5 -> 0 | E28: =TrNavi_act!E5 -> 0 | F28: =TrNavi_act!F5 -> 0 | G28: =TrNavi_act!G5 -> 0 | H28: =TrNavi_act!H5 -> 0 | I28: =TrNavi_act!I5 -> 0 | ... W28: =TrNavi_act!W5 -> 0 | DA28: Activity.Mtkm.EL.Tr.DNavi.Freight.IWW
A29: International maritime bunkers (mio tkm) | B29: =B30+B31 -> 76319.079 | C29: =C30+C31 -> 107675.05 | D29: =D30+D31 -> 113285.97 | E29: =E30+E31 -> 128164.98 | F29: =F30+F31 -> 129305.38 | G29: =G30+G31 -> 128433.74 | H29: =H30+H31 -> 127172.2 | I29: =I30+I31 -> 132434.09 | ... W29: =W30+W31 -> 265285.89 | DA29: Activity.Mtkm.EL.MBunk.Freight
A30: Intra-EEA | B30: =MBunk_act!B$4 -> 42664.712 | C30: =MBunk_act!C$4 -> 34945.892 | D30: =MBunk_act!D$4 -> 32645.76 | E30: =MBunk_act!E$4 -> 39228.228 | F30: =MBunk_act!F$4 -> 35441.028 | G30: =MBunk_act!G$4 -> 32943.818 | H30: =MBunk_act!H$4 -> 29876.123 | I30: =MBunk_act!I$4 -> 36134.746 | ... W30: =MBunk_act!W$4 -> 46498.825 | DA30: Activity.Mtkm.EL.MBunk.Freight.IntraEEA
A31: Extra-EEA | B31: =MBunk_act!B$5 -> 33654.367 | C31: =MBunk_act!C$5 -> 72729.159 | D31: =MBunk_act!D$5 -> 80640.214 | E31: =MBunk_act!E$5 -> 88936.752 | F31: =MBunk_act!F$5 -> 93864.354 | G31: =MBunk_act!G$5 -> 95489.919 | H31: =MBunk_act!H$5 -> 97296.073 | I31: =MBunk_act!I$5 -> 96299.342 | ... W31: =MBunk_act!W$5 -> 218787.06 | DA31: Activity.Mtkm.EL.MBunk.Freight.ExtraEEA
A33: Energy consumption (ktoe)
A34: Passenger transport | B34: =B35+B39+B43 -> 4860.7399 | C34: =C35+C39+C43 -> 4835.4046 | D34: =D35+D39+D43 -> 4959.2269 | E34: =E35+E39+E43 -> 5306.5051 | F34: =F35+F39+F43 -> 5291.8288 | G34: =G35+G39+G43 -> 5515.7739 | H34: =H35+H39+H43 -> 5713.8806 | I34: =I35+I39+I43 -> 5938.6246 | ... W34: =W35+W39+W43 -> 4029.1227
A35: =$A$5 -> Road transport | B35: =B36+B37+B38 -> 3489.3262 | C35: =C36+C37+C38 -> 3602.8229 | D35: =D36+D37+D38 -> 3763.5729 | E35: =E36+E37+E38 -> 4098.6118 | F35: =F36+F37+F38 -> 4027.1831 | G35: =G36+G37+G38 -> 4281.6241 | H35: =H36+H37+H38 -> 4363.7098 | I35: =I36+I37+I38 -> 4571.0325 | ... W35: =W36+W37+W38 -> 3171.83 | DA35: FEC.ktoe.EL.Tr.Road.Passenger
A36: =$A$6 -> Powered two-wheelers | B36: =TrRoad_ene!B$19 -> 169.12614 | C36: =TrRoad_ene!C$19 -> 183.28186 | D36: =TrRoad_ene!D$19 -> 201.62988 | E36: =TrRoad_ene!E$19 -> 211.32154 | F36: =TrRoad_ene!F$19 -> 212.79747 | G36: =TrRoad_ene!G$19 -> 219.1618 | H36: =TrRoad_ene!H$19 -> 200.05889 | I36: =TrRoad_ene!I$19 -> 200.25704 | ... W36: =TrRoad_ene!W$19 -> 229.96149 | DA36: FEC.ktoe.EL.Tr.Road.Passenger.P2W
A37: =$A$7 -> Passenger cars | B37: =TrRoad_ene!B$21 -> 2753.7785 | C37: =TrRoad_ene!C$21 -> 2871.0489 | D37: =TrRoad_ene!D$21 -> 3015.7548 | E37: =TrRoad_ene!E$21 -> 3184.1534 | F37: =TrRoad_ene!F$21 -> 3282.838 | G37: =TrRoad_ene!G$21 -> 3461.8739 | H37: =TrRoad_ene!H$21 -> 3575.7978 | I37: =TrRoad_ene!I$21 -> 3765.0147 | ... W37: =TrRoad_ene!W$21 -> 2376.8339 | DA37: FEC.ktoe.EL.Tr.Road.Passenger.Car
A38: =$A$8 -> Motor coaches, buses and trolley buses | B38: =TrRoad_ene!B$33 -> 566.42158 | C38: =TrRoad_ene!C$33 -> 548.49223 | D38: =TrRoad_ene!D$33 -> 546.18819 | E38: =TrRoad_ene!E$33 -> 703.13682 | F38: =TrRoad_ene!F$33 -> 531.54762 | G38: =TrRoad_ene!G$33 -> 600.58847 | H38: =TrRoad_ene!H$33 -> 587.8531 | I38: =TrRoad_ene!I$33 -> 605.76085 | ... W38: =TrRoad_ene!W$33 -> 565.03468 | DA38: FEC.ktoe.EL.Tr.Road.Passenger.Bus
A39: =$A$9 -> Rail, metro and tram | B39: =B40+B41+B42 -> 46.185354 | C39: =C40+C41+C42 -> 47.378892 | D39: =D40+D41+D42 -> 47.158537 | E39: =E40+E41+E42 -> 46.517174 | F39: =F40+F41+F42 -> 45.753407 | G39: =G40+G41+G42 -> 42.320721 | H39: =H40+H41+H42 -> 44.980934 | I39: =I40+I41+I42 -> 42.567322 | ... W39: =W40+W41+W42 -> 19.392934 | DA39: FEC.ktoe.EL.Tr.Rail.Passenger
A40: =$A$10 -> Metro and tram, urban light rail | B40: =TrRail_ene!B$12 -> 6.3868449 | C40: =TrRail_ene!C$12 -> 7.0782011 | D40: =TrRail_ene!D$12 -> 7.1672254 | E40: =TrRail_ene!E$12 -> 7.5109964 | F40: =TrRail_ene!F$12 -> 7.9296353 | G40: =TrRail_ene!G$12 -> 3.9245083 | H40: =TrRail_ene!H$12 -> 6.5000834 | I40: =TrRail_ene!I$12 -> 7.7806674 | ... W40: =TrRail_ene!W$12 -> 6.3416967 | DA40: FEC.ktoe.EL.Tr.Rail.Passenger.MTU
A41: =$A$11 -> Conventional passenger trains | B41: =TrRail_ene!B$13 -> 39.798509 | C41: =TrRail_ene!C$13 -> 40.300691 | D41: =TrRail_ene!D$13 -> 39.991312 | E41: =TrRail_ene!E$13 -> 39.006177 | F41: =TrRail_ene!F$13 -> 37.823772 | G41: =TrRail_ene!G$13 -> 38.396213 | H41: =TrRail_ene!H$13 -> 38.480851 | I41: =TrRail_ene!I$13 -> 34.786655 | ... W41: =TrRail_ene!W$13 -> 13.051237 | DA41: FEC.ktoe.EL.Tr.Rail.Passenger.CPT
A42: =$A$12 -> High speed passenger trains | B42: =TrRail_ene!B$16 -> 0 | C42: =TrRail_ene!C$16 -> 0 | D42: =TrRail_ene!D$16 -> 0 | E42: =TrRail_ene!E$16 -> 0 | F42: =TrRail_ene!F$16 -> 0 | G42: =TrRail_ene!G$16 -> 0 | H42: =TrRail_ene!H$16 -> 0 | I42: =TrRail_ene!I$16 -> 0 | ... W42: =TrRail_ene!W$16 -> 0 | DA42: FEC.ktoe.EL.Tr.Rail.Passenger.HST
...

Sheet TrRoad_act
A1: Road transport - EL - Greece | B1: 2000 | C1: 2001 | D1: 2002 | E1: 2003 | F1: 2004 | G1: 2005 | H1: 2006 | I1: 2007 | J1: 2008 | K1: 2009 | L1: 2010 | M1: 2011 | N1: 2012 | O1: 2013 | P1: 2014 | Q1: 2015 | R1: 2016 | S1: 2017 | T1: 2018 | U1: 2019 | V1: 2020 | W1: 2021 | DA1: Code
A3: Transport activity
A4: Passenger transport (mio pkm) | B4: =B5+B6+B13 -> 89081.034 | C4: =C5+C6+C13 -> 94433.617 | D4: =D5+D6+D13 -> 99135.28 | E4: =E5+E6+E13 -> 103397.51 | F4: =F5+F6+F13 -> 107255.69 | G4: =G5+G6+G13 -> 112483.57 | H4: =H5+H6+H13 -> 117284.74 | I4: =I5+I6+I13 -> 122620.7 | ... W4: =W5+W6+W13 -> 119011.03 | DA4: Activity.Mpkm.EL.Tr.Road.Passenger
A5: Powered two-wheelers | B5: =IF(B32=0,0,B32*B142) -> 4381.0337 | C5: =IF(C32=0,0,C32*C142) -> 4633.6165 | D5: =IF(D32=0,0,D32*D142) -> 5135.2801 | E5: =IF(E32=0,0,E32*E142) -> 5447.5095 | F5: =IF(F32=0,0,F32*F142) -> 5655.6905 | G5: =IF(G32=0,0,G32*G142) -> 5783.5689 | H5: =IF(H32=0,0,H32*H142) -> 5484.7376 | I5: =IF(I32=0,0,I32*I142) -> 5620.6996 | ... W5: =IF(W32=0,0,W32*W142) -> 7595.5854 | DA5: Activity.Mpkm.EL.Tr.Road.Passenger.P2W
A6: Passenger cars | B6: =SUM(B7:B12) -> 63000 | C6: =SUM(C7:C12) -> 68000 | D6: =SUM(D7:D12) -> 72000 | E6: =SUM(E7:E12) -> 76000 | F6: =SUM(F7:F12) -> 80000 | G6: =SUM(G7:G12) -> 85000 | H6: =SUM(H7:H12) -> 90000 | I6: =SUM(I7:I12) -> 95000 | ... W6: =SUM(W7:W12) -> 97646.142 | DA6: Activity.Mpkm.EL.Tr.Road.Passenger.Car
A7: Gasoline engine | B7: =IF(B34=0,0,B34*B144) -> 58222.639 | C7: =IF(C34=0,0,C34*C144) -> 63384.689 | D7: =IF(D34=0,0,D34*D144) -> 67409.486 | E7: =IF(E34=0,0,E34*E144) -> 71199.355 | F7: =IF(F34=0,0,F34*F144) -> 75688.653 | G7: =IF(G34=0,0,G34*G144) -> 80591.297 | H7: =IF(H34=0,0,H34*H144) -> 85105.089 | I7: =IF(I34=0,0,I34*I144) -> 89816.713 | ... W7: =IF(W34=0,0,W34*W144) -> 70315.11 | DA7: Activity.Mpkm.EL.Tr.Road.Passenger.Car.ICE.Gasoline
A8: Diesel oil engine | B8: =IF(B35=0,0,B35*B145) -> 4427.2261 | C8: =IF(C35=0,0,C35*C145) -> 4257.2566 | D8: =IF(D35=0,0,D35*D145) -> 4251.5994 | E8: =IF(E35=0,0,E35*E145) -> 4496.4378 | F8: =IF(F35=0,0,F35*F145) -> 4033.3308 | G8: =IF(G35=0,0,G35*G145) -> 4130.0931 | H8: =IF(H35=0,0,H35*H145) -> 4612.3063 | I8: =IF(I35=0,0,I35*I145) -> 4869.0237 | ... W8: =IF(W35=0,0,W35*W145) -> 20912.048 | DA8: Activity.Mpkm.EL.Tr.Road.Passenger.Car.ICE.Diesel
A9: LPG engine | B9: =IF(B36=0,0,B36*B146) -> 350.13451 | C9: =IF(C36=0,0,C36*C146) -> 338.53412 | D9: =IF(D36=0,0,D36*D146) -> 307.66601 | E9: =IF(E36=0,0,E36*E146) -> 270.17973 | F9: =IF(F36=0,0,F36*F146) -> 244.59316 | G9: =IF(G36=0,0,G36*G146) -> 241.89002 | H9: =IF(H36=0,0,H36*H146) -> 244.16002 | I9: =IF(I36=0,0,I36*I146) -> 270.78338 | ... W9: =IF(W36=0,0,W36*W146) -> 6039.3548 | DA9: Activity.Mpkm.EL.Tr.Road.Passenger.Car.ICE.LPG
A10: Natural gas engine | B10: =IF(B37=0,0,B37*B147) -> 0 | C10: =IF(C37=0,0,C37*C147) -> 19.520568 | D10: =IF(D37=0,0,D37*D147) -> 31.248291 | E10: =IF(E37=0,0,E37*E147) -> 34.027908 | F10: =IF(F37=0,0,F37*F147) -> 33.423417 | G10: =IF(G37=0,0,G37*G147) -> 36.719831 | H10: =IF(H37=0,0,H37*H147) -> 38.444493 | I10: =IF(I37=0,0,I37*I147) -> 43.48008 | ... W10: =IF(W37=0,0,W37*W147) -> 160.2128 | DA10: Activity.Mpkm.EL.Tr.Road.Passenger.Car.ICE.NGas
A11: Plug-in hybrid electric | B11: =IF(B38=0,0,B38*B148) -> 0 | C11: =IF(C38=0,0,C38*C148) -> 0 | D11: =IF(D38=0,0,D38*D148) -> 0 | E11: =IF(E38=0,0,E38*E148) -> 0 | F11: =IF(F38=0,0,F38*F148) -> 0 | G11: =IF(G38=0,0,G38*G148) -> 0 | H11: =IF(H38=0,0,H38*H148) -> 0 | I11: =IF(I38=0,0,I38*I148) -> 0 | ... W11: =IF(W38=0,0,W38*W148) -> 135.69449 | DA11: Activity.Mpkm.EL.Tr.Road.Passenger.Car.PHEV
A12: Battery electric vehicles | B12: =IF(B39=0,0,B39*B149) -> 0 | C12: =IF(C39=0,0,C39*C149) -> 0 | D12: =IF(D39=0,0,D39*D149) -> 0 | E12: =IF(E39=0,0,E39*E149) -> 0 | F12: =IF(F39=0,0,F39*F149) -> 0 | G12: =IF(G39=0,0,G39*G149) -> 0 | H12: =IF(H39=0,0,H39*H149) -> 0 | I12: =IF(I39=0,0,I39*I149) -> 0 | ... W12: =IF(W39=0,0,W39*W149) -> 83.722145 | DA12: Activity.Mpkm.EL.Tr.Road.Passenger.Car.BEV
A13: Motor coaches, buses and trolley buses | B13: =SUM(B14:B18) -> 21700 | C13: =SUM(C14:C18) -> 21800 | D13: =SUM(D14:D18) -> 22000 | E13: =SUM(E14:E18) -> 21950 | F13: =SUM(F14:F18) -> 21600 | G13: =SUM(G14:G18) -> 21700 | H13: =SUM(H14:H18) -> 21800 | I13: =SUM(I14:I18) -> 22000 | ... W13: =SUM(W14:W18) -> 13769.303 | DA13: Activity.Mpkm.EL.Tr.Road.Passenger.Bus
A14: Gasoline engine | B14: =IF(B41=0,0,B41*B151) -> 0 | C14: =IF(C41=0,0,C41*C151) -> 0 | D14: =IF(D41=0,0,D41*D151) -> 0 | E14: =IF(E41=0,0,E41*E151) -> 0 | F14: =IF(F41=0,0,F41*F151) -> 0 | G14: =IF(G41=0,0,G41*G151) -> 0 | H14: =IF(H41=0,0,H41*H151) -> 0 | I14: =IF(I41=0,0,I41*I151) -> 0 | ... W14: =IF(W41=0,0,W41*W151) -> 0 | DA14: Activity.Mpkm.EL.Tr.Road.Passenger.Bus.ICE.Gasoline
A15: Diesel oil engine | B15: =IF(B42=0,0,B42*B152) -> 21700 | C15: =IF(C42=0,0,C42*C152) -> 21471.24 | D15: =IF(D42=0,0,D42*D152) -> 21494.764 | E15: =IF(E42=0,0,E42*E152) -> 21397.849 | F15: =IF(F42=0,0,F42*F152) -> 21054.883 | G15: =IF(G42=0,0,G42*G152) -> 21119.746 | H15: =IF(H42=0,0,H42*H152) -> 21199.287 | I15: =IF(I42=0,0,I42*I152) -> 21296.365 | ... W15: =IF(W42=0,0,W42*W152) -> 13115.552 | DA15: Activity.Mpkm.EL.Tr.Road.Passenger.Bus.ICE.Diesel
A16: LPG engine | B16: =IF(B43=0,0,B43*B153) -> 0 | C16: =IF(C43=0,0,C43*C153) -> 0 | D16: =IF(D43=0,0,D43*D153) -> 0 | E16: =IF(E43=0,0,E43*E153) -> 0 | F16: =IF(F43=0,0,F43*F153) -> 0 | G16: =IF(G43=0,0,G43*G153) -> 0 | H16: =IF(H43=0,0,H43*H153) -> 0 | I16: =IF(I43=0,0,I43*I153) -> 0 | ... W16: =IF(W43=0,0,W43*W153) -> 0 | DA16: Activity.Mpkm.EL.Tr.Road.Passenger.Bus.ICE.LPG
A17: Natural gas engine | B17: =IF(B44=0,0,B44*B154) -> 0 | C17: =IF(C44=0,0,C44*C154) -> 328.76025 | D17: =IF(D44=0,0,D44*D154) -> 505.23606 | E17: =IF(E44=0,0,E44*E154) -> 552.15108 | F17: =IF(F44=0,0,F44*F154) -> 545.11688 | G17: =IF(G44=0,0,G44*G154) -> 580.25443 | H17: =IF(H44=0,0,H44*H154) -> 600.71348 | I17: =IF(I44=0,0,I44*I154) -> 703.63451 | ... W17: =IF(W44=0,0,W44*W154) -> 652.93424 | DA17: Activity.Mpkm.EL.Tr.Road.Passenger.Bus.ICE.NGas
A18: Battery electric vehicles | B18: =IF(B45=0,0,B45*B155) -> 0 | C18: =IF(C45=0,0,C45*C155) -> 0 | D18: =IF(D45=0,0,D45*D155) -> 0 | E18: =IF(E45=0,0,E45*E155) -> 0 | F18: =IF(F45=0,0,F45*F155) -> 0 | G18: =IF(G45=0,0,G45*G155) -> 0 | H18: =IF(H45=0,0,H45*H155) -> 0 | I18: =IF(I45=0,0,I45*I155) -> 0 | ... W18: =IF(W45=0,0,W45*W155) -> 0.81682388 | DA18: Activity.Mpkm.EL.Tr.Road.Passenger.Bus.ICE.BEV
A19: Freight transport (mio tkm) | B19: =B20+B26 -> 25980.033 | C19: =C20+C26 -> 26665.249 | D19: =D20+D26 -> 27360.15 | E19: =E20+E26 -> 18787.848 | F19: =F20+F26 -> 35600.57 | G19: =G20+G26 -> 23589.425 | H19: =H20+H26 -> 30749.178 | I19: =I20+I26 -> 26102.111 | ... W19: =W20+W26 -> 21706.016 | DA19: Activity.Mtkm.EL.Tr.Road.Freight
A20: Light commercial vehicles | B20: =SUM(B21:B25) -> 1312.1663 | C20: =SUM(C21:C25) -> 1378.8971 | D20: =SUM(D21:D25) -> 1468.7122 | E20: =SUM(E21:E25) -> 1591.2658 | F20: =SUM(F21:F25) -> 1624.682 | G20: =SUM(G21:G25) -> 1672.8259 | H20: =SUM(H21:H25) -> 1778.2383 | I20: =SUM(I21:I25) -> 1958.9205 | ... W20: =SUM(W21:W25) -> 2009.0158 | DA20: Activity.Mtkm.EL.Tr.Road.Freight.LCV
A21: Gasoline engine | B21: =IF(B48=0,0,B48*B158) -> 951.9735 | C21: =IF(C48=0,0,C48*C158) -> 952.69999 | D21: =IF(D48=0,0,D48*D158) -> 981.78371 | E21: =IF(E48=0,0,E48*E158) -> 989.85028 | F21: =IF(F48=0,0,F48*F158) -> 958.16448 | G21: =IF(G48=0,0,G48*G158) -> 951.70708 | H21: =IF(H48=0,0,H48*H158) -> 916.85585 | I21: =IF(I48=0,0,I48*I158) -> 964.80998 | ... W21: =IF(W48=0,0,W48*W158) -> 626.3783 | DA21: Activity.Mtkm.EL.Tr.Road.Freight.LCV.ICE.Gasoline
A22: Diesel oil engine | B22: =IF(B49=0,0,B49*B159) -> 360.19285 | C22: =IF(C49=0,0,C49*C159) -> 426.19707 | D22: =IF(D49=0,0,D49*D159) -> 486.92853 | E22: =IF(E49=0,0,E49*E159) -> 601.41553 | F22: =IF(F49=0,0,F49*F159) -> 666.5175 | G22: =IF(G49=0,0,G49*G159) -> 721.1188 | H22: =IF(H49=0,0,H49*H159) -> 861.38242 | I22: =IF(I49=0,0,I49*I159) -> 994.11051 | ... W22: =IF(W49=0,0,W49*W159) -> 1382.6375 | DA22: Activity.Mtkm.EL.Tr.Road.Freight.LCV.ICE.Diesel
A23: LPG engine | B23: =IF(B50=0,0,B50*B160) -> 0 | C23: =IF(C50=0,0,C50*C160) -> 0 | D23: =IF(D50=0,0,D50*D160) -> 0 | E23: =IF(E50=0,0,E50*E160) -> 0 | F23: =IF(F50=0,0,F50*F160) -> 0 | G23: =IF(G50=0,0,G50*G160) -> 0 | H23: =IF(H50=0,0,H50*H160) -> 0 | I23: =IF(I50=0,0,I50*I160) -> 0 | ... W23: =IF(W50=0,0,W50*W160) -> 0 | DA23: Activity.Mtkm.EL.Tr.Road.Freight.LCV.ICE.LPG
A24: Natural gas engine | B24: =IF(B51=0,0,B51*B161) -> 0 | C24: =IF(C51=0,0,C51*C161) -> 0 | D24: =IF(D51=0,0,D51*D161) -> 0 | E24: =IF(E51=0,0,E51*E161) -> 0 | F24: =IF(F51=0,0,F51*F161) -> 0 | G24: =IF(G51=0,0,G51*G161) -> 0 | H24: =IF(H51=0,0,H51*H161) -> 0 | I24: =IF(I51=0,0,I51*I161) -> 0 | ... W24: =IF(W51=0,0,W51*W161) -> 0 | DA24: Activity.Mtkm.EL.Tr.Road.Freight.LCV.ICE.NGas
A25: Battery electric vehicles | B25: =IF(B52=0,0,B52*B162) -> 0 | C25: =IF(C52=0,0,C52*C162) -> 0 | D25: =IF(D52=0,0,D52*D162) -> 0 | E25: =IF(E52=0,0,E52*E162) -> 0 | F25: =IF(F52=0,0,F52*F162) -> 0 | G25: =IF(G52=0,0,G52*G162) -> 0 | H25: =IF(H52=0,0,H52*H162) -> 0 | I25: =IF(I52=0,0,I52*I162) -> 0 | ... W25: =IF(W52=0,0,W52*W162) -> 0 | DA25: Activity.Mtkm.EL.Tr.Road.Freight.LCV.ICE.BEV
A26: Heavy goods vehicles | B26: =SUM(B27:B28) -> 24667.867 | C26: =SUM(C27:C28) -> 25286.352 | D26: =SUM(D27:D28) -> 25891.438 | E26: =SUM(E27:E28) -> 17196.582 | F26: =SUM(F27:F28) -> 33975.888 | G26: =SUM(G27:G28) -> 21916.599 | H26: =SUM(H27:H28) -> 28970.94 | I26: =SUM(I27:I28) -> 24143.19 | ... W26: =SUM(W27:W28) -> 19697 | DA26: Activity.Mtkm.EL.Tr.Road.Freight.HGV
A27: Domestic | B27: =IF(B54=0,0,B54*B164) -> 23000 | C27: =IF(C54=0,0,C54*C164) -> 23500 | D27: =IF(D54=0,0,D54*D164) -> 24000 | E27: =IF(E54=0,0,E54*E164) -> 15276 | F27: =IF(F54=0,0,F54*F164) -> 31745 | G27: =IF(G54=0,0,G54*G164) -> 19610 | H27: =IF(H54=0,0,H54*H164) -> 26137 | I27: =IF(I54=0,0,I54*I164) -> 21729 | ... W27: =IF(W54=0,0,W54*W164) -> 16482 | DA27: Activity.Mtkm.EL.Tr.Road.Freight.HGV.Domestic
A28: International | B28: =IF(B55=0,0,B55*B165) -> 1667.8668 | C28: =IF(C55=0,0,C55*C165) -> 1786.3522 | D28: =IF(D55=0,0,D55*D165) -> 1891.4382 | E28: =IF(E55=0,0,E55*E165) -> 1920.582 | F28: =IF(F55=0,0,F55*F165) -> 2230.8881 | G28: =IF(G55=0,0,G55*G165) -> 2306.5989 | H28: =IF(H55=0,0,H55*H165) -> 2833.9401 | I28: =IF(I55=0,0,I55*I165) -> 2414.1902 | ... W28: =IF(W55=0,0,W55*W165) -> 3215 | DA28: Activity.Mtkm.EL.Tr.Road.Freight.HGV.International
A30: Vehicle-km driven (mio km) | B30: =B31+B46 -> 45566.959 | C30: =C31+C46 -> 48959.551 | D30: =D31+D46 -> 52285.895 | E30: =E31+E46 -> 54506.972 | F30: =F31+F46 -> 58547.234 | G30: =G31+G46 -> 61244.741 | H30: =H31+H46 -> 64380.153 | I30: =I31+I46 -> 67812.466 | ... W30: =W31+W46 -> 58708.885 | DA30: VehicleKm.Mkm.EL.Tr.Road
A31: Passenger transport | B31: =B32+B33+B40 -> 36663.158 | C31: =C32+C33+C40 -> 39786.56 | D31: =D32+D33+D40 -> 42665.197 | E31: =E32+E33+E40 -> 45413.141 | F31: =F32+F33+F40 -> 48106.778 | G31: =G32+G33+G40 -> 51334.636 | H31: =H32+H33+H40 -> 53809.31 | I31: =I32+I33+I40 -> 56572.845 | ... W31: =W32+W33+W40 -> 48296.044 | DA31: VehicleKm.Mkm.EL.Tr.Road.Passenger
A32: Powered two-wheelers | B32: 3793.2759 | C32: 4012.0493 | D32: 4447.191 | E32: 4715.6036 | F32: 4895.1587 | G32: 5010.378 | H32: 4750.1717 | I32: 4860.1236 | J32: 5192.5785 | K32: 5310.3364 | L32: 6339.8577 | M32: 6566.208 | N32: 6878.7175 | O32: 7013.3303 | P32: 7333.8246 | Q32: 7394.6574 | R32: 7610.494 | S32: 7154.328 | T32: 6697.5842 | U32: 7105.4988 | V32: 6359.1003 | W32: 6609.3105 | DA32: VehicleKm.Mkm.EL.Tr.Road.Passenger.P2W
A33: Passenger cars | B33: =SUM(B34:B39) -> 32090.08 | C33: =SUM(C34:C39) -> 34983.281 | D33: =SUM(D34:D39) -> 37411.533 | E33: =SUM(E34:E39) -> 39884.851 | F33: =SUM(F34:F39) -> 42403.894 | G33: =SUM(G34:G39) -> 45504.678 | H33: =SUM(H34:H39) -> 48213.203 | I33: =SUM(I34:I39) -> 50864.667 | ... W33: =SUM(W34:W39) -> 40908.732 | DA33: VehicleKm.Mkm.EL.Tr.Road.Passenger.Car
A34: Gasoline engine | B34: 29682.526 | C34: 32633.903 | D34: 35051.89 | E34: 37393.651 | F34: 40144.358 | G34: 43171.197 | H34: 45621.207 | I34: 48121.077 | J34: 50761.019 | K34: 51040.713 | L34: 49974.778 | M34: 45642.459 | N34: 39555.496 | O34: 36177.92 | P34: 34431.955 | Q34: 34043.057 | R34: 33541.557 | S34: 33480.795 | T34: 33016.52 | U34: 32272.961 | V34: 28556.24 | W34: 29489.708 | DA34: VehicleKm.Mkm.EL.Tr.Road.Passenger.Car.ICE.Gasoline
A35: Diesel oil engine | B35: 2223.692 | C35: 2159.4763 | D35: 2178.0945 | E35: 2326.6141 | F35: 2107.6162 | G35: 2179.7152 | H35: 2435.9218 | I35: 2570.1237 | J35: 2486.7528 | K35: 2824.9005 | L35: 2641.2969 | M35: 2355.1801 | N35: 2076.6194 | O35: 1840.7438 | P35: 2914.3851 | Q35: 2669.0865 | R35: 3529.199 | S35: 4460.2133 | T35: 5818.5479 | U35: 7368.7971 | V35: 8627.0742 | W35: 8640.7679 | DA35: VehicleKm.Mkm.EL.Tr.Road.Passenger.Car.ICE.Diesel
A36: LPG engine | B36: 183.86262 | C36: 179.54873 | D36: 164.80895 | E36: 146.17578 | F36: 133.65596 | G36: 133.50064 | H36: 134.84234 | I36: 149.46616 | J36: 150.78457 | K36: 219.99549 | L36: 556.76034 | M36: 1441.5717 | N36: 1019.609 | O36: 2507.0572 | P36: 2726.8745 | Q36: 3134.3403 | R36: 3509.345 | S36: 3353.5784 | T36: 3227.9929 | U36: 3269.3329 | V36: 2678.9393 | W36: 2608.4333 | DA36: VehicleKm.Mkm.EL.Tr.Road.Passenger.Car.ICE.LPG
A37: Natural gas engine | B37: 0 | C37: 10.353146 | D37: 16.738924 | E37: 18.410174 | F37: 18.263957 | G37: 20.265908 | H37: 21.231755 | I37: 23.999998 | J37: 23.430224 | K37: 30.863833 | L37: 35.463295 | M37: 37.961896 | N37: 37.678807 | O37: 36.005767 | P37: 36.379097 | Q37: 40.561909 | R37: 41.983698 | S37: 40.524668 | T37: 41.295046 | U37: 45.096729 | V37: 60.146146 | W37: 69.196862 | DA37: VehicleKm.Mkm.EL.Tr.Road.Passenger.Car.ICE.NGas
A38: Plug-in hybrid electric | B38: 0 | C38: 0 | D38: 0 | E38: 0 | F38: 0 | G38: 0 | H38: 0 | I38: 0 | J38: 0 | K38: 0 | L38: 0 | M38: 0 | N38: 0.0085854139 | O38: 0.0089061066 | P38: 0.18644739 | Q38: 0.35149608 | R38: 0.68123278 | S38: 1.7461265 | T38: 3.1186286 | U38: 4.8413904 | V38: 16.741966 | W38: 56.849041 | DA38: VehicleKm.Mkm.EL.Tr.Road.Passenger.Car.PHEV
A39: Battery electric vehicles | B39: 0 | C39: 0 | D39: 0 | E39: 0 | F39: 0 | G39: 0 | H39: 0 | I39: 0 | J39: 0 | K39: 0 | L39: 0 | M39: 0 | N39: 0.013494354 | O39: 0.040611657 | P39: 0.6101369 | Q39: 1.1403493 | R39: 1.5356624 | S39: 1.9893295 | T39: 2.8888199 | U39: 5.7201682 | V39: 13.027584 | W39: 43.776691 | DA39: VehicleKm.Mkm.EL.Tr.Road.Passenger.Car.BEV
A40: Motor coaches, buses and trolley buses | B40: =SUM(B41:B45) -> 779.80211 | C40: =SUM(C41:C45) -> 791.22962 | D40: =SUM(D41:D45) -> 806.47349 | E40: =SUM(E41:E45) -> 812.68701 | F40: =SUM(F41:F45) -> 807.72573 | G40: =SUM(G41:G45) -> 819.57985 | H40: =SUM(H41:H45) -> 845.93478 | I40: =SUM(I41:I45) -> 848.05479 | ... W40: =SUM(W41:W45) -> 778.00173 | DA40: VehicleKm.Mkm.EL.Tr.Road.Passenger.Bus
A41: Gasoline engine | B41: 0 | C41: 0 | D41: 0 | E41: 0 | F41: 0 | G41: 0 | H41: 0 | I41: 0 | J41: 0 | K41: 0 | L41: 0 | M41: 0 | N41: 0 | O41: 0 | P41: 0 | Q41: 0 | R41: 0 | S41: 0 | T41: 0 | U41: 0 | V41: 0 | W41: 0 | DA41: VehicleKm.Mkm.EL.Tr.Road.Passenger.Bus.ICE.Gasoline
A42: Diesel oil engine | B42: 779.80211 | C42: 779.29729 | D42: 787.95261 | E42: 792.24391 | F42: 787.34124 | G42: 797.66442 | H42: 822.62449 | I42: 820.93113 | J42: 799.84636 | K42: 781.67531 | L42: 788.02965 | M42: 796.89689 | N42: 791.10223 | O42: 791.46226 | P42: 790.5928 | Q42: 787.44307 | R42: 777.53942 | S42: 763.02289 | T42: 762.17407 | U42: 751.36303 | V42: 744.69932 | W42: 741.06308 | DA42: VehicleKm.Mkm.EL.Tr.Road.Passenger.Bus.ICE.Diesel
...

Sheet TrRoad_ene
A1: Road transport / energy consumption - EL - Greece | B1: 2000 | C1: 2001 | D1: 2002 | E1: 2003 | F1: 2004 | G1: 2005 | H1: 2006 | I1: 2007 | J1: 2008 | K1: 2009 | L1: 2010 | M1: 2011 | N1: 2012 | O1: 2013 | P1: 2014 | Q1: 2015 | R1: 2016 | S1: 2017 | T1: 2018 | U1: 2019 | V1: 2020 | W1: 2021 | DA1: Code
A3: Energy consumption (ktoe)
A4: by fuel (EUROSTAT DATA) | B4: =B5+B9+B10+B15 -> 5375.6687 | C4: =C5+C9+C10+C15 -> 5500.1958 | D4: =D5+D9+D10+D15 -> 5699.5439 | E4: =E5+E9+E10+E15 -> 6042.9947 | F4: =F5+F9+F10+F15 -> 6083.3334 | G4: =G5+G9+G10+G15 -> 6248.6985 | H4: =H5+H9+H10+H15 -> 6435.4258 | I4: =I5+I9+I10+I15 -> 6732.4758 | ... W4: =W5+W9+W10+W15 -> 4782.5253 | DA4: FEC.ktoe.EL.ES.Tr.Road
A5: Liquids | B5: =SUM(B6:B8) -> 5375.6687 | C5: =SUM(C6:C8) -> 5494.0909 | D5: =SUM(D6:D8) -> 5689.8921 | E5: =SUM(E6:E8) -> 6032.3541 | F5: =SUM(F6:F8) -> 6072.7358 | G5: =SUM(G6:G8) -> 6236.8324 | H5: =SUM(H6:H8) -> 6377.8447 | I5: =SUM(I6:I8) -> 6635.0673 | ... W5: =SUM(W6:W8) -> 4543.7629
A6: Liquified petroleum gas (LPG) | B6: 16.946088 | C6: 18.075838 | D6: 16.946088 | E6: 13.556922 | F6: 12.427171 | G6: 12.427171 | H6: 12.427171 | I6: 13.556922 | J6: 13.556922 | K6: 18.67773 | L6: 46.145056 | M6: 196.66569 | N6: 84.599226 | O6: 204.35658 | P6: 221.9356 | Q6: 257.09372 | R6: 261.48848 | S6: 245.90903 | T6: 235.5693 | U6: 240.3288 | V6: 193.71685 | W6: 188.56836 | DA6: FEC.ktoe.EL.ES.Tr.Road.LPG
A7: Gasoline (without biofuels) | B7: 3417.622 | C7: 3529.7793 | D7: 3695.8991 | E7: 3862.0187 | F7: 3946.6657 | G7: 4113.8435 | H7: 4159.3413 | I7: 4346.6227 | J7: 4265.15 | K7: 4247.8265 | L7: 3867.3928 | M7: 3497.4683 | N7: 3035.0626 | O7: 2777.5867 | P7: 2643.0687 | Q7: 2573.7078 | R7: 2536.9255 | S7: 2450.7542 | T7: 2402.9058 | U7: 2345.5232 | V7: 1880.6179 | W7: 2010.8193 | DA7: FEC.ktoe.EL.ES.Tr.Road.Gasoline
A8: Gas/Diesel oil (without biofuels) | B8: 1941.1006 | C8: 1946.2358 | D8: 1977.0469 | E8: 2156.7784 | F8: 2113.6429 | G8: 2110.5617 | H8: 2206.0763 | I8: 2274.8877 | J8: 2212.2384 | K8: 2774.6776 | L8: 2433.8206 | M8: 2124.5056 | N8: 1623.9037 | O8: 1844.6355 | P8: 1924.0613 | Q8: 1990.1978 | R8: 2128.5756 | S8: 2118.9013 | T8: 2192.2353 | U8: 2362.0694 | V8: 2222.4401 | W8: 2344.3752 | DA8: FEC.ktoe.EL.ES.Tr.Road.Diesel
A9: Natural gas | B9: 0 | C9: 6.1049011 | D9: 9.6518487 | E9: 10.640585 | F9: 10.597678 | G9: 11.866036 | H9: 12.510834 | I9: 14.337833 | J9: 14.187532 | K9: 14.724764 | L9: 14.144282 | M9: 14.939811 | N9: 14.724764 | O9: 13.413672 | P9: 13.757524 | Q9: 15.111694 | R9: 18.959587 | S9: 12.790198 | T9: 15.191488 | U9: 17.890972 | V9: 18.126053 | W9: 21.036371 | DA9: FEC.ktoe.EL.ES.Tr.Road.NG
A10: Renewable energies and wastes | B10: =SUM(B11:B13) -> 0 | C10: =SUM(C11:C13) -> 0 | D10: =SUM(D11:D13) -> 0 | E10: =SUM(E11:E13) -> 0 | F10: =SUM(F11:F13) -> 0 | G10: =SUM(G11:G13) -> 0 | H10: =SUM(H11:H13) -> 45.070249 | I10: =SUM(I11:I13) -> 83.070593 | ... W10: =SUM(W11:W13) -> 216.14488
A11: Biogas | B11: 0 | C11: 0 | D11: 0 | E11: 0 | F11: 0 | G11: 0 | H11: 0 | I11: 0 | J11: 0 | K11: 0 | L11: 0 | M11: 0 | N11: 0 | O11: 0 | P11: 0 | Q11: 0 | R11: 0 | S11: 0 | T11: 0 | U11: 0 | V11: 0 | W11: 0 | DA11: FEC.ktoe.EL.ES.Tr.Road.Biogas
A12: Biogasoline | B12: 0 | C12: 0 | D12: 0 | E12: 0 | F12: 0 | G12: 0 | H12: 0 | I12: 0 | J12: 0 | K12: 0 | L12: 0 | M12: 0 | N12: 0 | O12: 0 | P12: 0 | Q12: 0 | R12: 0 | S12: 0 | T12: 0 | U12: 25.154342 | V12: 62.666638 | W12: 67.851505 | DA12: FEC.ktoe.EL.ES.Tr.Road.Biogasoline
A13: Biodiesel and other biofuels | B13: 0 | C13: 0 | D13: 0 | E13: 0 | F13: 0 | G13: 0 | H13: 45.070249 | I13: 83.070593 | J13: 67.163457 | K13: 76.000774 | L13: 124.60593 | M13: 103.39639 | N13: 103.39639 | O13: 120.41651 | P13: 130.96397 | Q13: 138.87455 | R13: 146.78512 | S13: 163.68745 | T13: 156.83164 | U13: 160.55219 | V13: 136.50138 | W13: 148.29338 | DA13: FEC.ktoe.EL.ES.Tr.Road.Biodiesel
A14: Hydrogen | B14: 0 | C14: 0 | D14: 0 | E14: 0 | F14: 0 | G14: 0 | H14: 0 | I14: 0 | J14: 0 | K14: 0 | L14: 0 | M14: 0 | N14: 0 | O14: 0 | P14: 0 | Q14: 0 | R14: 0 | S14: 0 | T14: 0 | U14: 0 | V14: 0 | W14: 0 | DA14: FEC.ktoe.EL.ES.Tr.Road.OthLiqBio
A15: Electricity | B15: 0 | C15: 0 | D15: 0 | E15: 0 | F15: 0 | G15: 0 | H15: 0 | I15: 0 | J15: 0 | K15: 0 | L15: 0 | M15: 0 | N15: 0.00023910191 | O15: 0.00058046437 | P15: 0.0092755985 | Q15: 0.018191723 | R15: 0.029665749 | S15: 0.050228802 | T15: 0.084285352 | U15: 0.17284844 | V15: 0.49972846 | W15: 1.581129 | DA15: FEC.ktoe.EL.ES.Tr.Road.Elec
A17: Total energy consumption (ktoe) | B17: =B18+B42 -> 5375.6687 | C17: =C18+C42 -> 5500.1958 | D17: =D18+D42 -> 5699.5439 | E17: =E18+E42 -> 6042.9947 | F17: =F18+F42 -> 6083.3334 | G17: =G18+G42 -> 6248.6985 | H17: =H18+H42 -> 6435.4258 | I17: =I18+I42 -> 6732.4758 | ... W17: =W18+W42 -> 4782.5253 | DA17: FEC.ktoe.EL.Tr.Road
A18: Passenger transport | B18: =B19+B21+B33 -> 3489.3262 | C18: =C19+C21+C33 -> 3602.8229 | D18: =D19+D21+D33 -> 3763.5729 | E18: =E19+E21+E33 -> 4098.6118 | F18: =F19+F21+F33 -> 4027.1831 | G18: =G19+G21+G33 -> 4281.6241 | H18: =H19+H21+H33 -> 4363.7098 | I18: =I19+I21+I33 -> 4571.0325 | ... W18: =W19+W21+W33 -> 3171.83 | DA18: FEC.ktoe.EL.Tr.Road.Passenger
A19: Powered two-wheelers (Gasoline) | B19: 169.12614 | C19: 183.28186 | D19: 201.62988 | E19: 211.32154 | F19: 212.79747 | G19: 219.1618 | H19: 200.05889 | I19: 200.25704 | J19: 214.65444 | K19: 220.15019 | L19: 260.32986 | M19: 266.29533 | N19: 273.80395 | O19: 274.02632 | P19: 280.35015 | Q19: 288.13718 | R19: 278.79099 | S19: 273.85667 | T19: 251.56861 | U19: 263.4729 | V19: 222.18886 | W19: 229.96149 | DA19: FEC.ktoe.EL.Tr.Road.Passenger.P2W
A20: of which biofuels | B20: 0 | C20: 0 | D20: 0 | E20: 0 | F20: 0 | G20: 0 | H20: 0 | I20: 0 | J20: 0 | K20: 0 | L20: 0 | M20: 0 | N20: 0 | O20: 0 | P20: 0 | Q20: 0 | R20: 0 | S20: 0 | T20: 0 | U20: 2.795609 | V20: 7.1651006 | W20: 7.506351 | DA20: FEC.ktoe.EL.Tr.Road.Passenger.P2W.Biogasoline
A21: Passenger cars | B21: =B22+B24+B26+B27+B29+B32 -> 2753.7785 | C21: =C22+C24+C26+C27+C29+C32 -> 2871.0489 | D21: =D22+D24+D26+D27+D29+D32 -> 3015.7548 | E21: =E22+E24+E26+E27+E29+E32 -> 3184.1534 | F21: =F22+F24+F26+F27+F29+F32 -> 3282.838 | G21: =G22+G24+G26+G27+G29+G32 -> 3461.8739 | H21: =H22+H24+H26+H27+H29+H32 -> 3575.7978 | I21: =I22+I24+I26+I27+I29+I32 -> 3765.0147 | ... W21: =W22+W24+W26+W27+W29+W32 -> 2376.8339 | DA21: FEC.ktoe.EL.Tr.Road.Passenger.Car
A22: Gasoline engine | B22: 2583.2559 | C22: 2704.2903 | D22: 2850.6295 | E22: 3014.1394 | F22: 3129.3049 | G22: 3302.7825 | H22: 3401.3679 | I22: 3575.7282 | J22: 3494.5261 | K22: 3563.8391 | L22: 3173.9111 | M22: 2873.1426 | N22: 2474.0661 | O22: 2218.2689 | P22: 2082.3042 | Q22: 2000.7125 | R22: 1973.341 | S22: 1908.248 | T22: 1855.9625 | U22: 1812.648 | V22: 1458.4994 | W22: 1560.1338 | DA22: FEC.ktoe.EL.Tr.Road.Passenger.Car.ICE.Gasoline
A23: of which biofuels | B23: 0 | C23: 0 | D23: 0 | E23: 0 | F23: 0 | G23: 0 | H23: 0 | I23: 0 | J23: 0 | K23: 0 | L23: 0 | M23: 0 | N23: 0 | O23: 0 | P23: 0 | Q23: 0 | R23: 0 | S23: 0 | T23: 0 | U23: 19.233307 | V23: 47.033386 | W23: 50.925535 | DA23: FEC.ktoe.EL.Tr.Road.Passenger.Car.ICE.Gasoline.Biogasoline
A24: Diesel oil engine | B24: 153.57647 | C24: 147.74715 | D24: 146.66951 | E24: 154.79899 | F24: 139.46123 | G24: 144.84454 | H24: 160.10202 | I24: 173.59791 | J24: 159.18598 | K24: 195.02964 | L24: 182.83616 | M24: 169.38619 | N24: 169.57178 | O24: 99.699838 | P24: 152.16994 | Q24: 291.20798 | R24: 357.17528 | S24: 439.72103 | T24: 506.28721 | U24: 603.83644 | V24: 590.9767 | W24: 622.25402 | DA24: FEC.ktoe.EL.Tr.Road.Passenger.Car.ICE.Diesel
A25: of which biofuels | B25: 0 | C25: 0 | D25: 0 | E25: 0 | F25: 0 | G25: 0 | H25: 3.2054058 | I25: 6.1158339 | J25: 4.6904763 | K25: 5.1996059 | L25: 8.9048761 | M25: 7.8611718 | N25: 10.150587 | O25: 6.1095108 | P25: 9.6975837 | Q25: 18.994834 | R25: 23.041629 | S25: 31.532974 | T25: 33.801444 | U25: 38.431156 | V25: 34.197175 | W25: 37.019021 | DA25: FEC.ktoe.EL.Tr.Road.Passenger.Car.ICE.Diesel.BioDiesel_OthLiqBio
A26: LPG engine | B26: 16.946088 | C26: 18.075838 | D26: 16.946088 | E26: 13.556922 | F26: 12.427171 | G26: 12.427171 | H26: 12.427171 | I26: 13.556922 | J26: 13.556922 | K26: 18.67773 | L26: 46.145056 | M26: 196.66569 | N26: 84.599226 | O26: 204.35658 | P26: 221.9356 | Q26: 257.09372 | R26: 261.48848 | S26: 245.90903 | T26: 235.5693 | U26: 240.3288 | V26: 193.71685 | W26: 188.56836 | DA26: FEC.ktoe.EL.Tr.Road.Passenger.Car.ICE.LPG
A27: Natural gas engine | B27: 0 | C27: 0.93552166 | D27: 1.5097886 | E27: 1.6581072 | F27: 1.6447074 | G27: 1.8196536 | H27: 1.9007042 | I27: 2.1316428 | J27: 2.0769551 | K27: 2.6217199 | L27: 2.9365716 | M27: 3.0715602 | N27: 3.0271651 | O27: 2.8748083 | P27: 2.8911603 | Q27: 2.9765917 | R27: 2.9827598 | S27: 2.8256344 | T27: 2.8010272 | U27: 2.9104898 | V27: 3.4119992 | W27: 3.5316391 | DA27: FEC.ktoe.EL.Tr.Road.Passenger.Car.ICE.NGas
A28: of which biogas | B28: 0 | C28: 0 | D28: 0 | E28: 0 | F28: 0 | G28: 0 | H28: 0 | I28: 0 | J28: 0 | K28: 0 | L28: 0 | M28: 0 | N28: 0 | O28: 0 | P28: 0 | Q28: 0 | R28: 0 | S28: 0 | T28: 0 | U28: 0 | V28: 0 | W28: 0 | DA28: FEC.ktoe.EL.Tr.Road.Passenger.Car.ICE.NGas.Biogas
A29: Plug-in hybrid electric (Gasoline and electricity) | B29: 0 | C29: 0 | D29: 0 | E29: 0 | F29: 0 | G29: 0 | H29: 0 | I29: 0 | J29: 0 | K29: 0 | L29: 0 | M29: 0 | N29: 0.00020919164 | O29: 0.00013366983 | P29: 0.0036204936 | Q29: 0.0077265771 | R29: 0.020485778 | S29: 0.055904868 | T29: 0.10644219 | U29: 0.17133185 | V29: 0.52601028 | W29: 1.6510474 | DA29: FEC.ktoe.EL.Tr.Road.Passenger.Car.PHEV
A30: of which biofuels | B30: 0 | C30: 0 | D30: 0 | E30: 0 | F30: 0 | G30: 0 | H30: 0 | I30: 0 | J30: 0 | K30: 0 | L30: 0 | M30: 0 | N30: 0 | O30: 0 | P30: 0 | Q30: 0 | R30: 0 | S30: 0 | T30: 0 | U30: 0.0010460741 | V30: 0.0081049316 | W30: 0.02550105 | DA30: FEC.ktoe.EL.Tr.Road.Passenger.Car.PHEV.Biogasoline
A31: of which electricity | B31: 0 | C31: 0 | D31: 0 | E31: 0 | F31: 0 | G31: 0 | H31: 0 | I31: 0 | J31: 0 | K31: 0 | L31: 0 | M31: 0 | N31: 8.4778905e-05 | O31: 9.4327981e-05 | P31: 0.0019856609 | Q31: 0.0038651831 | R31: 0.010226675 | S31: 0.025308433 | T31: 0.047282861 | U31: 0.072744324 | V31: 0.27467737 | W31: 0.86980771 | DA31: FEC.ktoe.EL.Tr.Road.Passenger.Car.PHEV.Elec
A32: Battery electric vehicles | B32: 0 | C32: 0 | D32: 0 | E32: 0 | F32: 0 | G32: 0 | H32: 0 | I32: 0 | J32: 0 | K32: 0 | L32: 0 | M32: 0 | N32: 0.000154323 | O32: 0.00048613639 | P32: 0.0072899376 | Q32: 0.01432654 | R32: 0.019439074 | S32: 0.024920369 | T32: 0.037002491 | U32: 0.083770294 | V32: 0.20879633 | W32: 0.69499386 | DA32: FEC.ktoe.EL.Tr.Road.Passenger.Car.BEV
A33: Motor coaches, buses and trolley buses | B33: =B34+B36+B38+B39+B41 -> 566.42158 | C33: =C34+C36+C38+C39+C41 -> 548.49223 | D33: =D34+D36+D38+D39+D41 -> 546.18819 | E33: =E34+E36+E38+E39+E41 -> 703.13682 | F33: =F34+F36+F38+F39+F41 -> 531.54762 | G33: =G34+G36+G38+G39+G41 -> 600.58847 | H33: =H34+H36+H38+H39+H41 -> 587.8531 | I33: =I34+I36+I38+I39+I41 -> 605.76085 | ... W33: =W34+W36+W38+W39+W41 -> 565.03468 | DA33: FEC.ktoe.EL.Tr.Road.Passenger.Bus
A34: Gasoline engine | B34: 0 | C34: 0 | D34: 0 | E34: 0 | F34: 0 | G34: 0 | H34: 0 | I34: 0 | J34: 0 | K34: 0 | L34: 0 | M34: 0 | N34: 0 | O34: 0 | P34: 0 | Q34: 0 | R34: 0 | S34: 0 | T34: 0 | U34: 0 | V34: 0 | W34: 0 | DA34: FEC.ktoe.EL.Tr.Road.Passenger.Bus.ICE.Gasoline
A35: of which biofuels | B35: 0 | C35: 0 | D35: 0 | E35: 0 | F35: 0 | G35: 0 | H35: 0 | I35: 0 | J35: 0 | K35: 0 | L35: 0 | M35: 0 | N35: 0 | O35: 0 | P35: 0 | Q35: 0 | R35: 0 | S35: 0 | T35: 0 | U35: 0 | V35: 0 | W35: 0 | DA35: FEC.ktoe.EL.Tr.Road.Passenger.Bus.ICE.Gasoline.Biogasoline
A36: Diesel oil engine | B36: 566.42158 | C36: 543.32285 | D36: 538.04613 | E36: 694.15434 | F36: 522.59465 | G36: 590.54209 | H36: 577.24297 | I36: 593.55466 | J36: 542.47531 | K36: 645.11651 | L36: 565.8322 | M36: 601.98146 | N36: 493.50379 | O36: 565.52352 | P36: 546.80982 | Q36: 523.09532 | R36: 526.4166 | S36: 533.13972 | T36: 542.96922 | U36: 561.0089 | V36: 542.28619 | W36: 547.51362 | DA36: FEC.ktoe.EL.Tr.Road.Passenger.Bus.ICE.Diesel
A37: of which biofuels | B37: 0 | C37: 0 | D37: 0 | E37: 0 | F37: 0 | G37: 0 | H37: 11.556993 | I37: 20.910861 | J37: 15.984244 | K37: 17.199188 | L37: 27.558364 | M37: 27.937813 | N37: 29.541195 | O37: 34.654741 | P37: 34.847448 | Q37: 34.120319 | R37: 33.959506 | S37: 38.232152 | T37: 36.250458 | U37: 35.705399 | V37: 31.379673 | W37: 32.572579 | DA37: FEC.ktoe.EL.Tr.Road.Passenger.Bus.ICE.Diesel.BioDiesel_OthLiqBio
A38: LPG engine | B38: 0 | C38: 0 | D38: 0 | E38: 0 | F38: 0 | G38: 0 | H38: 0 | I38: 0 | J38: 0 | K38: 0 | L38: 0 | M38: 0 | N38: 0 | O38: 0 | P38: 0 | Q38: 0 | R38: 0 | S38: 0 | T38: 0 | U38: 0 | V38: 0 | W38: 0 | DA38: FEC.ktoe.EL.Tr.Road.Passenger.Bus.ICE.LPG
A39: Natural gas engine | B39: 0 | C39: 5.1693795 | D39: 8.14206 | E39: 8.9824775 | F39: 8.952971 | G39: 10.046382 | H39: 10.61013 | I39: 12.20619 | J39: 12.110577 | K39: 12.103044 | L39: 11.20771 | M39: 11.868251 | N39: 11.697598 | O39: 10.538863 | P39: 10.866363 | Q39: 12.135102 | R39: 15.976827 | S39: 9.9645634 | T39: 12.39046 | U39: 14.980482 | V39: 14.714054 | W39: 17.504732 | DA39: FEC.ktoe.EL.Tr.Road.Passenger.Bus.ICE.NGas
A40: of which biogas | B40: 0 | C40: 0 | D40: 0 | E40: 0 | F40: 0 | G40: 0 | H40: 0 | I40: 0 | J40: 0 | K40: 0 | L40: 0 | M40: 0 | N40: 0 | O40: 0 | P40: 0 | Q40: 0 | R40: 0 | S40: 0 | T40: 0 | U40: 0 | V40: 0 | W40: 0 | DA40: FEC.ktoe.EL.Tr.Road.Passenger.Bus.ICE.NGas.Biogas
A41: Battery electric vehicles | B41: 0 | C41: 0 | D41: 0 | E41: 0 | F41: 0 | G41: 0 | H41: 0 | I41: 0 | J41: 0 | K41: 0 | L41: 0 | M41: 0 | N41: 0 | O41: 0 | P41: 0 | Q41: 0 | R41: 0 | S41: 0 | T41: 0 | U41: 0.016333823 | V41: 0.016254755 | W41: 0.01632745 | DA41: FEC.ktoe.EL.Tr.Road.Passenger.Bus.ICE.BEV
A42: Freight transport | B42: =B43+B52 -> 1886.3425 | C42: =C43+C52 -> 1897.3728 | D42: =D43+D52 -> 1935.971 | E42: =E43+E52 -> 1944.3829 | F42: =F43+F52 -> 2056.1504 | G42: =G43+G52 -> 1967.0743 | H42: =H43+H52 -> 2071.716 | I42: =I43+I52 -> 2161.4432 | ... W42: =W43+W52 -> 1610.6953 | DA42: FEC.ktoe.EL.Tr.Road.Freight
...

Sheet TrRoad_emi
A1: Road transport / CO2 emissions - EL - Greece | B1: 2000 | C1: 2001 | D1: 2002 | E1: 2003 | F1: 2004 | G1: 2005 | H1: 2006 | I1: 2007 | J1: 2008 | K1: 2009 | L1: 2010 | M1: 2011 | N1: 2012 | O1: 2013 | P1: 2014 | Q1: 2015 | R1: 2016 | S1: 2017 | T1: 2018 | U1: 2019 | V1: 2020 | W1: 2021 | DA1: Code
A3: CO2 emissions (kt CO2)
A4: by fuel | B4: =B5+B9+B10+B15 -> 15982.944 | C4: =C5+C9+C10+C15 -> 16341.618 | D4: =D5+D9+D10+D15 -> 16924.542 | E4: =E5+E9+E10+E15 -> 17957.502 | F4: =F5+F9+F10+F15 -> 18066.191 | G4: =G5+G9+G10+G15 -> 18544.669 | H4: =H5+H9+H10+H15 -> 18974.52 | I4: =I5+I9+I10+I15 -> 19738.666 | ... W4: =W5+W9+W10+W15 -> 13655.144 | DA4: EMI.ktCO2.EL.ES.Tr.Road
A5: Liquids | B5: =SUM(B6:B8) -> 15982.944 | C5: =SUM(C6:C8) -> 16327.279 | D5: =SUM(D6:D8) -> 16901.872 | E5: =SUM(E6:E8) -> 17932.509 | F5: =SUM(F6:F8) -> 18041.299 | G5: =SUM(G6:G8) -> 18516.799 | H5: =SUM(H6:H8) -> 18945.134 | I5: =SUM(I6:I8) -> 19704.989 | ... W5: =SUM(W6:W8) -> 13605.734
A6: Liquified petroleum gas (LPG) | B6: 44.769374 | C6: 47.75403 | D6: 44.769374 | E6: 35.815636 | F6: 32.83098 | G6: 32.83098 | H6: 32.83098 | I6: 35.815636 | J6: 35.815636 | K6: 49.34415 | L6: 121.90928 | M6: 519.56535 | N6: 223.50023 | O6: 539.88368 | P6: 586.32517 | Q6: 679.2084 | R6: 690.81877 | S6: 649.65988 | T6: 622.34366 | U6: 634.91765 | V6: 511.7749 | W6: 498.17324 | DA6: EMI.ktCO2.EL.ES.Tr.Road.LPG
A7: Gasoline (without biofuels) | B7: 9916.0676 | C7: 10241.487 | D7: 10723.475 | E7: 11205.464 | F7: 11451.063 | G7: 11936.121 | H7: 12068.131 | I7: 12611.519 | J7: 12375.13 | K7: 12324.866 | L7: 11221.056 | M7: 10147.738 | N7: 8806.0897 | O7: 8059.0355 | P7: 7668.738 | Q7: 7467.4907 | R7: 7360.7687 | S7: 7110.7466 | T7: 6971.9212 | U7: 6805.424 | V7: 5456.5312 | W7: 5834.2966 | DA7: EMI.ktCO2.EL.ES.Tr.Road.Gasoline
A8: Gas/Diesel oil (without biofuels) | B8: 6022.107 | C8: 6038.0384 | D8: 6133.6276 | E8: 6691.2299 | F8: 6557.4055 | G8: 6547.8464 | H8: 6844.1725 | I8: 7057.6544 | J8: 6863.2901 | K8: 8608.2118 | L8: 7550.7306 | M8: 6591.1061 | N8: 5038.0294 | O8: 5722.9639 | P8: 5969.244 | Q8: 6174.427 | R8: 6603.7329 | S8: 6573.7192 | T8: 6801.2223 | U8: 7328.1332 | V8: 6894.9476 | W8: 7273.2643 | DA8: EMI.ktCO2.EL.ES.Tr.Road.Diesel
A9: Natural gas | B9: 0 | C9: 14.33916 | D9: 22.670212 | E9: 24.99255 | F9: 24.891772 | G9: 27.870884 | H9: 29.385382 | I9: 33.676628 | J9: 33.323602 | K9: 34.585448 | L9: 33.222016 | M9: 35.09055 | N9: 34.585448 | O9: 31.505962 | P9: 32.3136 | Q9: 35.494268 | R9: 44.53218 | S9: 30.04155 | T9: 35.681687 | U9: 42.022221 | V9: 42.57438 | W9: 49.41012 | DA9: EMI.ktCO2.EL.ES.Tr.Road.NG
A10: Renewable energies and wastes | B10: =SUM(B11:B14) -> 0 | C10: =SUM(C11:C14) -> 0 | D10: =SUM(D11:D14) -> 0 | E10: =SUM(E11:E14) -> 0 | F10: =SUM(F11:F14) -> 0 | G10: =SUM(G11:G14) -> 0 | H10: =SUM(H11:H14) -> 0 | I10: =SUM(I11:I14) -> 0 | ... W10: =SUM(W11:W14) -> 0
A11: Biogas | B11: 0 | C11: 0 | D11: 0 | E11: 0 | F11: 0 | G11: 0 | H11: 0 | I11: 0 | J11: 0 | K11: 0 | L11: 0 | M11: 0 | N11: 0 | O11: 0 | P11: 0 | Q11: 0 | R11: 0 | S11: 0 | T11: 0 | U11: 0 | V11: 0 | W11: 0 | DA11: EMI.ktCO2.EL.ES.Tr.Road.Biogas
A12: Biogasoline | B12: 0 | C12: 0 | D12: 0 | E12: 0 | F12: 0 | G12: 0 | H12: 0 | I12: 0 | J12: 0 | K12: 0 | L12: 0 | M12: 0 | N12: 0 | O12: 0 | P12: 0 | Q12: 0 | R12: 0 | S12: 0 | T12: 0 | U12: 0 | V12: 0 | W12: 0 | DA12: EMI.ktCO2.EL.ES.Tr.Road.Biogasoline
A13: Biodiesel | B13: 0 | C13: 0 | D13: 0 | E13: 0 | F13: 0 | G13: 0 | H13: 0 | I13: 0 | J13: 0 | K13: 0 | L13: 0 | M13: 0 | N13: 0 | O13: 0 | P13: 0 | Q13: 0 | R13: 0 | S13: 0 | T13: 0 | U13: 0 | V13: 0 | W13: 0 | DA13: EMI.ktCO2.EL.ES.Tr.Road.Biodiesel
A14: Other biofuels | B14: 0 | C14: 0 | D14: 0 | E14: 0 | F14: 0 | G14: 0 | H14: 0 | I14: 0 | J14: 0 | K14: 0 | L14: 0 | M14: 0 | N14: 0 | O14: 0 | P14: 0 | Q14: 0 | R14: 0 | S14: 0 | T14: 0 | U14: 0 | V14: 0 | W14: 0 | DA14: EMI.ktCO2.EL.ES.Tr.Road.OthLiqBio
A15: Electricity | B15: 0 | C15: 0 | D15: 0 | E15: 0 | F15: 0 | G15: 0 | H15: 0 | I15: 0 | J15: 0 | K15: 0 | L15: 0 | M15: 0 | N15: 0 | O15: 0 | P15: 0 | Q15: 0 | R15: 0 | S15: 0 | T15: 0 | U15: 0 | V15: 0 | W15: 0 | DA15: EMI.ktCO2.EL.ES.Tr.Road.Elec
A17: Split of CO2 emissions (kt CO2) | B17: =SUM(B18,B33) -> 15982.944 | C17: =SUM(C18,C33) -> 16341.618 | D17: =SUM(D18,D33) -> 16924.542 | E17: =SUM(E18,E33) -> 17957.502 | F17: =SUM(F18,F33) -> 18066.191 | G17: =SUM(G18,G33) -> 18544.669 | H17: =SUM(H18,H33) -> 18974.52 | I17: =SUM(I18,I33) -> 19738.666 | ... W17: =SUM(W18,W33) -> 13655.144 | DA17: EMI.ktCO2.EL.Tr.Road
A18: Passenger transport | B18: =SUM(B19,B20,B27) -> 10264.41 | C18: =SUM(C19,C20,C27) -> 10584.235 | D18: =SUM(D19,D20,D27) -> 11047.699 | E18: =SUM(E19,E20,E27) -> 12053.138 | F18: =SUM(F19,F20,F27) -> 11808.648 | G18: =SUM(G19,G20,G27) -> 12560.933 | H18: =SUM(H19,H20,H27) -> 12753.339 | I18: =SUM(I19,I20,I27) -> 13321.514 | ... W18: =SUM(W19,W20,W27) -> 8987.3362 | DA18: EMI.ktCO2.EL.Tr.Road.Passenger
A19: Powered two-wheelers | B19: 490.71143 | C19: 531.7836 | D19: 585.01951 | E19: 613.13938 | F19: 617.42172 | G19: 635.88752 | H19: 580.46136 | I19: 581.03628 | J19: 622.80963 | K19: 638.75528 | L19: 755.3347 | M19: 772.64322 | N19: 794.42912 | O19: 795.07433 | P19: 813.42261 | Q19: 836.01633 | R19: 808.89877 | S19: 794.58208 | T19: 729.91483 | U19: 756.34275 | V19: 623.88212 | W19: 645.44299 | DA19: EMI.ktCO2.EL.Tr.Road.Passenger.P2W
A20: Passenger cars | B20: =SUM(B21:B26) -> 8016.422 | C20: =SUM(C21:C26) -> 8354.6946 | D20: =SUM(D21:D26) -> 8774.3115 | E20: =SUM(E21:E26) -> 9265.3434 | F20: =SUM(F21:F26) -> 9548.8903 | G20: =SUM(G21:G26) -> 10069.34 | H20: =SUM(H21:H26) -> 10392.961 | I20: =SUM(I21:I26) -> 10935.227 | ... W20: =SUM(W21:W26) -> 6703.2087 | DA20: EMI.ktCO2.EL.Tr.Road.Passenger.Car
A21: Gasoline engine | B21: 7495.1941 | C21: 7846.3697 | D21: 8270.9657 | E21: 8745.382 | F21: 9079.5291 | G21: 9582.8662 | H21: 9868.9071 | I21: 10374.805 | J21: 10139.201 | K21: 10340.309 | L21: 9208.9519 | M21: 8336.2864 | N21: 7178.3851 | O21: 6436.2017 | P21: 6041.7065 | Q21: 5804.972 | R21: 5725.555 | S21: 5536.6906 | T21: 5384.9904 | U21: 5203.5075 | V21: 4095.3073 | W21: 4378.8959 | DA21: EMI.ktCO2.EL.Tr.Road.Passenger.Car.ICE.Gasoline
A22: Diesel oil engine | B22: 476.45852 | C22: 458.37353 | D22: 455.03023 | E22: 480.25128 | F22: 432.66713 | G22: 449.36842 | H22: 486.75902 | I22: 519.59954 | J22: 479.30975 | K22: 588.93228 | L22: 539.6077 | M22: 501.11825 | N22: 494.59129 | O22: 290.36309 | P22: 442.00891 | Q22: 844.51917 | R22: 1036.6225 | S22: 1266.3703 | T22: 1465.8466 | U22: 1754.1251 | V22: 1727.3652 | W22: 1815.6517 | DA22: EMI.ktCO2.EL.Tr.Road.Passenger.Car.ICE.Diesel
A23: LPG engine | B23: 44.769374 | C23: 47.75403 | D23: 44.769374 | E23: 35.815636 | F23: 32.83098 | G23: 32.83098 | H23: 32.83098 | I23: 35.815636 | J23: 35.815636 | K23: 49.34415 | L23: 121.90928 | M23: 519.56535 | N23: 223.50023 | O23: 539.88368 | P23: 586.32517 | Q23: 679.2084 | R23: 690.81877 | S23: 649.65988 | T23: 622.34366 | U23: 634.91765 | V23: 511.7749 | W23: 498.17324 | DA23: EMI.ktCO2.EL.Tr.Road.Passenger.Car.ICE.LPG
A24: Natural gas engine | B24: 0 | C24: 2.1973484 | D24: 3.5461837 | E24: 3.8945536 | F24: 3.8630802 | G24: 4.273993 | H24: 4.4643642 | I24: 5.0067916 | J24: 4.8783414 | K24: 6.157882 | L24: 6.8974042 | M24: 7.2144646 | N24: 7.1101895 | O24: 6.7523349 | P24: 6.7907422 | Q24: 6.9914032 | R24: 7.0058907 | S24: 6.6368353 | T24: 6.579038 | U24: 6.8361433 | V24: 8.0140859 | W24: 8.2950955 | DA24: EMI.ktCO2.EL.Tr.Road.Passenger.Car.ICE.NGas
A25: Plug-in hybrid electric | B25: 0 | C25: 0 | D25: 0 | E25: 0 | F25: 0 | G25: 0 | H25: 0 | I25: 0 | J25: 0 | K25: 0 | L25: 0 | M25: 0 | N25: 0.00036097764 | O25: 0.0001141485 | P25: 0.0047433892 | Q25: 0.011203651 | R25: 0.029766298 | S25: 0.088774101 | T25: 0.1716481 | U25: 0.28301187 | V25: 0.70571541 | W25: 2.1927397 | DA25: EMI.ktCO2.EL.Tr.Road.Passenger.Car.PHEV
A26: Battery electric vehicles | B26: 0 | C26: 0 | D26: 0 | E26: 0 | F26: 0 | G26: 0 | H26: 0 | I26: 0 | J26: 0 | K26: 0 | L26: 0 | M26: 0 | N26: 0 | O26: 0 | P26: 0 | Q26: 0 | R26: 0 | S26: 0 | T26: 0 | U26: 0 | V26: 0 | W26: 0 | DA26: EMI.ktCO2.EL.Tr.Road.Passenger.Car.BEV
A27: Motor coaches, buses and trolley buses | B27: =SUM(B28:B32) -> 1757.277 | C27: =SUM(C28:C32) -> 1697.7568 | D27: =SUM(D28:D32) -> 1688.3685 | E27: =SUM(E28:E32) -> 2174.6555 | F27: =SUM(F28:F32) -> 1642.3362 | G27: =SUM(G28:G32) -> 1855.7058 | H27: =SUM(H28:H32) -> 1779.9158 | I27: =SUM(I28:I32) -> 1805.2507 | ... W27: =SUM(W28:W32) -> 1638.6845 | DA27: EMI.ktCO2.EL.Tr.Road.Passenger.Bus
A28: Gasoline engine | B28: 0 | C28: 0 | D28: 0 | E28: 0 | F28: 0 | G28: 0 | H28: 0 | I28: 0 | J28: 0 | K28: 0 | L28: 0 | M28: 0 | N28: 0 | O28: 0 | P28: 0 | Q28: 0 | R28: 0 | S28: 0 | T28: 0 | U28: 0 | V28: 0 | W28: 0 | DA28: EMI.ktCO2.EL.Tr.Road.Passenger.Bus.ICE.Gasoline
A29: Diesel oil engine | B29: 1757.277 | C29: 1685.615 | D29: 1669.2444 | E29: 2153.5575 | F29: 1621.3075 | G29: 1832.1089 | H29: 1754.9948 | I29: 1776.5809 | J29: 1633.3958 | K29: 1948.0625 | L29: 1669.9509 | M29: 1780.9238 | N29: 1439.4063 | O29: 1647.0153 | P29: 1588.3217 | Q29: 1517.0052 | R29: 1527.8081 | S29: 1535.4106 | T29: 1572.0515 | U29: 1629.7125 | V29: 1585.0478 | W29: 1597.5695 | DA29: EMI.ktCO2.EL.Tr.Road.Passenger.Bus.ICE.Diesel
A30: LPG engine | B30: 0 | C30: 0 | D30: 0 | E30: 0 | F30: 0 | G30: 0 | H30: 0 | I30: 0 | J30: 0 | K30: 0 | L30: 0 | M30: 0 | N30: 0 | O30: 0 | P30: 0 | Q30: 0 | R30: 0 | S30: 0 | T30: 0 | U30: 0 | V30: 0 | W30: 0 | DA30: EMI.ktCO2.EL.Tr.Road.Passenger.Bus.ICE.LPG
A31: Natural gas engine | B31: 0 | C31: 12.141812 | D31: 19.124028 | E31: 21.097996 | F31: 21.028692 | G31: 23.596891 | H31: 24.921018 | I31: 28.669836 | J31: 28.445261 | K31: 28.427566 | L31: 26.324612 | M31: 27.876085 | N31: 27.475259 | O31: 24.753627 | P31: 25.522858 | Q31: 28.502865 | R31: 37.526289 | S31: 23.404715 | T31: 29.102649 | U31: 35.186078 | V31: 34.560294 | W31: 41.115024 | DA31: EMI.ktCO2.EL.Tr.Road.Passenger.Bus.ICE.NGas
A32: Battery electric vehicles | B32: 0 | C32: 0 | D32: 0 | E32: 0 | F32: 0 | G32: 0 | H32: 0 | I32: 0 | J32: 0 | K32: 0 | L32: 0 | M32: 0 | N32: 0 | O32: 0 | P32: 0 | Q32: 0 | R32: 0 | S32: 0 | T32: 0 | U32: 0 | V32: 0 | W32: 0 | DA32: EMI.ktCO2.EL.Tr.Road.Passenger.Bus.ICE.BEV
A33: Freight transport | B33: =B34+B40 -> 5718.5336 | C33: =C34+C40 -> 5757.3831 | D33: =D34+D40 -> 5876.843 | E33: =E34+E40 -> 5904.3633 | F33: =F34+F40 -> 6257.5427 | G33: =G34+G40 -> 5983.7365 | H33: =H34+H40 -> 6221.1809 | I33: =I34+I40 -> 6417.1514 | ... W33: =W34+W40 -> 4667.8081 | DA33: EMI.ktCO2.EL.Tr.Road.Freight
A34: Light commercial vehicles | B34: =SUM(B35:B39) -> 2339.8202 | C34: =SUM(C35:C39) -> 2320.7114 | D34: =SUM(D35:D39) -> 2369.8687 | E34: =SUM(E35:E39) -> 2431.7017 | F34: =SUM(F35:F39) -> 2386.1663 | G34: =SUM(G35:G39) -> 2388.2638 | H34: =SUM(H35:H39) -> 2384.2005 | I34: =SUM(I35:I39) -> 2511.5619 | ... W34: =SUM(W35:W39) -> 1915.5086 | DA34: EMI.ktCO2.EL.Tr.Road.Freight.LCV
A35: Gasoline engine | B35: 1930.1621 | C35: 1863.3332 | D35: 1867.49 | E35: 1846.9422 | F35: 1754.1118 | G35: 1717.3674 | H35: 1618.7622 | I35: 1655.6775 | J35: 1613.1187 | K35: 1345.8016 | L35: 1256.7694 | M35: 1038.8081 | N35: 833.27511 | O35: 827.75939 | P35: 813.60418 | Q35: 826.4912 | R35: 826.28511 | S35: 779.38508 | T35: 856.84425 | U35: 845.29074 | V35: 736.6361 | W35: 807.76494 | DA35: EMI.ktCO2.EL.Tr.Road.Freight.LCV.ICE.Gasoline
