Workbook

Sheet cover
B6: JRC-IDEES-2021 - Integrated Database of the European Energy System
C10: Italy
C15: Residential sector
L28: Prepared by JRC C.6
L30: 45432.786
L31: v2021-1.00
B33: Legal Notice
B35: The information made available is property of the Joint Research Centre of the European Commission.
B36: Neither the European Commission nor any person acting on behalf of the Commission is responsible for the use which might be made of this information.
B38: Use conditions
B39: This work is licensed under
B40: CC BY 4.0

Sheet index
A1: IT | B1: Italy
B3: Click on the link to jump to the sheet
B4: =HYPERLINK("#"&CELL("address",RES_summary!$B$2),MID(CELL("filename",RES_summary!$B$2),FIND("]",CELL("filename",RES_summary!$B$2))+1,256)) -> RES_summary | D4: Residential sector summary
B6: Thermal uses
B7: =HYPERLINK("#"&CELL("address",RES_hh_num!$B$2),MID(CELL("filename",RES_hh_num!$B$2),FIND("]",CELL("filename",RES_hh_num!$B$2))+1,256)) -> RES_hh_num | D7: Number of households
B8: =HYPERLINK("#"&CELL("address",RES_hh_fec!$B$2),MID(CELL("filename",RES_hh_fec!$B$2),FIND("]",CELL("filename",RES_hh_fec!$B$2))+1,256)) -> RES_hh_fec | D8: Final energy consumption
B9: =HYPERLINK("#"&CELL("address",RES_hh_tes!$B$2),MID(CELL("filename",RES_hh_tes!$B$2),FIND("]",CELL("filename",RES_hh_tes!$B$2))+1,256)) -> RES_hh_tes | D9: Thermal energy service
B10: =HYPERLINK("#"&CELL("address",RES_hh_eff!$B$2),MID(CELL("filename",RES_hh_eff!$B$2),FIND("]",CELL("filename",RES_hh_eff!$B$2))+1,256)) -> RES_hh_eff | D10: System efficiency indicator of total stock
B11: =HYPERLINK("#"&CELL("address",RES_hh_emi!$B$2),MID(CELL("filename",RES_hh_emi!$B$2),FIND("]",CELL("filename",RES_hh_emi!$B$2))+1,256)) -> RES_hh_emi | D11: CO2 emissions
B12: =HYPERLINK("#"&CELL("address",RES_hh_fech!$B$2),MID(CELL("filename",RES_hh_fech!$B$2),FIND("]",CELL("filename",RES_hh_fech!$B$2))+1,256)) -> RES_hh_fech | D12: Final energy consumption per household
B13: =HYPERLINK("#"&CELL("address",RES_hh_tesh!$B$2),MID(CELL("filename",RES_hh_tesh!$B$2),FIND("]",CELL("filename",RES_hh_tesh!$B$2))+1,256)) -> RES_hh_tesh | D13: Thermal energy service per household
B14: =HYPERLINK("#"&CELL("address",RES_hh_emih!$B$2),MID(CELL("filename",RES_hh_emih!$B$2),FIND("]",CELL("filename",RES_hh_emih!$B$2))+1,256)) -> RES_hh_emih | D14: CO2 emissions per household
B15: =HYPERLINK("#"&CELL("address",RES_hh_fecs!$B$2),MID(CELL("filename",RES_hh_fecs!$B$2),FIND("]",CELL("filename",RES_hh_fecs!$B$2))+1,256)) -> RES_hh_fecs | D15: Final energy consumption per surface area
B16: =HYPERLINK("#"&CELL("address",RES_hh_tess!$B$2),MID(CELL("filename",RES_hh_tess!$B$2),FIND("]",CELL("filename",RES_hh_tess!$B$2))+1,256)) -> RES_hh_tess | D16: Thermal energy service per surface area
B17: =HYPERLINK("#"&CELL("address",RES_hh_emis!$B$2),MID(CELL("filename",RES_hh_emis!$B$2),FIND("]",CELL("filename",RES_hh_emis!$B$2))+1,256)) -> RES_hh_emis | D17: CO2 emissions per surface area
B19: Thermal uses in new and renovated households
B20: =HYPERLINK("#"&CELL("address",RES_hh_num_in!$B$2),MID(CELL("filename",RES_hh_num_in!$B$2),FIND("]",CELL("filename",RES_hh_num_in!$B$2))+1,256)) -> RES_hh_num_in | D20: Number of new and renovated households
B21: =HYPERLINK("#"&CELL("address",RES_hh_fec_in!$B$2),MID(CELL("filename",RES_hh_fec_in!$B$2),FIND("]",CELL("filename",RES_hh_fec_in!$B$2))+1,256)) -> RES_hh_fec_in | D21: Final energy consumption
B22: =HYPERLINK("#"&CELL("address",RES_hh_tes_in!$B$2),MID(CELL("filename",RES_hh_tes_in!$B$2),FIND("]",CELL("filename",RES_hh_tes_in!$B$2))+1,256)) -> RES_hh_tes_in | D22: Thermal energy service
B23: =HYPERLINK("#"&CELL("address",RES_hh_eff_in!$B$2),MID(CELL("filename",RES_hh_eff_in!$B$2),FIND("]",CELL("filename",RES_hh_eff_in!$B$2))+1,256)) -> RES_hh_eff_in | D23: System efficiency indicator of total stock
B24: =HYPERLINK("#"&CELL("address",RES_hh_emi_in!$B$2),MID(CELL("filename",RES_hh_emi_in!$B$2),FIND("]",CELL("filename",RES_hh_emi_in!$B$2))+1,256)) -> RES_hh_emi_in | D24: CO2 emissions
B25: =HYPERLINK("#"&CELL("address",RES_hh_fech_in!$B$2),MID(CELL("filename",RES_hh_fech_in!$B$2),FIND("]",CELL("filename",RES_hh_fech_in!$B$2))+1,256)) -> RES_hh_fech_in | D25: Final energy consumption per household
B26: =HYPERLINK("#"&CELL("address",RES_hh_tesh_in!$B$2),MID(CELL("filename",RES_hh_tesh_in!$B$2),FIND("]",CELL("filename",RES_hh_tesh_in!$B$2))+1,256)) -> RES_hh_tesh_in | D26: Thermal energy service per household
B27: =HYPERLINK("#"&CELL("address",RES_hh_emih_in!$B$2),MID(CELL("filename",RES_hh_emih_in!$B$2),FIND("]",CELL("filename",RES_hh_emih_in!$B$2))+1,256)) -> RES_hh_emih_in | D27: CO2 emissions per household
B28: =HYPERLINK("#"&CELL("address",RES_hh_fecs_in!$B$2),MID(CELL("filename",RES_hh_fecs_in!$B$2),FIND("]",CELL("filename",RES_hh_fecs_in!$B$2))+1,256)) -> RES_hh_fecs_in | D28: Final energy consumption per surface area
B29: =HYPERLINK("#"&CELL("address",RES_hh_tess_in!$B$2),MID(CELL("filename",RES_hh_tess_in!$B$2),FIND("]",CELL("filename",RES_hh_tess_in!$B$2))+1,256)) -> RES_hh_tess_in | D29: Thermal energy service per surface area
B30: =HYPERLINK("#"&CELL("address",RES_hh_emis_in!$B$2),MID(CELL("filename",RES_hh_emis_in!$B$2),FIND("]",CELL("filename",RES_hh_emis_in!$B$2))+1,256)) -> RES_hh_emis_in | D30: CO2 emissions per surface area
B32: Specific electric uses
B33: =HYPERLINK("#"&CELL("address",'RES_se-appl'!$B$2),MID(CELL("filename",'RES_se-appl'!$B$2),FIND("]",CELL("filename",'RES_se-appl'!$B$2))+1,256)) -> RES_se-appl | D33: Residential / specific electric uses
B34: =HYPERLINK("#"&CELL("address",RES_RF!$B$2),MID(CELL("filename",RES_RF!$B$2),FIND("]",CELL("filename",RES_RF!$B$2))+1,256)) -> RES_RF | D34: Refrigerators and freezers
B35: =HYPERLINK("#"&CELL("address",RES_WM!$B$2),MID(CELL("filename",RES_WM!$B$2),FIND("]",CELL("filename",RES_WM!$B$2))+1,256)) -> RES_WM | D35: Washing machines
B36: =HYPERLINK("#"&CELL("address",RES_DR!$B$2),MID(CELL("filename",RES_DR!$B$2),FIND("]",CELL("filename",RES_DR!$B$2))+1,256)) -> RES_DR | D36: Clothes dryers
B37: =HYPERLINK("#"&CELL("address",RES_DW!$B$2),MID(CELL("filename",RES_DW!$B$2),FIND("]",CELL("filename",RES_DW!$B$2))+1,256)) -> RES_DW | D37: Dishwashers
B38: =HYPERLINK("#"&CELL("address",RES_TV!$B$2),MID(CELL("filename",RES_TV!$B$2),FIND("]",CELL("filename",RES_TV!$B$2))+1,256)) -> RES_TV | D38: TV and multimedia
B39: =HYPERLINK("#"&CELL("address",RES_IT!$B$2),MID(CELL("filename",RES_IT!$B$2),FIND("]",CELL("filename",RES_IT!$B$2))+1,256)) -> RES_IT | D39: ICT equipment
B40: =HYPERLINK("#"&CELL("address",RES_LI!$B$2),MID(CELL("filename",RES_LI!$B$2),FIND("]",CELL("filename",RES_LI!$B$2))+1,256)) -> RES_LI | D40: Lighting
B41: =HYPERLINK("#"&CELL("address",RES_OA!$B$2),MID(CELL("filename",RES_OA!$B$2),FIND("]",CELL("filename",RES_OA!$B$2))+1,256)) -> RES_OA | D41: Other appliances (vacuum cleaners, irons etc.)
B43: Number of households - detailed structure
B44: =HYPERLINK("#"&CELL("address",RES_hhdet_num!$B$2),MID(CELL("filename",RES_hhdet_num!$B$2),FIND("]",CELL("filename",RES_hhdet_num!$B$2))+1,256)) -> RES_hhdet_num | D44: Number of households
B45: =HYPERLINK("#"&CELL("address",RES_hhdet_out!$B$2),MID(CELL("filename",RES_hhdet_out!$B$2),FIND("]",CELL("filename",RES_hhdet_out!$B$2))+1,256)) -> RES_hhdet_out | D45: Retired equipment
...

Sheet RES_summary
A1: IT - Residential sector summary | B1: 2000 | C1: 2001 | D1: 2002 | E1: 2003 | F1: 2004 | G1: 2005 | H1: 2006 | I1: 2007 | J1: 2008 | K1: 2009 | L1: 2010 | M1: 2011 | N1: 2012 | O1: 2013 | P1: 2014 | Q1: 2015 | R1: 2016 | S1: 2017 | T1: 2018 | U1: 2019 | V1: 2020 | W1: 2021 | DA1: Code
A3: Household consumption expenditure (M€ at 2015 prices) | B3: 1002734.8 | C3: 1009193.2 | D3: 1008770.2 | E3: 1015575.6 | F3: 1025443.3 | G3: 1039663.4 | H3: 1053622 | I3: 1066133.3 | J3: 1054060 | K3: 1038236.2 | L3: 1049134.5 | M3: 1049822.2 | N3: 1010821.9 | O3: 986114.34 | P3: 987840.65 | Q3: 1005936.2 | R3: 1018478.7 | S3: 1034148.9 | T3: 1043808.6 | U3: 1045967.8 | V3: 937066.54 | W3: 986430.99 | DA3: Macro.Meuro2015.IT.ConsumptionExpenditure
A4: Population (inhabitants) | B4: 56923524 | C4: 56960692 | D4: 56987507 | E4: 57130506 | F4: 57495900 | G4: 57874753 | H4: 58064214 | I4: 58223744 | J4: 58652875 | K4: 59000586 | L4: 59190143 | M4: 59364690 | N4: 59394207 | O4: 59685227 | P4: 60782668 | Q4: 60795612 | R4: 60665551 | S4: 60589445 | T4: 60483973 | U4: 59816673 | V4: 59641488 | W4: 59236213 | DA4: Macro.number.IT.Population
A6: Number of households | B6: 22309710 | C6: 22408839 | D6: 22504633 | E6: 22647215 | F6: 22879387 | G6: 23214903 | H6: 23450813 | I6: 23755098 | J6: 24047919 | K6: 24320110 | L6: 24499231 | M6: 24797281 | N6: 25039716 | O6: 25258242 | P6: 25776589 | Q6: 25887308 | R6: 25947627 | S6: 25970615 | T6: 26037009 | U6: 25950834 | V6: 25841199 | W6: 25822238 | DA6: NUM.number.IT.Res.HH
A7: Total households useful surface area (in thousand sqm) | B7: 2052400.6 | C7: 2062321 | D7: 2072065.6 | E7: 2086712.9 | F7: 2110153.1 | G7: 2143944.7 | H7: 2168407.7 | I7: 2199683 | J7: 2230405 | K7: 2260098 | L7: 2280953.4 | M7: 2314809.2 | N7: 2343717.4 | O7: 2371049.6 | P7: 2429968 | Q7: 2448023.8 | R7: 2461606.9 | S7: 2472003.2 | T7: 2487741.6 | U7: 2489117 | V7: 2488911.1 | W7: 2497963.6 | DA7: SurfaceArea.ksqm.IT.Res.HH
A8: Number of new and renovated households | B8: 0 | C8: 584123 | D8: 582943 | E8: 631813 | F8: 724503 | G8: 832894 | H8: 740582 | I8: 814085 | J8: 809236 | K8: 794972 | L8: 707819 | M8: 830642 | N8: 781506 | O8: 762868 | P8: 1067439 | Q8: 671080 | R8: 623087 | S8: 587067 | T8: 630973 | U8: 566022 | V8: 564149 | W8: 561765 | DA8: NUM.number.IT.Res.HHnew
A9: New and renovated households useful surface area (in thousand sqm) | B9: 0 | C9: 54537.751 | D9: 54560.284 | E9: 59654.561 | F9: 68732.629 | G9: 79548.308 | H9: 70890.74 | I9: 78174.72 | J9: 78230.056 | K9: 77786.728 | L9: 69493.397 | M9: 82852.052 | N9: 78500.488 | O9: 77409.339 | P9: 109432.59 | Q9: 69606.76 | R9: 65355.374 | S9: 62289.206 | T9: 67677.366 | U9: 61374.786 | V9: 61779.393 | W9: 62476.902 | DA9: SurfaceArea.ksqm.IT.Res.HHnew
A11: Actual heating degree-days | B11: 1848.2 | C11: 1877.19 | D11: 1804.77 | E11: 2007.84 | F11: 2006.05 | G11: 2162.84 | H11: 1949 | I11: 1836.76 | J11: 1896.16 | K11: 1947.26 | L11: 2074.34 | M11: 1856.24 | N11: 1952.79 | O11: 1932.55 | P11: 1631.87 | Q11: 1808.06 | R11: 1766.12 | S11: 1879.86 | T11: 1746.84 | U11: 1813.91 | V11: 1750.4 | W11: 1916.57 | DA11: HDD.Celsius.IT.Actual
A12: Mean heating degree-days over period 2000 - 2020 | B12: =AVERAGE($B11:$V11) -> 1883.2881 | C12: =AVERAGE($B11:$V11) -> 1883.2881 | D12: =AVERAGE($B11:$V11) -> 1883.2881 | E12: =AVERAGE($B11:$V11) -> 1883.2881 | F12: =AVERAGE($B11:$V11) -> 1883.2881 | G12: =AVERAGE($B11:$V11) -> 1883.2881 | H12: =AVERAGE($B11:$V11) -> 1883.2881 | I12: =AVERAGE($B11:$V11) -> 1883.2881 | ... W12: =AVERAGE($B11:$V11) -> 1883.2881 | DA12: HDD.Celsius.IT.Mean
A13: Relative heating degree-days | B13: =B11/B12 -> 0.98136871 | C13: =C11/C12 -> 0.996762 | D13: =D11/D12 -> 0.95830797 | E13: =E11/E12 -> 1.0661353 | F13: =F11/F12 -> 1.0651849 | G13: =G11/G12 -> 1.1484382 | H13: =H11/H12 -> 1.0348921 | I13: =I11/I12 -> 0.97529422 | ... W13: =W11/W12 -> 1.0176722 | DA13: HDD.ratio.IT.Relative
A15: Indicators
A17: Households size (inhabitants/household) | B17: =B4/B6 -> 2.5515134 | C17: =C4/C6 -> 2.541885 | D17: =D4/D6 -> 2.5322567 | E17: =E4/E6 -> 2.5226283 | F17: =F4/F6 -> 2.513 | G17: =G4/G6 -> 2.493 | H17: =H4/H6 -> 2.476 | I17: =I4/I6 -> 2.4509999 | ... W17: =W4/W6 -> 2.294
A18: Households useful surface area (in sqm/capita) | B18: =B7*1000/B4 -> 36.055404 | C18: =C7*1000/C4 -> 36.206038 | D18: =D7*1000/D4 -> 36.359997 | E18: =E7*1000/E4 -> 36.525371 | F18: =F7*1000/F4 -> 36.700932 | G18: =G7*1000/G4 -> 37.044559 | H18: =H7*1000/H4 -> 37.344994 | I18: =I7*1000/I4 -> 37.779827 | ... W18: =W7*1000/W4 -> 42.169535
A19: Households useful surface area (in sqm/household) | B19: =B7*1000/B6 -> 91.995846 | C19: =C7*1000/C6 -> 92.031585 | D19: =D7*1000/D6 -> 92.072844 | E19: =E7*1000/E6 -> 92.139934 | F19: =F7*1000/F6 -> 92.229443 | G19: =G7*1000/G6 -> 92.352086 | H19: =H7*1000/H6 -> 92.466207 | I19: =I7*1000/I6 -> 92.598354 | ... W19: =W7*1000/W6 -> 96.736912
A20: New and renovated households useful surface area (in sqm/capita) | B20: =IF(SUM(B21)=0,"",B21/B17) | C20: =IF(SUM(C21)=0,"",C21/C17) -> 36.731361 | D20: =IF(SUM(D21)=0,"",D21/D17) -> 36.960923 | E20: =IF(SUM(E21)=0,"",E21/E17) -> 37.428449 | F20: =IF(SUM(F21)=0,"",F21/F17) -> 37.751158 | G20: =IF(SUM(G21)=0,"",G21/G17) -> 38.310599 | H20: =IF(SUM(H21)=0,"",H21/H17) -> 38.660344 | I20: =IF(SUM(I21)=0,"",I21/I17) -> 39.178994 | ... W20: =IF(SUM(W21)=0,"",W21/W17) -> 48.480982
A21: New and renovated households useful surface area (in sqm/household) | B21: =IF(SUM(B9)=0,"",B9*1000/B8) | C21: =IF(SUM(C9)=0,"",C9*1000/C8) -> 93.366895 | D21: =IF(SUM(D9)=0,"",D9*1000/D8) -> 93.594543 | E21: =IF(SUM(E9)=0,"",E9*1000/E8) -> 94.418065 | F21: =IF(SUM(F9)=0,"",F9*1000/F8) -> 94.86866 | G21: =IF(SUM(G9)=0,"",G9*1000/G8) -> 95.508322 | H21: =IF(SUM(H9)=0,"",H9*1000/H8) -> 95.723013 | I21: =IF(SUM(I9)=0,"",I9*1000/I8) -> 96.027712 | ... W21: =IF(SUM(W9)=0,"",W9*1000/W8) -> 111.21537
A22: Household consumption expenditure per capita (€ at 2015 prices) | B22: =B3*1000000/B4 -> 17615.472 | C22: =C3*1000000/C4 -> 17717.361 | D22: =D3*1000000/D4 -> 17701.602 | E22: =E3*1000000/E4 -> 17776.416 | F22: =F3*1000000/F4 -> 17835.068 | G22: =G3*1000000/G4 -> 17964.024 | H22: =H3*1000000/H4 -> 18145.807 | I22: =I3*1000000/I4 -> 18310.972 | ... W22: =W3*1000000/W4 -> 16652.499
A23: Household consumption expenditure per household (€ at 2015 prices) | B23: =B3*1000000/B6 -> 44946.114 | C23: =C3*1000000/C6 -> 45035.496 | D23: =D3*1000000/D6 -> 44825 | E23: =E3*1000000/E6 -> 44843.291 | F23: =F3*1000000/F6 -> 44819.527 | G23: =G3*1000000/G6 -> 44784.311 | H23: =H3*1000000/H6 -> 44929.02 | I23: =I3*1000000/I6 -> 44880.192 | ... W23: =W3*1000000/W6 -> 38200.833
A24: Consumption expenditure per household relative to the EU average | B24: 1.3741548 | C24: 1.3599729 | D24: 1.3474781 | E24: 1.3406225 | F24: 1.3235983 | G24: 1.3022248 | H24: 1.2881453 | I24: 1.2695417 | J24: 1.2474296 | K24: 1.2380665 | L24: 1.2387433 | M24: 1.2230777 | N24: 1.1851862 | O24: 1.1590764 | P24: 1.1354928 | Q24: 1.1359591 | R24: 1.1277531 | S24: 1.1243192 | T24: 1.1162642 | U24: 1.1095943 | V24: 1.0776311 | W24: 1.0874349
A26: Energy consumption
A28: Energy consumption by fuel - Eurostat structure (ktoe) | B28: 27591.928 | C28: 28907.182 | D28: 28741.859 | E28: 31590.488 | F28: 31425.185 | G28: 33921.569 | H28: 32423.683 | I28: 32339.575 | J28: 33611.747 | K28: 34040.636 | L28: 35392.912 | M28: 32378.064 | N28: 34348.336 | O28: 34230.62 | P28: 29545.98 | Q28: 32494.483 | R28: 32185.101 | S28: 32796.92 | T28: 31805.895 | U28: 31042.208 | V28: 30560.678 | W28: 30817.068 | DA28: FEC.ktoe.IT.ES.Res
A29: Solids | B29: 64.912554 | C29: 74.712984 | D29: 16.815993 | E29: 16.816079 | F29: 7.6202064 | G29: 6.9852107 | H29: 6.9852107 | I29: 5.4985383 | J29: 4.266896 | K29: 3.6646604 | L29: 3.6261393 | M29: 3.6199484 | N29: 2.4197764 | O29: 0 | P29: 0 | Q29: 0 | R29: 0 | S29: 0 | T29: 0 | U29: 0 | V29: 0 | W29: 0 | DA29: FEC.ktoe.IT.ES.Res.Solids
A30: Liquids | B30: 6006.5301 | C30: 6451.3232 | D30: 5837.4463 | E30: 5204.4711 | F30: 5338.115 | G30: 5323.6791 | H30: 4714.2448 | I30: 3922.7859 | J30: 3940.2169 | K30: 3789.228 | L30: 3325.3893 | M30: 3079.2873 | N30: 2808.9854 | O30: 2708.9662 | P30: 2242.9732 | Q30: 2374.6058 | R30: 2289.5482 | S30: 2087.4673 | T30: 2199.7291 | U30: 1975.6692 | V30: 1871.2633 | W30: 1878.0847
A31: Liquified petroleum gas (LPG) | B31: 1528.2794 | C31: 1505.2069 | D31: 1474.4435 | E31: 1537.0689 | F31: 1500.812 | G31: 1551.3518 | H31: 1427.1997 | I31: 1357.9822 | J31: 1457.9631 | K31: 1382.1534 | L31: 1371.1666 | M31: 1244.817 | N31: 1206.3629 | O31: 1192.0799 | P31: 1080.0134 | Q31: 1085.5068 | R31: 1118.4676 | S31: 1147.7972 | T31: 1116.09 | U31: 1118.3225 | V31: 1100.6205 | W31: 1154.7672 | DA31: FEC.ktoe.IT.ES.Res.LPG
A32: Diesel oil and other liquids (without biofuels) | B32: 4478.2507 | C32: 4946.1163 | D32: 4363.0028 | E32: 3667.4022 | F32: 3837.3029 | G32: 3772.3273 | H32: 3287.0451 | I32: 2564.8037 | J32: 2482.2537 | K32: 2407.0746 | L32: 1954.2228 | M32: 1834.4702 | N32: 1602.6225 | O32: 1516.8863 | P32: 1162.9598 | Q32: 1289.0991 | R32: 1171.0806 | S32: 939.67016 | T32: 1083.639 | U32: 857.34669 | V32: 770.64282 | W32: 723.31745 | DA32: FEC.ktoe.IT.ES.Res.Oil
A33: Natural gas | B33: 14974.785 | C33: 15746.389 | D33: 15300.881 | E33: 17272.807 | F33: 17936.887 | G33: 18745.787 | H33: 17016.917 | I33: 15942.068 | J33: 16014.746 | K33: 16820.701 | L33: 18697.592 | M33: 17989.639 | N33: 18116.552 | O33: 18073.087 | P33: 15150.838 | Q33: 16985.555 | R33: 17097.463 | S33: 17260.611 | T33: 16499.391 | U33: 16126.645 | V33: 15932.597 | W33: 15479.77 | DA33: FEC.ktoe.IT.ES.Res.NG
A34: Renewable energies and wastes | B34: 1291.0145 | C34: 1342.1515 | D34: 2173.3878 | E34: 3506.0237 | F34: 2260.6907 | G34: 3928.7378 | H34: 4726.3542 | I34: 6555.995 | J34: 7728.8668 | K34: 7448.9586 | L34: 7263.4805 | M34: 4706.9218 | N34: 6753.8264 | O34: 6758.5459 | P34: 5808.8517 | Q34: 6534.8619 | R34: 6322.2747 | S34: 7014.4313 | T34: 6513.9759 | U34: 6508.5844 | V34: 6289.3332 | W34: 7594.2752
A35: Biomass and waste | B35: 1280.2187 | C35: 1330.3525 | D35: 2160.108 | E35: 3491.1436 | F35: 2243.9715 | G35: 3905.1399 | H35: 4658.928 | I35: 6474.1187 | J35: 7674.4578 | K35: 7380.4815 | L35: 7162.8786 | M35: 4601.7101 | N35: 6637.3651 | O35: 6632.698 | P35: 5675.5279 | Q35: 6393.4652 | R35: 6173.3304 | S35: 6757.3409 | T35: 6251.6962 | U35: 6242.8244 | V35: 6012.9586 | W35: 6793.5034 | DA35: FEC.ktoe.IT.ES.Res.Biomass_Waste
A36: Biogas | B36: 0 | C36: 0 | D36: 0 | E36: 0 | F36: 0 | G36: 0 | H36: 0 | I36: 0 | J36: 0 | K36: 0 | L36: 0 | M36: 0 | N36: 0 | O36: 0 | P36: 0 | Q36: 0 | R36: 0 | S36: 0 | T36: 0 | U36: 0 | V36: 0 | W36: 0 | DA36: FEC.ktoe.IT.ES.Res.Biogas
A37: Liquid biofuels | B37: 0 | C37: 0 | D37: 0 | E37: 0 | F37: 0 | G37: 0 | H37: 38.000344 | I37: 38.884093 | J37: 0 | K37: 0 | L37: 0 | M37: 0 | N37: 0 | O37: 0 | P37: 0 | Q37: 0 | R37: 0 | S37: 0 | T37: 0 | U37: 0 | V37: 0 | W37: 0 | DA37: FEC.ktoe.IT.ES.Res.LiqBio
A38: Solar | B38: 8.4790198 | C38: 9.4343938 | D38: 10.915219 | E38: 12.515563 | F38: 14.402408 | G38: 21.281169 | H38: 27.109028 | I38: 40.675494 | J38: 52.092261 | K38: 66.160275 | L38: 99.264316 | M38: 103.87412 | N38: 114.93267 | O38: 124.43869 | P38: 132.86999 | Q38: 140.53689 | R38: 148.06053 | S38: 154.49106 | T38: 161.63181 | U38: 168.6804 | V38: 180.18349 | W38: 188.95692 | DA38: FEC.ktoe.IT.ES.Res.Solar
A39: Geothermal | B39: 2.316767 | C39: 2.3645744 | D39: 2.3645744 | E39: 2.3645744 | F39: 2.316767 | G39: 2.316767 | H39: 2.316767 | I39: 2.316767 | J39: 2.316767 | K39: 2.316767 | L39: 1.3375752 | M39: 1.3375752 | N39: 1.5286328 | O39: 1.4092003 | P39: 0.45382631 | Q39: 0.85984523 | R39: 0.88374893 | S39: 0.88039553 | T39: 0.98400688 | U39: 0.95245056 | V39: 0.87764402 | W39: 0.83817713 | DA39: FEC.ktoe.IT.ES.Res.Geo
A40: Ambient heat | B40: 1.1441001 | C40: 1.6054548 | D40: 2.2675935 | E40: 3.7231789 | F40: 6.7023623 | G40: 11.714628 | H40: 12.394563 | I40: 15.634433 | J40: 20.914837 | K40: 29.343552 | L40: 49.117782 | M40: 57.47305 | N40: 69.911562 | O40: 80.310923 | P40: 63.636872 | Q40: 81.67694 | R40: 88.419896 | S40: 101.71892 | T40: 99.663887 | U40: 96.127085 | V40: 95.3135 | W40: 610.97678 | DA40: FEC.ktoe.IT.ES.Res.Ambient
A41: Distributed heat | B41: 0 | C41: 0 | D41: 0 | E41: 0 | F41: 155.99028 | G41: 158.85641 | H41: 143.61806 | I41: 133.34764 | J41: 43.25503 | K41: 51.686242 | L41: 122.59957 | M41: 567.64119 | N41: 694.32502 | O41: 930.51969 | P41: 818.3816 | Q41: 908.40258 | R41: 946.66569 | S41: 904.94239 | T41: 1091.6215 | U41: 887.8828 | V41: 869.6215 | W41: 710.45752 | DA41: FEC.ktoe.IT.ES.Res.Steam_Distr
A42: Electricity | B42: 5254.6862 | C42: 5292.6053 | D42: 5413.3276 | E42: 5590.3697 | F42: 5725.8813 | G42: 5757.5236 | H42: 5815.5632 | I42: 5779.8796 | J42: 5880.3955 | K42: 5926.3972 | L42: 5980.2236 | M42: 6030.9544 | N42: 5972.227 | O42: 5759.5013 | P42: 5524.9355 | Q42: 5691.0576 | R42: 5529.1488 | S42: 5631.1864 | T42: 5600.8422 | U42: 5639.5531 | V42: 5693.177 | W42: 5765.4574 | DA42: FEC.ktoe.IT.ES.Res.Elec
A44: Energy consumption by end-uses (ktoe) | B44: =SUM(B45,B50) -> 27591.928 | C44: =SUM(C45,C50) -> 28907.182 | D44: =SUM(D45,D50) -> 28741.859 | E44: =SUM(E45,E50) -> 31590.488 | F44: =SUM(F45,F50) -> 31425.185 | G44: =SUM(G45,G50) -> 33921.569 | H44: =SUM(H45,H50) -> 32423.683 | I44: =SUM(I45,I50) -> 32339.575 | ... W44: =SUM(W45,W50) -> 30817.068 | DA44: FEC.ktoe.IT.Res.HH
A45: Thermal uses | B45: =SUM(B46:B49) -> 24217.459 | C45: =SUM(C46:C49) -> 25494.291 | D45: =SUM(D46:D49) -> 25297.24 | E45: =SUM(E46:E49) -> 28107.414 | F45: =SUM(F46:F49) -> 27886.952 | G45: =SUM(G46:G49) -> 30317.375 | H45: =SUM(H46:H49) -> 28750.947 | I45: =SUM(I46:I49) -> 28576.755 | ... W45: =SUM(W46:W49) -> 26592.634 | DA45: FEC.ktoe.IT.Res.HH.Thermal
A46: Space heating | B46: 18161.284 | C46: 19367.542 | D46: 19124.356 | E46: 21881.342 | F46: 21722.053 | G46: 24182.811 | H46: 22633.211 | I46: 22837.101 | J46: 24396.965 | K46: 24547.965 | L46: 25621.2 | M46: 22457.072 | N46: 24605.511 | O46: 24599.152 | P46: 20227.843 | Q46: 23002.891 | R46: 22791.832 | S46: 23153.753 | T46: 22198.923 | U46: 21493.339 | V46: 20947.131 | W46: 21819.534 | DA46: FEC.ktoe.IT.Res.HH.Thermal.SH
A47: Cooling | B47: 67.348167 | C47: 83.899502 | D47: 72.073478 | E47: 233.66474 | F47: 98.162402 | G47: 103.5606 | H47: 140.64804 | I47: 137.8975 | J47: 182.73976 | K47: 199.26098 | L47: 159.86503 | M47: 181.57302 | N47: 296.28665 | O47: 179.64448 | P47: 132.15016 | Q47: 271.00834 | R47: 188.15993 | S47: 277.90138 | T47: 214.01478 | U47: 263.64885 | V47: 206.10507 | W47: 250.08816 | DA47: FEC.ktoe.IT.Res.HH.Thermal.SC
A48: Water heating | B48: 4134.713 | C48: 4164.271 | D48: 4200.2306 | E48: 4114.6411 | F48: 4119.3311 | G48: 4130.4139 | H48: 4083.1051 | I48: 3888.2437 | J48: 3619.0093 | K48: 3746.5393 | L48: 3998.8315 | M48: 4111.0263 | N48: 4038.3067 | O48: 3952.2706 | P48: 3743.0214 | Q48: 3772.8981 | R48: 3786.8469 | S48: 3715.2807 | T48: 3705.7393 | U48: 3574.9869 | V48: 3469.6517 | W48: 2927.2641 | DA48: FEC.ktoe.IT.Res.HH.Thermal.WH
...

Sheet RES_hh_num
A1: IT - Number of households | B1: 2000 | C1: 2001 | D1: 2002 | E1: 2003 | F1: 2004 | G1: 2005 | H1: 2006 | I1: 2007 | J1: 2008 | K1: 2009 | L1: 2010 | M1: 2011 | N1: 2012 | O1: 2013 | P1: 2014 | Q1: 2015 | R1: 2016 | S1: 2017 | T1: 2018 | U1: 2019 | V1: 2020 | W1: 2021 | DA1: Code
A3: Stock of households | B3: =B4 -> 22309710 | C3: =C4 -> 22408839 | D3: =D4 -> 22504633 | E3: =E4 -> 22647215 | F3: =F4 -> 22879387 | G3: =G4 -> 23214903 | H3: =H4 -> 23450813 | I3: =I4 -> 23755098 | ... W3: =W4 -> 25822238 | DA3: NUM.number.IT.Res.HH.Thermal
A4: Space heating | B4: =SUM(B5:B13) -> 22309710 | C4: =SUM(C5:C13) -> 22408839 | D4: =SUM(D5:D13) -> 22504633 | E4: =SUM(E5:E13) -> 22647215 | F4: =SUM(F5:F13) -> 22879387 | G4: =SUM(G5:G13) -> 23214903 | H4: =SUM(H5:H13) -> 23450813 | I4: =SUM(I5:I13) -> 23755098 | ... W4: =SUM(W5:W13) -> 25822238 | DA4: NUM.number.IT.Res.HH.Thermal.SH
A5: Solids | B5: 100497 | C5: 83072 | D5: 45342 | E5: 26021 | F5: 12458 | G5: 9139 | H5: 7336 | I5: 6111 | J5: 4932 | K5: 4112 | L5: 3617 | M5: 3110 | N5: 2068 | O5: 0 | P5: 0 | Q5: 0 | R5: 0 | S5: 0 | T5: 0 | U5: 0 | V5: 0 | W5: 0 | DA5: NUM.number.IT.Res.HH.Thermal.SH.Solids
A6: Liquified petroleum gas (LPG) | B6: 1149936 | C6: 1103905 | D6: 1042572 | E6: 977845 | F6: 922216 | G6: 890853 | H6: 873070 | I6: 865146 | J6: 863779 | K6: 835497 | L6: 796221 | M6: 757994 | N6: 740607 | O6: 743687 | P6: 748642 | Q6: 749755 | R6: 752426 | S6: 753348 | T6: 761220 | U6: 776133 | V6: 788101 | W6: 792121 | DA6: NUM.number.IT.Res.HH.Thermal.SH.LPG
A7: Diesel oil | B7: 4648383 | C7: 4502732 | D7: 3993489 | E7: 3426999 | F7: 3097308 | G7: 2765685 | H7: 2485913 | I7: 2121004 | J7: 1847774 | K7: 1666446 | L7: 1494689 | M7: 1425406 | N7: 1317351 | O7: 1269067 | P7: 1196697 | Q7: 1128444 | R7: 1041673 | S7: 935774 | T7: 891087 | U7: 795933 | V7: 704361 | W7: 645409 | DA7: NUM.number.IT.Res.HH.Thermal.SH.Oil
A8: Natural gas | B8: 14442801 | C8: 14508800 | D8: 14551516 | E8: 14852321 | F8: 15065850 | G8: 14899849 | H8: 14353420 | I8: 13861494 | J8: 14221524 | K8: 14632500 | L8: 14867233 | M8: 15107142 | N8: 15389799 | O8: 15559758 | P8: 15831613 | Q8: 15875934 | R8: 15922356 | S8: 15893849 | T8: 15965509 | U8: 15767709 | V8: 15609280 | W8: 15168177 | DA8: NUM.number.IT.Res.HH.Thermal.SH.Gas
A9: Biomass | B9: 1376409 | C9: 1642425 | D9: 2316250 | E9: 2813338 | F9: 3086231 | G9: 3956467 | H9: 5057083 | I9: 6258102 | J9: 6459180 | K9: 6455851 | L9: 6481357 | M9: 6346336 | N9: 6243427 | O9: 6210149 | P9: 6482714 | Q9: 6578956 | R9: 6647041 | S9: 6819563 | T9: 6873443 | U9: 7008183 | V9: 7086972 | W9: 7238501 | DA9: NUM.number.IT.Res.HH.Thermal.SH.Biomass
A10: Geothermal | B10: 3615 | C10: 3551 | D10: 3386 | E10: 3152 | F10: 2998 | G10: 2863 | H10: 2846 | I10: 2804 | J10: 2621 | K10: 2350 | L10: 1888 | M10: 1715 | N10: 1539 | O10: 1367 | P10: 1048 | Q10: 1012 | R10: 1022 | S10: 1040 | T10: 1041 | U10: 1036 | V10: 1043 | W10: 1019 | DA10: NUM.number.IT.Res.HH.Thermal.SH.Geo
A11: Distributed heat | B11: 0 | C11: 0 | D11: 0 | E11: 0 | F11: 139247 | G11: 140777 | H11: 149776 | I11: 137604 | J11: 146598 | K11: 195499 | L11: 283653 | M11: 560046 | N11: 764186 | O11: 943332 | P11: 1025404 | Q11: 1057843 | R11: 1088229 | S11: 1092686 | T11: 1087106 | U11: 1066840 | V11: 989373 | W11: 934432 | DA11: NUM.number.IT.Res.HH.Thermal.SH.DistrHeat
A12: Advanced electric heating | B12: 13276 | C12: 15290 | D12: 20017 | E12: 27130 | F12: 37407 | G12: 48580 | H12: 57413 | I12: 67852 | J12: 83679 | K12: 109046 | L12: 142303 | M12: 173292 | N12: 193118 | O12: 207364 | P12: 214489 | Q12: 227744 | R12: 240338 | S12: 251606 | T12: 252287 | U12: 356854 | V12: 514747 | W12: 975418 | DA12: NUM.number.IT.Res.HH.Thermal.SH.AdvElc
A13: Conventional electric heating | B13: 574793 | C13: 549064 | D13: 532061 | E13: 520409 | F13: 515672 | G13: 500690 | H13: 463956 | I13: 434981 | J13: 417832 | K13: 418809 | L13: 428270 | M13: 422240 | N13: 387621 | O13: 323518 | P13: 275982 | Q13: 267620 | R13: 254542 | S13: 222749 | T13: 205316 | U13: 178146 | V13: 147322 | W13: 67161 | DA13: NUM.number.IT.Res.HH.Thermal.SH.ConvElc
A14: Circulation | B14: =SUM(B5:B11) -> 21721641 | C14: =SUM(C5:C11) -> 21844485 | D14: =SUM(D5:D11) -> 21952555 | E14: =SUM(E5:E11) -> 22099676 | F14: =SUM(F5:F11) -> 22326308 | G14: =SUM(G5:G11) -> 22665633 | H14: =SUM(H5:H11) -> 22929444 | I14: =SUM(I5:I11) -> 23252265 | ... W14: =SUM(W5:W11) -> 24779659
A15: Space cooling | B15: =B16 -> 2185984 | C15: =C16 -> 2402231 | D15: =D16 -> 3041577 | E15: =E16 -> 3874805 | F15: =F16 -> 4347819 | G15: =G16 -> 4851300 | H15: =H16 -> 5344334 | I15: =I16 -> 6030057 | ... W15: =W16 -> 12549893 | DA15: NUM.number.IT.Res.HH.Thermal.SC
A16: Air conditioning | B16: 2185984 | C16: 2402231 | D16: 3041577 | E16: 3874805 | F16: 4347819 | G16: 4851300 | H16: 5344334 | I16: 6030057 | J16: 6851543 | K16: 7490701 | L16: 7815712 | M16: 8184672 | N16: 8715177 | O16: 9244018 | P16: 9484777 | Q16: 9628345 | R16: 10015445 | S16: 10362864 | T16: 11144030 | U16: 11769750 | V16: 12377715 | W16: 12549893 | DA16: NUM.number.IT.Res.HH.Thermal.SC.AC
A17: Water heating | B17: =SUM(B18:B25) -> 22309710 | C17: =SUM(C18:C25) -> 22408839 | D17: =SUM(D18:D25) -> 22504633 | E17: =SUM(E18:E25) -> 22647215 | F17: =SUM(F18:F25) -> 22879387 | G17: =SUM(G18:G25) -> 23214903 | H17: =SUM(H18:H25) -> 23450813 | I17: =SUM(I18:I25) -> 23755098 | ... W17: =SUM(W18:W25) -> 25822238 | DA17: NUM.number.IT.Res.HH.Thermal.WH
A18: Solids | B18: 0 | C18: 0 | D18: 0 | E18: 0 | F18: 0 | G18: 0 | H18: 0 | I18: 0 | J18: 0 | K18: 0 | L18: 0 | M18: 0 | N18: 0 | O18: 0 | P18: 0 | Q18: 0 | R18: 0 | S18: 0 | T18: 0 | U18: 0 | V18: 0 | W18: 0 | DA18: NUM.number.IT.Res.HH.Thermal.WH.Solids
A19: Liquified petroleum gas (LPG) | B19: 1502272 | C19: 1510721 | D19: 1553365 | E19: 1605752 | F19: 1615275 | G19: 1605787 | H19: 1568725 | I19: 1488152 | J19: 1453640 | K19: 1439821 | L19: 1442046 | M19: 1442407 | N19: 1371576 | O19: 1288309 | P19: 1218692 | Q19: 1213458 | R19: 1256447 | S19: 1327679 | T19: 1389710 | U19: 1460018 | V19: 1536067 | W19: 1653796 | DA19: NUM.number.IT.Res.HH.Thermal.WH.LPG
A20: Diesel oil | B20: 2523883 | C20: 2418134 | D20: 2218243 | E20: 2047196 | F20: 1977168 | G20: 1847915 | H20: 1721082 | I20: 1542628 | J20: 1402284 | K20: 1255679 | L20: 1076390 | M20: 976557 | N20: 874205 | O20: 835268 | P20: 801877 | Q20: 761553 | R20: 717286 | S20: 665853 | T20: 655400 | U20: 603669 | V20: 558560 | W20: 555240 | DA20: NUM.number.IT.Res.HH.Thermal.WH.Oil
A21: Natural gas | B21: 12506676 | C21: 12597479 | D21: 12522659 | E21: 12525635 | F21: 12272820 | G21: 12501610 | H21: 12591027 | I21: 12947994 | J21: 13233549 | K21: 13678418 | L21: 14014716 | M21: 14189325 | N21: 14537399 | O21: 14766555 | P21: 15228873 | Q21: 15437807 | R21: 15546861 | S21: 15563134 | T21: 15575077 | U21: 15425975 | V21: 15273148 | W21: 14904756 | DA21: NUM.number.IT.Res.HH.Thermal.WH.Gas
A22: Biomass | B22: 247404 | C22: 302905 | D22: 433447 | E22: 546256 | F22: 671966 | G22: 815508 | H22: 983163 | I22: 1102862 | J22: 1212388 | K22: 1273376 | L22: 1347377 | M22: 1431249 | N22: 1509534 | O22: 1580047 | P22: 1654144 | Q22: 1675185 | R22: 1680406 | S22: 1716714 | T22: 1709075 | U22: 1775641 | V22: 1850827 | W22: 2062405 | DA22: NUM.number.IT.Res.HH.Thermal.WH.Biomass
A23: Geothermal | B23: 1985 | C23: 1988 | D23: 2020 | E23: 2009 | F23: 1984 | G23: 1958 | H23: 1970 | I23: 1987 | J23: 1936 | K23: 1742 | L23: 1370 | M23: 1218 | N23: 1090 | O23: 987 | P23: 817 | Q23: 805 | R23: 814 | S23: 816 | T23: 850 | U23: 872 | V23: 877 | W23: 903 | DA23: NUM.number.IT.Res.HH.Thermal.WH.Geo
A24: Distributed heat | B24: 0 | C24: 0 | D24: 0 | E24: 0 | F24: 114146 | G24: 112134 | H24: 124108 | I24: 121378 | J24: 123578 | K24: 134445 | L24: 176508 | M24: 501473 | N24: 692017 | O24: 868732 | P24: 961915 | Q24: 997295 | R24: 1022764 | S24: 1021970 | T24: 989192 | U24: 952427 | V24: 838818 | W24: 803162 | DA24: NUM.number.IT.Res.HH.Thermal.WH.DistrHeat
A25: Electricity | B25: 5527490 | C25: 5577612 | D25: 5774899 | E25: 5920367 | F25: 6226028 | G25: 6329991 | H25: 6460738 | I25: 6550097 | J25: 6620544 | K25: 6536629 | L25: 6440824 | M25: 6255052 | N25: 6053895 | O25: 5918344 | P25: 5910271 | Q25: 5801205 | R25: 5723049 | S25: 5674449 | T25: 5717705 | U25: 5732232 | V25: 5782902 | W25: 5841976 | DA25: NUM.number.IT.Res.HH.Thermal.WH.Elc
A26: Solar | B26: 101155 | C26: 111535 | D26: 127100 | E26: 148414 | F26: 169810 | G26: 251364 | H26: 322978 | I26: 507862 | J26: 696718 | K26: 853583 | L26: 1185893 | M26: 1196886 | N26: 1318062 | O26: 1463272 | P26: 1695025 | Q26: 1706618 | R26: 1766176 | S26: 1847304 | T26: 1901659 | U26: 2022917 | V26: 2189874 | W26: 2680854 | DA26: NUM.number.IT.Res.HH.Thermal.WH.Solar
A27: Cooking | B27: =SUM(B28:B32) -> 22309710 | C27: =SUM(C28:C32) -> 22408839 | D27: =SUM(D28:D32) -> 22504633 | E27: =SUM(E28:E32) -> 22647215 | F27: =SUM(F28:F32) -> 22879387 | G27: =SUM(G28:G32) -> 23214903 | H27: =SUM(H28:H32) -> 23450813 | I27: =SUM(I28:I32) -> 23755098 | ... W27: =SUM(W28:W32) -> 25822238 | DA27: NUM.number.IT.Res.HH.Thermal.CO
A28: Solids | B28: 0 | C28: 0 | D28: 0 | E28: 0 | F28: 0 | G28: 0 | H28: 0 | I28: 0 | J28: 0 | K28: 0 | L28: 0 | M28: 0 | N28: 0 | O28: 0 | P28: 0 | Q28: 0 | R28: 0 | S28: 0 | T28: 0 | U28: 0 | V28: 0 | W28: 0 | DA28: NUM.number.IT.Res.HH.Thermal.CO.Solids
A29: Liquified petroleum gas (LPG) | B29: 3091375 | C29: 3002635 | D29: 2968398 | E29: 2950763 | F29: 2968803 | G29: 2961020 | H29: 2995127 | I29: 3082429 | J29: 3204898 | K29: 3208541 | L29: 3210548 | M29: 3225712 | N29: 3285346 | O29: 3306333 | P29: 3417204 | Q29: 3350898 | R29: 3308142 | S29: 3183313 | T29: 3135474 | U29: 3082202 | V29: 3039562 | W29: 3113390 | DA29: NUM.number.IT.Res.HH.Thermal.CO.LPG
A30: Natural gas | B30: 13917834 | C30: 13881041 | D30: 13798525 | E30: 13809650 | F30: 13616324 | G30: 13791156 | H30: 13473350 | I30: 13289709 | J30: 13299204 | K30: 13741595 | L30: 14292649 | M30: 14775541 | N30: 14979179 | O30: 15010554 | P30: 15424835 | Q30: 15485788 | R30: 15545917 | S30: 15511628 | T30: 15531724 | U30: 15371644 | V30: 15197309 | W30: 14759015 | DA30: NUM.number.IT.Res.HH.Thermal.CO.Gas
A31: Biomass | B31: 115780 | C31: 136116 | D31: 167479 | E31: 197005 | F31: 241624 | G31: 315832 | H31: 414218 | I31: 533547 | J31: 617827 | K31: 650752 | L31: 654693 | M31: 650070 | N31: 671501 | O31: 708406 | P31: 764302 | Q31: 774460 | R31: 756311 | S31: 724672 | T31: 688355 | U31: 672657 | V31: 667580 | W31: 668868 | DA31: NUM.number.IT.Res.HH.Thermal.CO.Biomass
A32: Electricity | B32: 5184721 | C32: 5389047 | D32: 5570231 | E32: 5689797 | F32: 6052636 | G32: 6146895 | H32: 6568118 | I32: 6849413 | J32: 6925990 | K32: 6719222 | L32: 6341341 | M32: 6145958 | N32: 6103690 | O32: 6232949 | P32: 6170248 | Q32: 6276162 | R32: 6337257 | S32: 6551002 | T32: 6681456 | U32: 6824331 | V32: 6936748 | W32: 7280965 | DA32: NUM.number.IT.Res.HH.Thermal.CO.Elc

Sheet RES_hh_fec
A1: IT - Final energy consumption | B1: 2000 | C1: 2001 | D1: 2002 | E1: 2003 | F1: 2004 | G1: 2005 | H1: 2006 | I1: 2007 | J1: 2008 | K1: 2009 | L1: 2010 | M1: 2011 | N1: 2012 | O1: 2013 | P1: 2014 | Q1: 2015 | R1: 2016 | S1: 2017 | T1: 2018 | U1: 2019 | V1: 2020 | W1: 2021 | DA1: Code
A3: Final energy consumption (ktoe) | B3: =SUM(B4,B15,B17,B27) -> 24217.459 | C3: =SUM(C4,C15,C17,C27) -> 25494.291 | D3: =SUM(D4,D15,D17,D27) -> 25297.24 | E3: =SUM(E4,E15,E17,E27) -> 28107.414 | F3: =SUM(F4,F15,F17,F27) -> 27886.952 | G3: =SUM(G4,G15,G17,G27) -> 30317.375 | H3: =SUM(H4,H15,H17,H27) -> 28750.947 | I3: =SUM(I4,I15,I17,I27) -> 28576.755 | ... W3: =SUM(W4,W15,W17,W27) -> 26592.634 | DA3: FEC.ktoe.IT.Res.HH.Thermal
A4: Space heating | B4: =SUM(B5:B14) -> 18161.284 | C4: =SUM(C5:C14) -> 19367.542 | D4: =SUM(D5:D14) -> 19124.356 | E4: =SUM(E5:E14) -> 21881.342 | F4: =SUM(F5:F14) -> 21722.053 | G4: =SUM(G5:G14) -> 24182.811 | H4: =SUM(H5:H14) -> 22633.211 | I4: =SUM(I5:I14) -> 22837.101 | ... W4: =SUM(W5:W14) -> 21819.534 | DA4: FEC.ktoe.IT.Res.HH.Thermal.SH
A5: Solids | B5: 64.912554 | C5: 74.712984 | D5: 16.815993 | E5: 16.816079 | F5: 7.6202064 | G5: 6.9852107 | H5: 6.9852107 | I5: 5.4985383 | J5: 4.266896 | K5: 3.6646604 | L5: 3.6261393 | M5: 3.6199484 | N5: 2.4197764 | O5: 0 | P5: 0 | Q5: 0 | R5: 0 | S5: 0 | T5: 0 | U5: 0 | V5: 0 | W5: 0 | DA5: FEC.ktoe.IT.Res.HH.Thermal.SH.Solids.Solids
A6: Liquified petroleum gas (LPG) | B6: 984.00836 | C6: 970.81419 | D6: 936.56687 | E6: 1002.9357 | F6: 909.34639 | G6: 1009.4296 | H6: 906.63195 | I6: 887.9485 | J6: 997.98565 | K6: 932.58326 | L6: 910.43032 | M6: 750.44998 | N6: 769.73271 | O6: 778.77602 | P6: 684.24452 | Q6: 703.76217 | R6: 725.13067 | S6: 736.58894 | T6: 697.56891 | U6: 708.73597 | V6: 688.36848 | W6: 746.47604 | DA6: FEC.ktoe.IT.Res.HH.Thermal.SH.LPG.LPG
A7: Diesel oil | B7: 3965.3206 | C7: 4452.169 | D7: 3909.3523 | E7: 3285.6332 | F7: 3420.8864 | G7: 3398.188 | H7: 2974.5333 | I7: 2327.9125 | J7: 2230.9988 | K7: 2167.9303 | L7: 1770.6549 | M7: 1635.7421 | N7: 1446.7963 | O7: 1370.2924 | P7: 1024.9942 | Q7: 1157.225 | R7: 1051.4031 | S7: 841.19708 | T7: 962.38655 | U7: 764.60612 | V7: 684.61865 | W7: 648.82003 | DA7: FEC.ktoe.IT.Res.HH.Thermal.SH.Oil.Oil_LiqBio
A8: Natural gas | B8: 11353.774 | C8: 12059.11 | D8: 11647.135 | E8: 13602.328 | F8: 14513.736 | G8: 15178.995 | H8: 13569.193 | I8: 12694.878 | J8: 13094.825 | K8: 13670.627 | L8: 15243.112 | M8: 14584.473 | N8: 14758.429 | O8: 14691.984 | P8: 12011.894 | Q8: 13717.083 | R8: 13765.112 | S8: 13873.146 | T8: 13168.474 | U8: 12842.44 | V8: 12639.371 | W8: 12803.468 | DA8: FEC.ktoe.IT.Res.HH.Thermal.SH.Gas.NG_Biogas
A9: Biomass | B9: 1217.9398 | C9: 1266.0091 | D9: 2054.4554 | E9: 3371.2722 | F9: 2110.4559 | G9: 3741.7892 | H9: 4450.6287 | I9: 6257.0736 | J9: 7446.5432 | K9: 7149.317 | L9: 6907.5362 | M9: 4328.416 | N9: 6368.8705 | O9: 6360.5024 | P9: 5384.7405 | Q9: 6111.8986 | R9: 5901.6203 | S9: 6459.5457 | T9: 5976.5615 | U9: 5968.1787 | V9: 5748.9512 | W9: 6505.3122 | DA9: FEC.ktoe.IT.Res.HH.Thermal.SH.Biomass.Biomass_Waste
A10: Geothermal | B10: 2.0322016 | C10: 2.0831228 | D10: 2.0716463 | E10: 2.1003847 | F10: 2.0470254 | G10: 2.0700485 | H10: 2.0546702 | I10: 2.0534343 | J10: 2.0650145 | K10: 2.0696274 | L10: 1.2026097 | M10: 1.1821086 | N10: 1.3690166 | O10: 1.2629418 | P10: 0.39610977 | Q10: 0.76542222 | R10: 0.7864142 | S10: 0.78336889 | T10: 0.87444462 | U10: 0.84421601 | V10: 0.77728306 | W10: 0.74220325 | DA10: FEC.ktoe.IT.Res.HH.Thermal.SH.Geo.Geo
A11: Distributed heat | B11: 0 | C11: 0 | D11: 0 | E11: 0 | F11: 134.62972 | G11: 138.92055 | H11: 124.49648 | I11: 115.51166 | J11: 37.785424 | K11: 45.188989 | L11: 108.00507 | M11: 490.04153 | N11: 608.8523 | O11: 816.64703 | P11: 699.95722 | Q11: 790.92403 | R11: 824.23878 | S11: 789.62647 | T11: 951.23249 | U11: 774.91717 | V11: 770.89087 | W11: 639.75821 | DA11: FEC.ktoe.IT.Res.HH.Thermal.SH.DistrHeat.Steam_Distr
A12: Advanced electric heating | B12: 3.7913411 | C12: 4.8350919 | D12: 5.70198 | E12: 7.7334628 | F12: 11.62045 | G12: 17.642573 | H12: 16.923509 | I12: 19.333026 | J12: 23.040438 | K12: 28.369876 | L12: 42.109946 | M12: 44.989876 | N12: 51.415086 | O12: 56.063325 | P12: 42.937688 | Q12: 52.294922 | R12: 53.586704 | S12: 58.224064 | T12: 54.578591 | U12: 46.20449 | V12: 41.737582 | W12: 245.86024 | DA12: FEC.ktoe.IT.Res.HH.Thermal.SH.AdvElc.Elec
A13: Conventional electric heating | B13: 360.85168 | C13: 317.8326 | D13: 340.44463 | E13: 375.20058 | F13: 372.52203 | G13: 432.14185 | H13: 351.45078 | I13: 307.42797 | J13: 334.87864 | K13: 317.37741 | L13: 376.95198 | M13: 378.45281 | N13: 354.45069 | O13: 257.831 | P13: 154.05492 | Q13: 235.37313 | R13: 235.57532 | S13: 156.58973 | T13: 158.49212 | U13: 161.10266 | V13: 149.32313 | W13: 4.8700298 | DA13: FEC.ktoe.IT.Res.HH.Thermal.SH.ConvElc.Elec
A14: Electricity in circulation | B14: 208.65392 | C14: 219.9753 | D14: 211.81203 | E14: 217.32234 | F14: 239.18854 | G14: 256.6494 | H14: 230.31346 | I14: 219.46446 | J14: 224.57548 | K14: 230.83735 | L14: 257.57137 | M14: 239.70497 | N14: 243.17578 | O14: 265.79266 | P14: 224.62436 | Q14: 233.56403 | R14: 234.37804 | S14: 238.05178 | T14: 228.75369 | U14: 226.31015 | V14: 223.09312 | W14: 224.22694 | DA14: FEC.ktoe.IT.Res.HH.Thermal.SH.TotalCirculation.Elec
A15: Space cooling | B15: =B16 -> 67.348167 | C15: =C16 -> 83.899502 | D15: =D16 -> 72.073478 | E15: =E16 -> 233.66474 | F15: =F16 -> 98.162402 | G15: =G16 -> 103.5606 | H15: =H16 -> 140.64804 | I15: =I16 -> 137.8975 | ... W15: =W16 -> 250.08816 | DA15: FEC.ktoe.IT.Res.HH.Thermal.SC
A16: Air conditioning | B16: 67.348167 | C16: 83.899502 | D16: 72.073478 | E16: 233.66474 | F16: 98.162402 | G16: 103.5606 | H16: 140.64804 | I16: 137.8975 | J16: 182.73976 | K16: 199.26098 | L16: 159.86503 | M16: 181.57302 | N16: 296.28665 | O16: 179.64448 | P16: 132.15016 | Q16: 271.00834 | R16: 188.15993 | S16: 277.90138 | T16: 214.01478 | U16: 263.64885 | V16: 206.10507 | W16: 250.08816 | DA16: FEC.ktoe.IT.Res.HH.Thermal.SC.AC.Elec
A17: Water heating | B17: =SUM(B18:B26) -> 4134.713 | C17: =SUM(C18:C26) -> 4164.271 | D17: =SUM(D18:D26) -> 4200.2306 | E17: =SUM(E18:E26) -> 4114.6411 | F17: =SUM(F18:F26) -> 4119.3311 | G17: =SUM(G18:G26) -> 4130.4139 | H17: =SUM(H18:H26) -> 4083.1051 | I17: =SUM(I18:I26) -> 3888.2437 | ... W17: =SUM(W18:W26) -> 2927.2641 | DA17: FEC.ktoe.IT.Res.HH.Thermal.WH
A18: Solids | B18: 0 | C18: 0 | D18: 0 | E18: 0 | F18: 0 | G18: 0 | H18: 0 | I18: 0 | J18: 0 | K18: 0 | L18: 0 | M18: 0 | N18: 0 | O18: 0 | P18: 0 | Q18: 0 | R18: 0 | S18: 0 | T18: 0 | U18: 0 | V18: 0 | W18: 0 | DA18: FEC.ktoe.IT.Res.HH.Thermal.WH.Solids.Solids
A19: Liquified petroleum gas (LPG) | B19: 269.8965 | C19: 274.40978 | D19: 277.05047 | E19: 280.80581 | F19: 318.37602 | G19: 287.25859 | H19: 273.44205 | I19: 238.22455 | J19: 223.38517 | K19: 224.30632 | L19: 240.78557 | M19: 268.1351 | N19: 236.85635 | O19: 212.70098 | P19: 182.16813 | Q19: 181.62573 | R19: 187.14116 | S19: 195.64393 | T19: 199.12348 | U19: 194.87265 | V19: 196.14054 | W19: 194.25628 | DA19: FEC.ktoe.IT.Res.HH.Thermal.WH.LPG.LPG
A20: Diesel oil | B20: 512.93015 | C20: 493.94731 | D20: 453.65043 | E20: 381.76903 | F20: 416.41655 | G20: 374.13925 | H20: 350.51211 | I20: 275.77528 | J20: 251.25493 | K20: 239.14434 | L20: 183.56787 | M20: 198.72813 | N20: 155.82622 | O20: 146.5939 | P20: 137.96559 | Q20: 131.87401 | R20: 119.67744 | S20: 98.473082 | T20: 121.25248 | U20: 92.740566 | V20: 86.024171 | W20: 74.49742 | DA20: FEC.ktoe.IT.Res.HH.Thermal.WH.Oil.Oil_LiqBio
A21: Natural gas | B21: 2407.3595 | C21: 2467.1154 | D21: 2433.438 | E21: 2437.9403 | F21: 2245.8526 | G21: 2338.3225 | H21: 2287.1674 | I21: 2248.0296 | J21: 2027.0691 | K21: 2192.1999 | L21: 2429.3564 | M21: 2367.6119 | N21: 2453.5836 | O21: 2429.7807 | P21: 2239.3333 | Q21: 2338.9122 | R21: 2372.9397 | S21: 2306.1409 | T21: 2271.2262 | U21: 2205.5342 | V21: 2157.0172 | W21: 1715.003 | DA21: FEC.ktoe.IT.Res.HH.Thermal.WH.Gas.NG_Biogas
A22: Biomass | B22: 52.265067 | C22: 52.501596 | D22: 89.025111 | E22: 102.94383 | F22: 112.33987 | G22: 136.66929 | H22: 173.98481 | I22: 170.12703 | J22: 181.19022 | K22: 181.15121 | L22: 201.10387 | M22: 229.94821 | N22: 227.39967 | O22: 225.73547 | P22: 240.4473 | Q22: 231.05921 | R22: 222.97077 | S22: 244.37676 | T22: 225.78112 | U22: 225.37976 | V22: 216.64978 | W22: 236.49549 | DA22: FEC.ktoe.IT.Res.HH.Thermal.WH.Biomass.Biomass_Waste
A23: Geothermal | B23: 0.28456539 | C23: 0.28145156 | D23: 0.29292809 | E23: 0.26418967 | F23: 0.2697416 | G23: 0.24671852 | H23: 0.26209678 | I23: 0.26333273 | J23: 0.25175246 | K23: 0.24713959 | L23: 0.13496552 | M23: 0.15546665 | N23: 0.15961629 | O23: 0.14625857 | P23: 0.057716541 | Q23: 0.094423006 | R23: 0.097334722 | S23: 0.097026643 | T23: 0.10956226 | U23: 0.10823455 | V23: 0.10036097 | W23: 0.09597388 | DA23: FEC.ktoe.IT.Res.HH.Thermal.WH.Geo.Geo
A24: Distributed heat | B24: 0 | C24: 0 | D24: 0 | E24: 0 | F24: 21.360563 | G24: 19.935852 | H24: 19.121577 | I24: 17.835978 | J24: 5.469606 | K24: 6.4972539 | L24: 14.594503 | M24: 77.59966 | N24: 85.472718 | O24: 113.87266 | P24: 118.42438 | Q24: 117.47855 | R24: 122.42691 | S24: 115.31592 | T24: 140.38901 | U24: 112.96563 | V24: 98.73063 | W24: 70.699317 | DA24: FEC.ktoe.IT.Res.HH.Thermal.WH.DistrHeat.Steam_Distr
A25: Electricity | B25: 883.4982 | C25: 866.58099 | D25: 935.8585 | E25: 898.40235 | F25: 990.31337 | G25: 952.56053 | H25: 951.50605 | I25: 897.31241 | J25: 878.29624 | K25: 836.83292 | L25: 830.02408 | M25: 864.97377 | N25: 764.07578 | O25: 699.00187 | P25: 691.75501 | Q25: 631.31712 | R25: 613.533 | S25: 600.74198 | T25: 586.2256 | U25: 574.70548 | V25: 534.80561 | W25: 447.25963 | DA25: FEC.ktoe.IT.Res.HH.Thermal.WH.Elc.Elec
A26: Solar | B26: 8.4790198 | C26: 9.4343938 | D26: 10.915219 | E26: 12.515563 | F26: 14.402408 | G26: 21.281169 | H26: 27.109028 | I26: 40.675494 | J26: 52.092261 | K26: 66.160275 | L26: 99.264316 | M26: 103.87412 | N26: 114.93267 | O26: 124.43869 | P26: 132.86999 | Q26: 140.53689 | R26: 148.06053 | S26: 154.49106 | T26: 161.63181 | U26: 168.6804 | V26: 180.18349 | W26: 188.95692 | DA26: FEC.ktoe.IT.Res.HH.Thermal.WH.TotalSolar.Solar
A27: Cooking | B27: =SUM(B28:B32) -> 1854.114 | C27: =SUM(C28:C32) -> 1878.5785 | D27: =SUM(D28:D32) -> 1900.5801 | E27: =SUM(E28:E32) -> 1877.7656 | F27: =SUM(F28:F32) -> 1947.4056 | G27: =SUM(G28:G32) -> 1900.5895 | H27: =SUM(H28:H32) -> 1893.9829 | I27: =SUM(I28:I32) -> 1713.5128 | ... W27: =SUM(W28:W32) -> 1595.7477 | DA27: FEC.ktoe.IT.Res.HH.Thermal.CO
A28: Solids | B28: 0 | C28: 0 | D28: 0 | E28: 0 | F28: 0 | G28: 0 | H28: 0 | I28: 0 | J28: 0 | K28: 0 | L28: 0 | M28: 0 | N28: 0 | O28: 0 | P28: 0 | Q28: 0 | R28: 0 | S28: 0 | T28: 0 | U28: 0 | V28: 0 | W28: 0 | DA28: FEC.ktoe.IT.Res.HH.Thermal.CO.Solids.Solids
A29: Liquified petroleum gas (LPG) | B29: 274.3745 | C29: 259.9829 | D29: 260.82617 | E29: 253.32734 | F29: 273.08962 | G29: 254.6637 | H29: 247.12575 | I29: 231.80915 | J29: 236.59229 | K29: 225.26382 | L29: 219.95067 | M29: 226.23194 | N29: 199.7738 | O29: 200.60289 | P29: 213.60077 | Q29: 200.1189 | R29: 206.19576 | S29: 215.5643 | T29: 219.39763 | U29: 214.71391 | V29: 216.11145 | W29: 214.03492 | DA29: FEC.ktoe.IT.Res.HH.Thermal.CO.LPG.LPG
A30: Natural gas | B30: 1213.652 | C30: 1220.1628 | D30: 1220.3083 | E30: 1232.5388 | F30: 1177.2985 | G30: 1228.4694 | H30: 1160.5573 | I30: 999.16077 | J30: 892.85234 | K30: 957.87388 | L30: 1025.1243 | M30: 1037.5542 | N30: 904.53944 | O30: 951.32207 | P30: 899.61138 | Q30: 929.55895 | R30: 959.41152 | S30: 1081.324 | T30: 1059.6902 | U30: 1078.6712 | V30: 1136.2084 | W30: 961.29899 | DA30: FEC.ktoe.IT.Res.HH.Thermal.CO.Gas.NG_Biogas
A31: Biomass | B31: 10.013881 | C31: 11.841856 | D31: 16.627449 | E31: 16.927565 | F31: 21.175746 | G31: 26.68141 | H31: 34.31449 | I31: 46.918075 | J31: 46.724312 | K31: 50.013321 | L31: 54.238502 | M31: 43.345982 | N31: 41.094899 | O31: 46.460194 | P31: 50.340054 | Q31: 50.50738 | R31: 48.739324 | S31: 53.418458 | T31: 49.353635 | U31: 49.265907 | V31: 47.3576 | W31: 51.695686 | DA31: FEC.ktoe.IT.Res.HH.Thermal.CO.Biomass.Biomass_Waste
A32: Electricity | B32: 356.07369 | C32: 386.59101 | D32: 402.81819 | E32: 374.97189 | F32: 475.84172 | G32: 390.77501 | H32: 451.98528 | I32: 435.62478 | J32: 395.85622 | K32: 387.89187 | L32: 341.92437 | M32: 328.29943 | N32: 285.75272 | O32: 329.61404 | P32: 273.47897 | Q32: 298.68855 | R32: 295.06923 | S32: 356.25512 | T32: 356.59944 | U32: 356.18839 | V32: 369.08923 | W32: 368.71813 | DA32: FEC.ktoe.IT.Res.HH.Thermal.CO.Elc.Elec

Sheet RES_hh_tes
A1: IT - Thermal energy service | B1: 2000 | C1: 2001 | D1: 2002 | E1: 2003 | F1: 2004 | G1: 2005 | H1: 2006 | I1: 2007 | J1: 2008 | K1: 2009 | L1: 2010 | M1: 2011 | N1: 2012 | O1: 2013 | P1: 2014 | Q1: 2015 | R1: 2016 | S1: 2017 | T1: 2018 | U1: 2019 | V1: 2020 | W1: 2021 | DA1: Code
A3: Thermal energy service (ktoe useful) | B3: =SUM(B4,B15,B17,B27) -> 12475.05 | C3: =SUM(C4,C15,C17,C27) -> 13258.545 | D3: =SUM(D4,D15,D17,D27) -> 13338.526 | E3: =SUM(E4,E15,E17,E27) -> 15286.808 | F3: =SUM(F4,F15,F17,F27) -> 15225.348 | G3: =SUM(G4,G15,G17,G27) -> 16767.122 | H3: =SUM(H4,H15,H17,H27) -> 16257.851 | I3: =SUM(I4,I15,I17,I27) -> 16483.838 | ... W3: =SUM(W4,W15,W17,W27) -> 20718.109 | DA3: TES.ktoe.IT.Res.HH.Thermal
A4: Space heating | B4: =SUM(B5:B14) -> 8891.3588 | C4: =SUM(C5:C14) -> 9584.1729 | D4: =SUM(D5:D14) -> 9612.513 | E4: =SUM(E5:E14) -> 11242.157 | F4: =SUM(F5:F14) -> 11367.43 | G4: =SUM(G5:G14) -> 12894.431 | H4: =SUM(H5:H14) -> 12269.609 | I4: =SUM(I5:I14) -> 12685.657 | ... W4: =SUM(W5:W14) -> 16444.793 | DA4: TES.ktoe.IT.Res.HH.Thermal.SH
A5: Solids | B5: 38.710894 | C5: 44.555425 | D5: 10.028293 | E5: 10.028345 | F5: 4.5443445 | G5: 4.1656619 | H5: 4.1656619 | I5: 3.2790781 | J5: 2.5445827 | K5: 2.1854368 | L5: 2.1624645 | M5: 2.1587726 | N5: 1.4430446 | O5: 0 | P5: 0 | Q5: 0 | R5: 0 | S5: 0 | T5: 0 | U5: 0 | V5: 0 | W5: 0 | DA5: TES.ktoe.IT.Res.HH.Thermal.SH.Solids.Solids
A6: Liquified petroleum gas (LPG) | B6: 458.4971 | C6: 454.58811 | D6: 440.29633 | E6: 473.53748 | F6: 432.17524 | G6: 485.34305 | H6: 442.67068 | I6: 441.69612 | J6: 507.15605 | K6: 483.44109 | L6: 482.27807 | M6: 408.21606 | N6: 434.16272 | O6: 456.73311 | P6: 404.12539 | Q6: 419.59981 | R6: 437.97791 | S6: 452.21897 | T6: 435.99504 | U6: 452.15248 | V6: 448.77747 | W6: 497.48238 | DA6: TES.ktoe.IT.Res.HH.Thermal.SH.LPG.LPG
A7: Diesel oil | B7: 1756.1962 | C7: 1983.7252 | D7: 1742.7865 | E7: 1465.3073 | F7: 1525.7538 | G7: 1515.9508 | H7: 1327.4538 | I7: 1039.6864 | J7: 997.45122 | K7: 988.12541 | L7: 833.56596 | M7: 814.6536 | N7: 773.34148 | O7: 796.34749 | P7: 597.59678 | Q7: 677.06156 | R7: 618.00611 | S7: 497.50968 | T7: 569.1849 | U7: 452.22671 | V7: 404.92037 | W7: 383.83499 | DA7: TES.ktoe.IT.Res.HH.Thermal.SH.Oil.Oil_LiqBio
A8: Natural gas | B8: 5639.44 | C8: 6069.2746 | D8: 5944.75 | E8: 7066.8921 | F8: 7674.6386 | G8: 8147.8568 | H8: 7377.2904 | I8: 7007.2145 | J8: 7414.9588 | K8: 7953.0506 | L8: 9109.568 | M8: 8973.2848 | N8: 9379.6442 | O8: 9620.1948 | P8: 7934.4229 | Q8: 9153.2152 | R8: 9307.7632 | S8: 9535.4701 | T8: 9203.0076 | U8: 9107.4157 | V8: 9087.3702 | W8: 9308.557 | DA8: TES.ktoe.IT.Res.HH.Thermal.SH.Gas.NG_Biogas
A9: Biomass | B9: 539.95997 | C9: 589.25727 | D9: 1022.5581 | E9: 1740.725 | F9: 1114.1038 | G9: 2051.0095 | H9: 2520.0105 | I9: 3637.2111 | J9: 4373.9797 | K9: 4234.7462 | L9: 4132.4304 | M9: 2612.2744 | N9: 3886.8563 | O9: 3931.8675 | P9: 3369.7166 | Q9: 3871.4194 | R9: 3795.8428 | S9: 4244.8948 | T9: 4012.9845 | U9: 4094.7016 | V9: 4026.3437 | W9: 4662.0662 | DA9: TES.ktoe.IT.Res.HH.Thermal.SH.Biomass.Biomass_Waste
A10: Geothermal | B10: 1.453289 | C10: 1.4957222 | D10: 1.4915118 | E10: 1.5147655 | F10: 1.4822984 | G10: 1.5068726 | H10: 1.5095162 | I10: 1.5228284 | J10: 1.5420694 | K10: 1.5549204 | L10: 0.90966378 | M10: 0.90289408 | N10: 1.0653225 | O10: 1.0021549 | P10: 0.31472934 | Q10: 0.60840126 | R10: 0.62826656 | S10: 0.63116047 | T10: 0.70978883 | U10: 0.69075183 | V10: 0.64209717 | W10: 0.61844329 | DA10: TES.ktoe.IT.Res.HH.Thermal.SH.Geo.Geo
A11: Distributed heat | B11: 0 | C11: 0 | D11: 0 | E11: 0 | F11: 102.39767 | G11: 105.66492 | H11: 94.730473 | I11: 87.893991 | J11: 28.77313 | K11: 34.541895 | L11: 82.950578 | M11: 379.32142 | N11: 473.31654 | O11: 637.47603 | P11: 547.75239 | Q11: 620.09629 | R11: 647.74018 | S11: 621.83431 | T11: 750.91692 | U11: 613.40227 | V11: 611.16826 | W11: 507.55857 | DA11: TES.ktoe.IT.Res.HH.Thermal.SH.DistrHeat.Steam_Distr
A12: Advanced electric heating | B12: 4.9354412 | C12: 6.4405468 | D12: 7.9695735 | E12: 11.456642 | F12: 18.322812 | G12: 29.357201 | H12: 29.318072 | I12: 34.967459 | J12: 43.955275 | K12: 57.713428 | L12: 91.227728 | M12: 102.46293 | N12: 121.32665 | O12: 136.37425 | P12: 106.57456 | Q12: 133.97186 | R12: 142.0066 | S12: 159.94298 | T12: 154.24248 | U12: 142.33158 | V12: 137.05108 | W12: 856.83702 | DA12: TES.ktoe.IT.Res.HH.Thermal.SH.AdvElc.Elec
A13: Conventional electric heating | B13: 243.51196 | C13: 214.86067 | D13: 230.82065 | E13: 255.37276 | F13: 254.8226 | G13: 296.92723 | H13: 242.14666 | I13: 212.72059 | J13: 233.24157 | K13: 223.20028 | L13: 268.10417 | M13: 272.08151 | N13: 257.39531 | O13: 188.85412 | P13: 112.89611 | Q13: 172.54024 | R13: 172.91256 | S13: 115.17793 | T13: 116.83529 | U13: 119.045 | V13: 110.57664 | W13: 3.6116912 | DA13: TES.ktoe.IT.Res.HH.Thermal.SH.ConvElc.Elec
A14: Electricity in circulation | B14: 208.65392 | C14: 219.9753 | D14: 211.81203 | E14: 217.32234 | F14: 239.18854 | G14: 256.6494 | H14: 230.31346 | I14: 219.46446 | J14: 224.57548 | K14: 230.83735 | L14: 257.57137 | M14: 239.70497 | N14: 243.17578 | O14: 265.79266 | P14: 224.62436 | Q14: 233.56403 | R14: 234.37804 | S14: 238.05178 | T14: 228.75369 | U14: 226.31015 | V14: 223.09312 | W14: 224.22694 | DA14: TES.ktoe.IT.Res.HH.Thermal.SH.TotalCirculation.Elec
A15: Space cooling | B15: =B16 -> 120.96505 | C15: =C16 -> 158.80842 | D15: =D16 -> 146.98625 | E15: =E16 -> 508.80959 | F15: =F16 -> 223.60477 | G15: =G16 -> 247.13827 | H15: =H16 -> 350.83109 | I15: =I16 -> 354.66496 | ... W15: =W16 -> 977.07034 | DA15: TES.ktoe.IT.Res.HH.Thermal.SC
A16: Air conditioning | B16: 120.96505 | C16: 158.80842 | D16: 146.98625 | E16: 508.80959 | F16: 223.60477 | G16: 247.13827 | H16: 350.83109 | I16: 354.66496 | J16: 481.3338 | K16: 539.55287 | L16: 445.2317 | M16: 521.28677 | N16: 876.53876 | O16: 554.15003 | P16: 419.44089 | Q16: 886.68051 | R16: 637.88688 | S16: 976.37414 | T16: 777.86357 | U16: 985.8687 | V16: 790.11705 | W16: 977.07034 | DA16: TES.ktoe.IT.Res.HH.Thermal.SC.AC.Elec
A17: Water heating | B17: =SUM(B18:B26) -> 2265.9095 | C17: =SUM(C18:C26) -> 2296.7978 | D17: =SUM(D18:D26) -> 2341.7914 | E17: =SUM(E18:E26) -> 2314.2268 | F17: =SUM(F18:F26) -> 2351.4335 | G17: =SUM(G18:G26) -> 2381.7101 | H17: =SUM(H18:H26) -> 2385.278 | I17: =SUM(I18:I26) -> 2305.5321 | ... W17: =SUM(W18:W26) -> 2210.6956 | DA17: TES.ktoe.IT.Res.HH.Thermal.WH
A18: Solids | B18: 0 | C18: 0 | D18: 0 | E18: 0 | F18: 0 | G18: 0 | H18: 0 | I18: 0 | J18: 0 | K18: 0 | L18: 0 | M18: 0 | N18: 0 | O18: 0 | P18: 0 | Q18: 0 | R18: 0 | S18: 0 | T18: 0 | U18: 0 | V18: 0 | W18: 0 | DA18: TES.ktoe.IT.Res.HH.Thermal.WH.Solids.Solids
A19: Liquified petroleum gas (LPG) | B19: 151.90211 | C19: 155.27192 | D19: 157.79853 | E19: 161.02031 | F19: 183.74658 | G19: 166.92131 | H19: 160.11723 | I19: 140.06996 | J19: 131.69584 | K19: 132.91769 | L19: 143.59776 | M19: 161.23204 | N19: 143.72172 | O19: 130.64069 | P19: 113.62371 | Q19: 115.9278 | R19: 123.63104 | S19: 134.56865 | T19: 142.00614 | U19: 143.05712 | V19: 146.92497 | W19: 147.95024 | DA19: TES.ktoe.IT.Res.HH.Thermal.WH.LPG.LPG
A20: Diesel oil | B20: 260.16132 | C20: 250.85552 | D20: 230.42679 | E20: 194.07561 | F20: 212.27206 | G20: 191.1485 | H20: 179.59226 | I20: 141.58219 | J20: 129.65968 | K20: 124.41962 | L20: 96.634373 | M20: 106.64966 | N20: 86.055209 | O20: 83.995493 | P20: 79.699949 | Q20: 77.146349 | R20: 71.258568 | S20: 60.088353 | T20: 74.227205 | U20: 57.649015 | V20: 54.260955 | W20: 47.545027 | DA20: TES.ktoe.IT.Res.HH.Thermal.WH.Oil.Oil_LiqBio
A21: Natural gas | B21: 1263.3724 | C21: 1305.3322 | D21: 1297.4766 | E21: 1311.8062 | F21: 1218.2204 | G21: 1284.6757 | H21: 1272.3772 | I21: 1271.9401 | J21: 1166.656 | K21: 1285.572 | L21: 1451.7476 | M21: 1442.7868 | N21: 1530.6415 | O21: 1548.1325 | P21: 1442.8797 | Q21: 1526.1657 | R21: 1572.3074 | S21: 1556.8975 | T21: 1562.5818 | U21: 1544.8821 | V21: 1537.6911 | W21: 1242.4515 | DA21: TES.ktoe.IT.Res.HH.Thermal.WH.Gas.NG_Biogas
A22: Biomass | B22: 24.711623 | C22: 26.186222 | D22: 47.573215 | E22: 57.306514 | F22: 64.6851 | G22: 81.050783 | H22: 105.99055 | I22: 105.67012 | J22: 115.23244 | K22: 117.23466 | L22: 132.67867 | M22: 154.88773 | N22: 156.48544 | O22: 158.21726 | P22: 170.16274 | Q22: 164.92346 | R22: 160.86159 | S22: 179.63605 | T22: 169.53087 | U22: 173.05213 | V22: 169.689 | W22: 190.34096 | DA22: TES.ktoe.IT.Res.HH.Thermal.WH.Biomass.Biomass_Waste
A23: Geothermal | B23: 0.20257742 | C23: 0.20139654 | D23: 0.21096892 | E23: 0.19133234 | F23: 0.19645276 | G23: 0.18079465 | H23: 0.1935877 | I23: 0.19627297 | J23: 0.18972061 | K23: 0.18773268 | L23: 0.10371984 | M23: 0.12056 | N23: 0.1259654 | O23: 0.11717602 | P23: 0.046436514 | Q23: 0.07601861 | R23: 0.078617857 | S23: 0.078706789 | T23: 0.089251586 | U23: 0.088536992 | V23: 0.082531162 | W23: 0.0794103 | DA23: TES.ktoe.IT.Res.HH.Thermal.WH.Geo.Geo
A24: Distributed heat | B24: 0 | C24: 0 | D24: 0 | E24: 0 | F24: 17.308877 | G24: 16.155288 | H24: 15.504865 | I24: 14.471206 | J24: 4.4386886 | K24: 5.2790786 | L24: 11.908133 | M24: 64.092764 | N24: 70.880224 | O24: 94.826371 | P24: 98.909116 | Q24: 98.317066 | R24: 102.68691 | S24: 96.896703 | T24: 118.13205 | U24: 95.245084 | V24: 83.741951 | W24: 60.130458 | DA24: TES.ktoe.IT.Res.HH.Thermal.WH.DistrHeat.Steam_Distr
A25: Electricity | B25: 557.08047 | C25: 549.51617 | D25: 597.39008 | E25: 577.31126 | F25: 640.60156 | G25: 620.29651 | H25: 624.3933 | I25: 590.92681 | J25: 579.0199 | K25: 552.48103 | L25: 548.91573 | M25: 574.31519 | N25: 510.02792 | O25: 470.25085 | P25: 470.4895 | Q25: 434.77545 | R25: 425.88597 | S25: 421.20061 | T25: 416.72126 | U25: 415.92791 | V25: 393.30012 | W25: 333.24109 | DA25: TES.ktoe.IT.Res.HH.Thermal.WH.Elc.Elec
A26: Solar | B26: 8.4790198 | C26: 9.4343938 | D26: 10.915219 | E26: 12.515563 | F26: 14.402408 | G26: 21.281169 | H26: 27.109028 | I26: 40.675494 | J26: 52.092261 | K26: 66.160275 | L26: 99.264316 | M26: 103.87412 | N26: 114.93267 | O26: 124.43869 | P26: 132.86999 | Q26: 140.53689 | R26: 148.06053 | S26: 154.49106 | T26: 161.63181 | U26: 168.6804 | V26: 180.18349 | W26: 188.95692 | DA26: TES.ktoe.IT.Res.HH.Thermal.WH.TotalSolar.Solar
A27: Cooking | B27: =SUM(B28:B32) -> 1196.8169 | C27: =SUM(C28:C32) -> 1218.7661 | D27: =SUM(D28:D32) -> 1237.235 | E27: =SUM(E28:E32) -> 1221.6148 | F27: =SUM(F28:F32) -> 1282.88 | G27: =SUM(G28:G32) -> 1243.8419 | H27: =SUM(H28:H32) -> 1252.1328 | I27: =SUM(I28:I32) -> 1137.9845 | ... W27: =SUM(W28:W32) -> 1085.5503 | DA27: TES.ktoe.IT.Res.HH.Thermal.CO
A28: Solids | B28: 0 | C28: 0 | D28: 0 | E28: 0 | F28: 0 | G28: 0 | H28: 0 | I28: 0 | J28: 0 | K28: 0 | L28: 0 | M28: 0 | N28: 0 | O28: 0 | P28: 0 | Q28: 0 | R28: 0 | S28: 0 | T28: 0 | U28: 0 | V28: 0 | W28: 0 | DA28: TES.ktoe.IT.Res.HH.Thermal.CO.Solids.Solids
A29: Liquified petroleum gas (LPG) | B29: 169.46047 | C29: 160.7888 | D29: 161.5751 | E29: 157.20146 | F29: 169.77764 | G29: 158.61329 | H29: 154.215 | I29: 144.78136 | J29: 147.79498 | K29: 140.74953 | L29: 137.46332 | M29: 141.42178 | N29: 124.90706 | O29: 125.44434 | P29: 133.58468 | Q29: 125.16091 | R29: 128.98007 | S29: 134.87667 | T29: 137.34947 | U29: 134.52349 | V29: 135.5378 | W29: 134.40963 | DA29: TES.ktoe.IT.Res.HH.Thermal.CO.LPG.LPG
A30: Natural gas | B30: 750.09662 | C30: 755.32186 | D30: 756.64322 | E30: 765.55971 | F30: 732.51534 | G30: 765.82992 | H30: 724.88053 | I30: 624.6299 | J30: 558.29796 | K30: 599.16523 | L30: 641.45117 | M30: 649.42734 | N30: 566.30664 | O30: 595.70673 | P30: 563.37414 | Q30: 582.16765 | R30: 600.98368 | S30: 677.66228 | T30: 664.6044 | U30: 677.17331 | V30: 714.10485 | W30: 604.85816 | DA30: TES.ktoe.IT.Res.HH.Thermal.CO.Gas.NG_Biogas
A31: Biomass | B31: 5.8783638 | C31: 6.9716112 | D31: 9.8142354 | E31: 10.00935 | F31: 12.540623 | G31: 15.821059 | H31: 20.36539 | I31: 27.856623 | J31: 27.746562 | K31: 29.70437 | L31: 32.218694 | M31: 25.752387 | N31: 24.419533 | O31: 27.612561 | P31: 29.922147 | Q31: 30.023936 | R31: 28.976627 | S31: 31.765459 | T31: 29.360547 | U31: 29.331311 | V31: 28.228236 | W31: 30.858946 | DA31: TES.ktoe.IT.Res.HH.Thermal.CO.Biomass.Biomass_Waste
A32: Electricity | B32: 271.38148 | C32: 295.68382 | D32: 309.20248 | E32: 288.84424 | F32: 368.04636 | G32: 303.57769 | H32: 352.67188 | I32: 340.71666 | J32: 309.91611 | K32: 304.08933 | L32: 268.51287 | M32: 258.46256 | N32: 225.6084 | O32: 261.34743 | P32: 217.80448 | Q32: 239.04322 | R32: 237.40857 | S32: 289.07158 | T32: 292.41804 | U32: 296.27931 | V32: 311.10934 | W32: 315.42351 | DA32: TES.ktoe.IT.Res.HH.Thermal.CO.Elc.Elec

Sheet RES_hh_eff
A1: IT - System efficiency indicator of total stock | B1: 2000 | C1: 2001 | D1: 2002 | E1: 2003 | F1: 2004 | G1: 2005 | H1: 2006 | I1: 2007 | J1: 2008 | K1: 2009 | L1: 2010 | M1: 2011 | N1: 2012 | O1: 2013 | P1: 2014 | Q1: 2015 | R1: 2016 | S1: 2017 | T1: 2018 | U1: 2019 | V1: 2020 | W1: 2021 | DA1: Code
A3: Ratio of energy service to energy consumption | B3: =IF(RES_hh_tes!B3=0,"",RES_hh_tes!B3/RES_hh_fec!B3) -> 0.5151263 | C3: =IF(RES_hh_tes!C3=0,"",RES_hh_tes!C3/RES_hh_fec!C3) -> 0.52005938 | D3: =IF(RES_hh_tes!D3=0,"",RES_hh_tes!D3/RES_hh_fec!D3) -> 0.52727197 | E3: =IF(RES_hh_tes!E3=0,"",RES_hh_tes!E3/RES_hh_fec!E3) -> 0.54387103 | F3: =IF(RES_hh_tes!F3=0,"",RES_hh_tes!F3/RES_hh_fec!F3) -> 0.54596672 | G3: =IF(RES_hh_tes!G3=0,"",RES_hh_tes!G3/RES_hh_fec!G3) -> 0.55305321 | H3: =IF(RES_hh_tes!H3=0,"",RES_hh_tes!H3/RES_hh_fec!H3) -> 0.56547185 | I3: =IF(RES_hh_tes!I3=0,"",RES_hh_tes!I3/RES_hh_fec!I3) -> 0.5768268 | ... W3: =IF(RES_hh_tes!W3=0,"",RES_hh_tes!W3/RES_hh_fec!W3) -> 0.77909204 | DA3: Eff.ratio.IT.Res.HH.Thermal
