Workbook

Sheet cover
B6: JRC-IDEES-2021 - Integrated Database of the European Energy System
C10: Lithuania
C15: Services and Agriculture sector
L28: Prepared by JRC C.6
L30: 45432.787
L31: v2021-1.00
B33: Legal Notice
B35: The information made available is property of the Joint Research Centre of the European Commission.
B36: Neither the European Commission nor any person acting on behalf of the Commission is responsible for the use which might be made of this information.
B38: Use conditions
B39: This work is licensed under
B40: CC BY 4.0

Sheet index
A1: LT | B1: Lithuania
B3: Click on the link to jump to the sheet
B4: =HYPERLINK("#"&CELL("address",SER_summary!$B$2),MID(CELL("filename",SER_summary!$B$2),FIND("]",CELL("filename",SER_summary!$B$2))+1,256)) -> SER_summary | D4: Services sector summary
B6: Services sector: Thermal uses
B7: =HYPERLINK("#"&CELL("address",SER_hh_num!$B$2),MID(CELL("filename",SER_hh_num!$B$2),FIND("]",CELL("filename",SER_hh_num!$B$2))+1,256)) -> SER_hh_num | D7: Number of buildings
B8: =HYPERLINK("#"&CELL("address",SER_hh_fec!$B$2),MID(CELL("filename",SER_hh_fec!$B$2),FIND("]",CELL("filename",SER_hh_fec!$B$2))+1,256)) -> SER_hh_fec | D8: Final energy consumption
B9: =HYPERLINK("#"&CELL("address",SER_hh_tes!$B$2),MID(CELL("filename",SER_hh_tes!$B$2),FIND("]",CELL("filename",SER_hh_tes!$B$2))+1,256)) -> SER_hh_tes | D9: Thermal energy service
B10: =HYPERLINK("#"&CELL("address",SER_hh_eff!$B$2),MID(CELL("filename",SER_hh_eff!$B$2),FIND("]",CELL("filename",SER_hh_eff!$B$2))+1,256)) -> SER_hh_eff | D10: System efficiency indicator of total stock
B11: =HYPERLINK("#"&CELL("address",SER_hh_emi!$B$2),MID(CELL("filename",SER_hh_emi!$B$2),FIND("]",CELL("filename",SER_hh_emi!$B$2))+1,256)) -> SER_hh_emi | D11: CO2 emissions
B12: =HYPERLINK("#"&CELL("address",SER_hh_fech!$B$2),MID(CELL("filename",SER_hh_fech!$B$2),FIND("]",CELL("filename",SER_hh_fech!$B$2))+1,256)) -> SER_hh_fech | D12: Final energy consumption per building
B13: =HYPERLINK("#"&CELL("address",SER_hh_tesh!$B$2),MID(CELL("filename",SER_hh_tesh!$B$2),FIND("]",CELL("filename",SER_hh_tesh!$B$2))+1,256)) -> SER_hh_tesh | D13: Thermal energy service per building
B14: =HYPERLINK("#"&CELL("address",SER_hh_emih!$B$2),MID(CELL("filename",SER_hh_emih!$B$2),FIND("]",CELL("filename",SER_hh_emih!$B$2))+1,256)) -> SER_hh_emih | D14: CO2 emissions per building
B15: =HYPERLINK("#"&CELL("address",SER_hh_fecs!$B$2),MID(CELL("filename",SER_hh_fecs!$B$2),FIND("]",CELL("filename",SER_hh_fecs!$B$2))+1,256)) -> SER_hh_fecs | D15: Final energy consumption per useful surface area
B16: =HYPERLINK("#"&CELL("address",SER_hh_tess!$B$2),MID(CELL("filename",SER_hh_tess!$B$2),FIND("]",CELL("filename",SER_hh_tess!$B$2))+1,256)) -> SER_hh_tess | D16: Thermal energy service per useful surface area
B17: =HYPERLINK("#"&CELL("address",SER_hh_emis!$B$2),MID(CELL("filename",SER_hh_emis!$B$2),FIND("]",CELL("filename",SER_hh_emis!$B$2))+1,256)) -> SER_hh_emis | D17: CO2 emissions per useful surface area
B19: Services sector: Thermal uses in new and renovated buildings
B20: =HYPERLINK("#"&CELL("address",SER_hh_num_in!$B$2),MID(CELL("filename",SER_hh_num_in!$B$2),FIND("]",CELL("filename",SER_hh_num_in!$B$2))+1,256)) -> SER_hh_num_in | D20: Number of new and renovated buildings
B21: =HYPERLINK("#"&CELL("address",SER_hh_fec_in!$B$2),MID(CELL("filename",SER_hh_fec_in!$B$2),FIND("]",CELL("filename",SER_hh_fec_in!$B$2))+1,256)) -> SER_hh_fec_in | D21: Final energy consumption
B22: =HYPERLINK("#"&CELL("address",SER_hh_tes_in!$B$2),MID(CELL("filename",SER_hh_tes_in!$B$2),FIND("]",CELL("filename",SER_hh_tes_in!$B$2))+1,256)) -> SER_hh_tes_in | D22: Thermal energy service
B23: =HYPERLINK("#"&CELL("address",SER_hh_eff_in!$B$2),MID(CELL("filename",SER_hh_eff_in!$B$2),FIND("]",CELL("filename",SER_hh_eff_in!$B$2))+1,256)) -> SER_hh_eff_in | D23: System efficiency indicator of total stock
B24: =HYPERLINK("#"&CELL("address",SER_hh_emi_in!$B$2),MID(CELL("filename",SER_hh_emi_in!$B$2),FIND("]",CELL("filename",SER_hh_emi_in!$B$2))+1,256)) -> SER_hh_emi_in | D24: CO2 emissions
B25: =HYPERLINK("#"&CELL("address",SER_hh_fech_in!$B$2),MID(CELL("filename",SER_hh_fech_in!$B$2),FIND("]",CELL("filename",SER_hh_fech_in!$B$2))+1,256)) -> SER_hh_fech_in | D25: Final energy consumption per building
B26: =HYPERLINK("#"&CELL("address",SER_hh_tesh_in!$B$2),MID(CELL("filename",SER_hh_tesh_in!$B$2),FIND("]",CELL("filename",SER_hh_tesh_in!$B$2))+1,256)) -> SER_hh_tesh_in | D26: Thermal energy service per building
B27: =HYPERLINK("#"&CELL("address",SER_hh_emih_in!$B$2),MID(CELL("filename",SER_hh_emih_in!$B$2),FIND("]",CELL("filename",SER_hh_emih_in!$B$2))+1,256)) -> SER_hh_emih_in | D27: CO2 emissions per building
B28: =HYPERLINK("#"&CELL("address",SER_hh_fecs_in!$B$2),MID(CELL("filename",SER_hh_fecs_in!$B$2),FIND("]",CELL("filename",SER_hh_fecs_in!$B$2))+1,256)) -> SER_hh_fecs_in | D28: Final energy consumption per useful surface area
B29: =HYPERLINK("#"&CELL("address",SER_hh_tess_in!$B$2),MID(CELL("filename",SER_hh_tess_in!$B$2),FIND("]",CELL("filename",SER_hh_tess_in!$B$2))+1,256)) -> SER_hh_tess_in | D29: Thermal energy service per useful surface area
B30: =HYPERLINK("#"&CELL("address",SER_hh_emis_in!$B$2),MID(CELL("filename",SER_hh_emis_in!$B$2),FIND("]",CELL("filename",SER_hh_emis_in!$B$2))+1,256)) -> SER_hh_emis_in | D30: CO2 emissions per useful surface area
B32: Services sector: Specific electric uses
B33: =HYPERLINK("#"&CELL("address",'SER_se-appl'!$B$2),MID(CELL("filename",'SER_se-appl'!$B$2),FIND("]",CELL("filename",'SER_se-appl'!$B$2))+1,256)) -> SER_se-appl | D33: Services / specific electric uses
B34: =HYPERLINK("#"&CELL("address",SER_VE!$B$2),MID(CELL("filename",SER_VE!$B$2),FIND("]",CELL("filename",SER_VE!$B$2))+1,256)) -> SER_VE | D34: Ventilation and others
B35: =HYPERLINK("#"&CELL("address",SER_SL!$B$2),MID(CELL("filename",SER_SL!$B$2),FIND("]",CELL("filename",SER_SL!$B$2))+1,256)) -> SER_SL | D35: Street lighting
B36: =HYPERLINK("#"&CELL("address",SER_BL!$B$2),MID(CELL("filename",SER_BL!$B$2),FIND("]",CELL("filename",SER_BL!$B$2))+1,256)) -> SER_BL | D36: Building lighting
B37: =HYPERLINK("#"&CELL("address",SER_CR!$B$2),MID(CELL("filename",SER_CR!$B$2),FIND("]",CELL("filename",SER_CR!$B$2))+1,256)) -> SER_CR | D37: Commercial refrigeration
B38: =HYPERLINK("#"&CELL("address",SER_BT!$B$2),MID(CELL("filename",SER_BT!$B$2),FIND("]",CELL("filename",SER_BT!$B$2))+1,256)) -> SER_BT | D38: Miscellaneous building technologies
B39: =HYPERLINK("#"&CELL("address",SER_IT!$B$2),MID(CELL("filename",SER_IT!$B$2),FIND("]",CELL("filename",SER_IT!$B$2))+1,256)) -> SER_IT | D39: ICT and multimedia
B41: Agriculture, forestry and fishing
B42: =HYPERLINK("#"&CELL("address",AGR!$B$2),MID(CELL("filename",AGR!$B$2),FIND("]",CELL("filename",AGR!$B$2))+1,256)) -> AGR | D42: Agriculture, forestry and fishing summary
B43: =HYPERLINK("#"&CELL("address",AGR_fec!$B$2),MID(CELL("filename",AGR_fec!$B$2),FIND("]",CELL("filename",AGR_fec!$B$2))+1,256)) -> AGR_fec | D43: detailed split of final energy consumption
B44: =HYPERLINK("#"&CELL("address",AGR_ued!$B$2),MID(CELL("filename",AGR_ued!$B$2),FIND("]",CELL("filename",AGR_ued!$B$2))+1,256)) -> AGR_ued | D44: detailed split of useful energy demand
B45: =HYPERLINK("#"&CELL("address",AGR_emi!$B$2),MID(CELL("filename",AGR_emi!$B$2),FIND("]",CELL("filename",AGR_emi!$B$2))+1,256)) -> AGR_emi | D45: detailed split of CO2 emissions

Sheet SER_summary
A1: LT - Services sector summary | B1: 2000 | C1: 2001 | D1: 2002 | E1: 2003 | F1: 2004 | G1: 2005 | H1: 2006 | I1: 2007 | J1: 2008 | K1: 2009 | L1: 2010 | M1: 2011 | N1: 2012 | O1: 2013 | P1: 2014 | Q1: 2015 | R1: 2016 | S1: 2017 | T1: 2018 | U1: 2019 | V1: 2020 | W1: 2021 | DA1: Code
A3: Population (inhabitants) | B3: 3512074 | C3: 3486998 | D3: 3454637 | E3: 3431497 | F3: 3398929 | G3: 3355220 | H3: 3289835 | I3: 3249983 | J3: 3212605 | K3: 3183856 | L3: 3141976 | M3: 3052588 | N3: 3003641 | O3: 2971905 | P3: 2943472 | Q3: 2921262 | R3: 2888558 | S3: 2847904 | T3: 2808901 | U3: 2794184 | V3: 2794090 | W3: 2795680 | DA3: Macro.number.LT.Population
A4: Gross domestic product (M€2015) | B4: 20260.324 | C4: 21582.613 | D4: 23039.485 | E4: 25473.823 | F4: 27147.349 | G4: 29246.393 | H4: 31415.119 | I4: 34904.471 | J4: 35817.011 | K4: 30502.036 | L4: 31005.696 | M4: 32878.26 | N4: 34142.209 | O4: 35354.152 | P4: 36604.727 | Q4: 37345.7 | R4: 38286.505 | S4: 39925.864 | T4: 41520.512 | U4: 43457.483 | V4: 43446.96 | W4: 46177.324 | DA4: Macro.Meuro2015.LT.GDP
A5: Value added (M€2015) | B5: 11689.376 | C5: 12456.813 | D5: 13501.978 | E5: 14673.821 | F5: 15322.368 | G5: 16450.485 | H5: 17663.439 | I5: 19844.947 | J5: 20570.464 | K5: 19053.193 | L5: 18848.636 | M5: 19226.756 | N5: 19870.527 | O5: 20971.162 | P5: 21686.428 | Q5: 22371.8 | R5: 23344.3 | S5: 24184.706 | T5: 25537.712 | U5: 26751.49 | V5: 26716.543 | W5: 28436.42 | DA5: Macro.Meuro2015.LT.VA
A6: Employment data (employees) | B6: 794050 | C6: 781210 | D6: 789560 | E6: 798200 | F6: 813210 | G6: 831660 | H6: 810420 | I6: 883550 | J6: 901680 | K6: 864750 | L6: 849050 | M6: 860100 | N6: 869500 | O6: 880720 | P6: 895850 | Q6: 906510 | R6: 945150 | S6: 939260 | T6: 954380 | U6: 970720 | V6: 968040 | W6: 971680 | DA6: Macro.number.LT.Employees
A8: Number of representative building cells | B8: 29446.326 | C8: 30758.893 | D8: 32329.096 | E8: 34700.491 | F8: 36690.252 | G8: 38912.258 | H8: 40476.339 | I8: 44681.766 | J8: 46652.674 | K8: 46561.275 | L8: 46983.491 | M8: 47951.164 | N8: 48420.48 | O8: 49023.236 | P8: 49862.069 | Q8: 50249.833 | R8: 50613.842 | S8: 51033.922 | T8: 51394.556 | U8: 51662.788 | V8: 51822.172 | W8: 51895.583 | DA8: NUM.number.LT.Ser.Bld
A9: Total services useful surface area (in 000 sqm) | B9: 26501.693 | C9: 27683.004 | D9: 29096.186 | E9: 31230.442 | F9: 33021.227 | G9: 35021.032 | H9: 36428.705 | I9: 40213.589 | J9: 41987.406 | K9: 41905.148 | L9: 42285.141 | M9: 43156.048 | N9: 43578.432 | O9: 44120.912 | P9: 44875.862 | Q9: 45224.85 | R9: 45552.458 | S9: 45930.529 | T9: 46255.1 | U9: 46496.509 | V9: 46639.955 | W9: 46706.025 | DA9: SurfaceArea.ksqm.LT.Ser.Bld
A10: Number of new and renovated buildings | C10: 1430.4074 | D10: 1692.952 | E10: 2500.4578 | F10: 2128.6432 | G10: 2368.604 | H10: 1719.7985 | I10: 4367.4558 | J10: 2149.7718 | K10: 186.57952 | L10: 608.79466 | M10: 1155.6559 | N10: 660.8057 | O10: 796.34943 | P10: 1035.2328 | Q10: 586.96905 | R10: 621.70007 | S10: 679.63803 | T10: 622.34655 | U10: 531.79432 | V10: 424.32143 | W10: 339.1656 | DA10: NUM.number.LT.Ser.BldNew
A11: New and renovated buildings useful surface area (in 000 sqm) | C11: 1287.3666 | D11: 1523.6568 | E11: 2250.412 | F11: 1915.7789 | G11: 2131.7436 | H11: 1547.8187 | I11: 3930.7102 | J11: 1934.7947 | K11: 167.92157 | L11: 547.9152 | M11: 1040.0903 | N11: 594.72513 | O11: 716.71449 | P11: 931.7095 | Q11: 528.27214 | R11: 559.53006 | S11: 611.67423 | T11: 560.11189 | U11: 478.61489 | V11: 381.88929 | W11: 305.24904 | DA11: SurfaceArea.ksqm.LT.Ser.BldNew
A13: Actual heating degree-days | B13: 3566.72 | C13: 4011.72 | D13: 3834.5 | E13: 4085.35 | F13: 4071.09 | G13: 4020.15 | H13: 3892.89 | I13: 3739.7 | J13: 3555.94 | K13: 3949.81 | L13: 4415 | M13: 3767.86 | N13: 4081.27 | O13: 3873.17 | P13: 3729.28 | Q13: 3523.32 | R13: 3829.94 | S13: 3761.5 | T13: 3687.57 | U13: 3391.36 | V13: 3305.64 | W13: 4016.22 | DA13: HDD.Celsius.LT.Actual
A14: Mean heating degree-days over period 2000- 2020 | B14: =AVERAGE($B$13:$V$13) -> 3813.9895 | C14: =AVERAGE($B$13:$V$13) -> 3813.9895 | D14: =AVERAGE($B$13:$V$13) -> 3813.9895 | E14: =AVERAGE($B$13:$V$13) -> 3813.9895 | F14: =AVERAGE($B$13:$V$13) -> 3813.9895 | G14: =AVERAGE($B$13:$V$13) -> 3813.9895 | H14: =AVERAGE($B$13:$V$13) -> 3813.9895 | I14: =AVERAGE($B$13:$V$13) -> 3813.9895 | ... W14: =AVERAGE($B$13:$V$13) -> 3813.9895 | DA14: HDD.Celsius.LT.Mean
A15: Relative heating degree-days | B15: =B13/B14 -> 0.93516775 | C15: =C13/C14 -> 1.0518435 | D15: =D13/D14 -> 1.0053777 | E15: =E13/E14 -> 1.0711487 | F15: =F13/F14 -> 1.0674099 | G15: =G13/G14 -> 1.0540538 | H15: =H13/H14 -> 1.0206871 | I15: =I13/I14 -> 0.98052183 | ... W15: =W13/W14 -> 1.0530233 | DA15: HDD.ratio.LT.Relative
A17: Indicators
A19: GDP per capita (€2015) | B19: =B4*1000000/B3 -> 5768.7635 | C19: =C4*1000000/C3 -> 6189.4539 | D19: =D4*1000000/D3 -> 6669.148 | E19: =E4*1000000/E3 -> 7423.5305 | F19: =F4*1000000/F3 -> 7987.0302 | G19: =G4*1000000/G3 -> 8716.6841 | H19: =H4*1000000/H3 -> 9549.1473 | I19: =I4*1000000/I3 -> 10739.893 | ... W19: =W4*1000000/W3 -> 16517.385
A20: Value added per employee (€2015) | B20: =B5*1000000/B6 -> 14721.209 | C20: =C5*1000000/C6 -> 15945.537 | D20: =D5*1000000/D6 -> 17100.636 | E20: =E5*1000000/E6 -> 18383.64 | F20: =F5*1000000/F6 -> 18841.834 | G20: =G5*1000000/G6 -> 19780.301 | H20: =H5*1000000/H6 -> 21795.414 | I20: =I5*1000000/I6 -> 22460.469 | ... W20: =W5*1000000/W6 -> 29265.211
A21: Value added per capita (€2015) | B21: =B5*1000000/B3 -> 3328.3399 | C21: =C5*1000000/C3 -> 3572.3603 | D21: =D5*1000000/D3 -> 3908.3637 | E21: =E5*1000000/E3 -> 4276.2156 | F21: =F5*1000000/F3 -> 4507.9988 | G21: =G5*1000000/G3 -> 4902.9528 | H21: =H5*1000000/H3 -> 5369.0958 | I21: =I5*1000000/I3 -> 6106.1695 | ... W21: =W5*1000000/W3 -> 10171.558
A22: Value added per capita relative to EU | B22: 0.22877219 | C22: 0.23930579 | D22: 0.25682652 | E22: 0.27788057 | F22: 0.28623656 | G22: 0.30514044 | H22: 0.32471074 | I22: 0.35838194 | J22: 0.37092849 | K22: 0.35463399 | L22: 0.35076465 | M22: 0.3614182 | N22: 0.38076243 | O22: 0.40460521 | P22: 0.41698454 | Q22: 0.42721168 | R22: 0.44362722 | S22: 0.4541831 | T22: 0.47619399 | U22: 0.49206675 | V22: 0.52062183 | W22: 0.5256406
A23: Representative building cell size (employees/representative building cell) | B23: =B6/B8 -> 26.966013 | C23: =C6/C8 -> 25.397858 | D23: =D6/D8 -> 24.422582 | E23: =E6/E8 -> 23.002556 | F23: =F6/F8 -> 22.164198 | G23: =G6/G8 -> 21.3727 | H23: =H6/H8 -> 20.022068 | I23: =I6/I8 -> 19.774286 | ... W23: =W6/W8 -> 18.723751
A24: Services useful surface area (in sqm/capita) | B24: =B9*1000/B3 -> 7.5458812 | C24: =C9*1000/C3 -> 7.9389217 | D24: =D9*1000/D3 -> 8.422357 | E24: =E9*1000/E3 -> 9.101113 | F24: =F9*1000/F3 -> 9.7151857 | G24: =G9*1000/G3 -> 10.437775 | H24: =H9*1000/H3 -> 11.07311 | I24: =I9*1000/I3 -> 12.373477 | ... W24: =W9*1000/W3 -> 16.706499
A25: Services useful surface area (in sqm/employee) | B25: =B9*1000/B6 -> 33.375346 | C25: =C9*1000/C6 -> 35.43606 | D25: =D9*1000/D6 -> 36.85114 | E25: =E9*1000/E6 -> 39.126086 | F25: =F9*1000/F6 -> 40.606026 | G25: =G9*1000/G6 -> 42.109795 | H25: =H9*1000/H6 -> 44.950403 | I25: =I9*1000/I6 -> 45.513654 | ... W25: =W9*1000/W6 -> 48.06729
A26: Services useful surface area (in sqm/representative building cell) | B26: =B9*1000/B8 -> 900 | C26: =C9*1000/C8 -> 900 | D26: =D9*1000/D8 -> 900 | E26: =E9*1000/E8 -> 900 | F26: =F9*1000/F8 -> 900 | G26: =G9*1000/G8 -> 900 | H26: =H9*1000/H8 -> 900 | I26: =I9*1000/I8 -> 900 | ... W26: =W9*1000/W8 -> 900
A27: New and renovated buildings useful surface area (in sqm/representative building cell) | B27: =IF(SUM(B11)=0,"",B11*1000/B10) | C27: =IF(SUM(C11)=0,"",C11*1000/C10) -> 900 | D27: =IF(SUM(D11)=0,"",D11*1000/D10) -> 900 | E27: =IF(SUM(E11)=0,"",E11*1000/E10) -> 900 | F27: =IF(SUM(F11)=0,"",F11*1000/F10) -> 900 | G27: =IF(SUM(G11)=0,"",G11*1000/G10) -> 900 | H27: =IF(SUM(H11)=0,"",H11*1000/H10) -> 900 | I27: =IF(SUM(I11)=0,"",I11*1000/I10) -> 900 | ... W27: =IF(SUM(W11)=0,"",W11*1000/W10) -> 900
A29: Energy consumption
A31: Energy consumption by fuel - Eurostat structure (ktoe) | B31: =SUM(B32:B33,B36:B37,B44:B45) -> 469.13121 | C31: =SUM(C32:C33,C36:C37,C44:C45) -> 477.73534 | D31: =SUM(D32:D33,D36:D37,D44:D45) -> 495.86071 | E31: =SUM(E32:E33,E36:E37,E44:E45) -> 522.72794 | F31: =SUM(F32:F33,F36:F37,F44:F45) -> 548.56064 | G31: =SUM(G32:G33,G36:G37,G44:G45) -> 565.3742 | H31: =SUM(H32:H33,H36:H37,H44:H45) -> 610.58325 | I31: =SUM(I32:I33,I36:I37,I44:I45) -> 632.20139 | ... W31: =SUM(W32:W33,W36:W37,W44:W45) -> 635.54262 | DA31: FEC.ktoe.LT.ES.Ser
A32: Solids | B32: 44.818401 | C32: 37.033878 | D32: 43.384007 | E32: 43.926311 | F32: 43.252365 | G32: 50.701978 | H32: 68.093293 | I32: 51.945916 | J32: 39.482717 | K32: 48.63319 | L32: 49.106965 | M32: 58.618143 | N32: 40.98693 | O32: 47.942132 | P32: 41.944626 | Q32: 31.328461 | R32: 38.243508 | S32: 39.788822 | T32: 41.187016 | U32: 34.636113 | V32: 22.883749 | W32: 27.925365 | DA32: FEC.ktoe.LT.ES.Ser.Solids
A33: Liquids | B33: =SUM(B34:B35) -> 19.891745 | C33: =SUM(C34:C35) -> 14.060619 | D33: =SUM(D34:D35) -> 15.145142 | E33: =SUM(E34:E35) -> 9.91135 | F33: =SUM(F34:F35) -> 10.143078 | G33: =SUM(G34:G35) -> 7.1135856 | H33: =SUM(H34:H35) -> 6.0917455 | I33: =SUM(I34:I35) -> 6.0306965 | ... W33: =SUM(W34:W35) -> 2.9952709
A34: Liquified petroleum gas (LPG) | B34: 0 | C34: 0 | D34: 0 | E34: 0 | F34: 0 | G34: 0 | H34: 0 | I34: 0 | J34: 0 | K34: 0 | L34: 0 | M34: 0 | N34: 0 | O34: 0 | P34: 0 | Q34: 0 | R34: 0 | S34: 0 | T34: 0 | U34: 0 | V34: 0 | W34: 0 | DA34: FEC.ktoe.LT.ES.Ser.LPG
A35: Diesel oil and other liquids (without biofuels) | B35: 19.891745 | C35: 14.060619 | D35: 15.145142 | E35: 9.91135 | F35: 10.143078 | G35: 7.1135856 | H35: 6.0917455 | I35: 6.0306965 | J35: 9.1578676 | K35: 3.0142734 | L35: 4.0360275 | M35: 5.0647463 | N35: 3.0861565 | O35: 3.0861565 | P35: 4.1148753 | Q35: 2.0473775 | R35: 2.0473775 | S35: 2.3715391 | T35: 1.7670679 | U35: 2.2751505 | V35: 2.5843508 | W35: 2.9952709 | DA35: FEC.ktoe.LT.ES.Ser.Oil
A36: Natural gas | B36: 31.104901 | C36: 33.920894 | D36: 38.478074 | E36: 40.004299 | F36: 51.913156 | G36: 50.580396 | H36: 53.826311 | I36: 71.990542 | J36: 68.615649 | K36: 62.145314 | L36: 66.401548 | M36: 60.146174 | N36: 63.263113 | O36: 63.198624 | P36: 53.8908 | Q36: 61.50043 | R36: 65.477214 | S36: 68.852966 | T36: 73.107825 | U36: 72.593895 | V36: 69.345744 | W36: 72.463371 | DA36: FEC.ktoe.LT.ES.Ser.NG
A37: Renewable energies and wastes | B37: =SUM(B38:B42) -> 40.675494 | C37: =SUM(C38:C42) -> 39.672313 | D37: =SUM(D38:D42) -> 39.743938 | E37: =SUM(E38:E42) -> 34.417627 | F37: =SUM(F38:F42) -> 31.264918 | G37: =SUM(G38:G42) -> 31.724678 | H37: =SUM(H38:H42) -> 31.270851 | I37: =SUM(I38:I42) -> 29.766122 | ... W37: =SUM(W38:W42) -> 39.508942
A38: Biomass and waste | B38: 40.675494 | C38: 39.672313 | D38: 38.9319 | E38: 33.486156 | F38: 30.954428 | G38: 31.175322 | H38: 30.649871 | I38: 29.049613 | J38: 30.682115 | K38: 29.397163 | L38: 30.037231 | M38: 32.545142 | N38: 33.505331 | O38: 35.32055 | P38: 33.863629 | Q38: 33.763285 | R38: 34.694755 | S38: 30.759587 | T38: 31.792261 | U38: 31.307911 | V38: 33.529149 | W38: 33.752794 | DA38: FEC.ktoe.LT.ES.Ser.Biomass_Waste
A39: Biogas | B39: 0 | C39: 0 | D39: 0.81203783 | E39: 0.93147034 | F39: 0.31049011 | G39: 0.54935512 | H39: 0.62098022 | I39: 0.71650903 | J39: 0.83594153 | K39: 1.2419604 | L39: 1.6718831 | M39: 1.9346518 | N39: 1.8868444 | O39: 2.1018057 | P39: 4.4663801 | Q39: 4.5619948 | R39: 5.2546002 | S39: 4.7769561 | T39: 4.8485813 | U39: 4.6813414 | V39: 4.6575236 | W39: 5.7561479 | DA39: FEC.ktoe.LT.ES.Ser.Biogas
A40: Liquid biofuels | B40: 0 | C40: 0 | D40: 0 | E40: 0 | F40: 0 | G40: 0 | H40: 0 | I40: 0 | J40: 0 | K40: 0 | L40: 0 | M40: 0 | N40: 0 | O40: 0 | P40: 0 | Q40: 0 | R40: 0 | S40: 0 | T40: 0 | U40: 0 | V40: 0 | W40: 0 | DA40: FEC.ktoe.LT.ES.Ser.LiqBio
A41: Solar | B41: 0 | C41: 0 | D41: 0 | E41: 0 | F41: 0 | G41: 0 | H41: 0 | I41: 0 | J41: 0 | K41: 0 | L41: 0 | M41: 0 | N41: 0 | O41: 0 | P41: 0 | Q41: 0 | R41: 0 | S41: 0 | T41: 0 | U41: 0 | V41: 0 | W41: 0 | DA41: FEC.ktoe.LT.ES.Ser.Solar
A42: Geothermal | B42: 0 | C42: 0 | D42: 0 | E42: 0 | F42: 0 | G42: 0 | H42: 0 | I42: 0 | J42: 0 | K42: 0 | L42: 0 | M42: 0 | N42: 0 | O42: 0 | P42: 0 | Q42: 0 | R42: 0 | S42: 0 | T42: 0 | U42: 0 | V42: 0 | W42: 0 | DA42: FEC.ktoe.LT.ES.Ser.Geo
A43: Ambient heat | B43: 0.0016571062 | C43: 0.0028301713 | D43: 0.0048326509 | E43: 0.011208038 | F43: 0.017093407 | G43: 0.026671976 | H43: 0.037014749 | I43: 0.049835138 | J43: 0.093339487 | K43: 0.11019058 | L43: 0.12988281 | M43: 0.25427627 | N43: 0.41660091 | O43: 0.60685987 | P43: 1.0137212 | Q43: 1.1413728 | R43: 1.2303781 | S43: 1.2818034 | T43: 1.3613929 | U43: 1.4092003 | V43: 1.4092003 | W43: 2.9616509 | DA43: FEC.ktoe.LT.ES.Ser.Ambient
A44: Distributed heat | B44: 167.98031 | C44: 177.72519 | D44: 174.9307 | E44: 186.29983 | F44: 189.57197 | G44: 190.86174 | H44: 204.33267 | I44: 210.90095 | J44: 178.91943 | K44: 192.27094 | L44: 205.33586 | M44: 170.63147 | N44: 199.57962 | O44: 171.1331 | P44: 169.58057 | Q44: 174.30972 | R44: 173.71264 | S44: 202.15916 | T44: 201.6098 | U44: 175.12184 | V44: 157.82941 | W44: 197.50163 | DA44: FEC.ktoe.LT.ES.Ser.Steam_Distr
A45: Electricity | B45: 164.66036 | C45: 175.32244 | D45: 184.17885 | E45: 208.16853 | F45: 222.41515 | G45: 234.39183 | H45: 246.96838 | I45: 261.56717 | J45: 281.0417 | K45: 256.24744 | L45: 245.89488 | M45: 255.63592 | N45: 269.76228 | O45: 265.95876 | P45: 272.84586 | Q45: 263.03718 | R45: 277.75121 | S45: 279.36342 | T45: 289.17664 | U45: 295.86749 | V45: 276.07337 | W45: 295.14804 | DA45: FEC.ktoe.LT.ES.Ser.Elec
A47: Energy consumption by end-uses (ktoe) | B47: =SUM(B48,B53) -> 469.13121 | C47: =SUM(C48,C53) -> 477.73534 | D47: =SUM(D48,D53) -> 495.86071 | E47: =SUM(E48,E53) -> 522.72794 | F47: =SUM(F48,F53) -> 548.56064 | G47: =SUM(G48,G53) -> 565.3742 | H47: =SUM(H48,H53) -> 610.58325 | I47: =SUM(I48,I53) -> 632.20139 | ... W47: =SUM(W48,W53) -> 635.54262 | DA47: FEC.ktoe.LT.Ser
A48: Thermal uses | B48: =SUM(B49:B52) -> 363.55794 | C48: =SUM(C49:C52) -> 364.59995 | D48: =SUM(D49:D52) -> 373.92978 | E48: =SUM(E49:E52) -> 387.86885 | F48: =SUM(F49:F52) -> 402.75788 | G48: =SUM(G49:G52) -> 408.5766 | H48: =SUM(H49:H52) -> 444.79778 | I48: =SUM(I49:I52) -> 452.2568 | ... W48: =SUM(W49:W52) -> 414.81236 | DA48: FEC.ktoe.LT.Ser.Bld.Thermal
...

Sheet SER_hh_num
A1: LT - Number of buildings | B1: 2000 | C1: 2001 | D1: 2002 | E1: 2003 | F1: 2004 | G1: 2005 | H1: 2006 | I1: 2007 | J1: 2008 | K1: 2009 | L1: 2010 | M1: 2011 | N1: 2012 | O1: 2013 | P1: 2014 | Q1: 2015 | R1: 2016 | S1: 2017 | T1: 2018 | U1: 2019 | V1: 2020 | W1: 2021 | DA1: Code
A3: Stock of buildings | B3: =B4 -> 29446.326 | C3: =C4 -> 30758.893 | D3: =D4 -> 32329.096 | E3: =E4 -> 34700.491 | F3: =F4 -> 36690.252 | G3: =G4 -> 38912.258 | H3: =H4 -> 40476.339 | I3: =I4 -> 44681.766 | ... W3: =W4 -> 51895.583 | DA3: NUM.number.LT.Ser.Bld.Thermal
A4: Space heating | B4: =SUM(B5:B14) -> 29446.326 | C4: =SUM(C5:C14) -> 30758.893 | D4: =SUM(D5:D14) -> 32329.096 | E4: =SUM(E5:E14) -> 34700.491 | F4: =SUM(F5:F14) -> 36690.252 | G4: =SUM(G5:G14) -> 38912.258 | H4: =SUM(H5:H14) -> 40476.339 | I4: =SUM(I5:I14) -> 44681.766 | ... W4: =SUM(W5:W14) -> 51895.583 | DA4: NUM.number.LT.Ser.Bld.Thermal.SH
A5: Solids | B5: 3411.8176 | C5: 3371.4869 | D5: 3673.2784 | E5: 3954.6031 | F5: 4461.3509 | G5: 5111.8978 | H5: 5459.8526 | I5: 5655.471 | J5: 5836.7352 | K5: 6213.3289 | L5: 6592.0186 | M5: 6711.9469 | N5: 6758.8188 | O5: 6738.9288 | P5: 6458.848 | Q5: 6065.2726 | R5: 5980.2118 | S5: 5851.5692 | T5: 5660.9556 | U5: 5196.9273 | V5: 4433.7508 | W5: 4085.9444 | DA5: NUM.number.LT.Ser.Bld.Thermal.SH.Solids
A6: Liquified petroleum gas (LPG) | B6: 0 | C6: 0 | D6: 0 | E6: 0 | F6: 0 | G6: 0 | H6: 0 | I6: 0 | J6: 0 | K6: 0 | L6: 0 | M6: 0 | N6: 0 | O6: 0 | P6: 0 | Q6: 0 | R6: 0 | S6: 0 | T6: 0 | U6: 0 | V6: 0 | W6: 0 | DA6: NUM.number.LT.Ser.Bld.Thermal.SH.LPG
A7: Diesel oil | B7: 1134.849 | C7: 1027.8253 | D7: 923.23566 | E7: 752.99664 | F7: 649.51367 | G7: 522.53869 | H7: 490.17854 | I7: 485.52209 | J7: 466.57638 | K7: 433.19601 | L7: 420.90558 | M7: 426.39518 | N7: 414.48034 | O7: 417.98659 | P7: 405.9043 | Q7: 335.23125 | R7: 281.39706 | S7: 247.52695 | T7: 243.94105 | U7: 279.47112 | V7: 331.66607 | W7: 345.78283 | DA7: NUM.number.LT.Ser.Bld.Thermal.SH.Oil
A8: Gas heat pumps | B8: 0 | C8: 0 | D8: 0 | E8: 0 | F8: 0 | G8: 0 | H8: 0 | I8: 0 | J8: 0 | K8: 0 | L8: 0 | M8: 0 | N8: 0 | O8: 0 | P8: 0 | Q8: 0 | R8: 0 | S8: 0 | T8: 0 | U8: 0 | V8: 0 | W8: 0 | DA8: NUM.number.LT.Ser.Bld.Thermal.SH.GasHP
A9: Conventional gas heaters | B9: 1695.784 | C9: 1922.3391 | D9: 2354.4071 | E9: 2804.2261 | F9: 3400.9811 | G9: 3895.0966 | H9: 4475.8514 | I9: 5266.4235 | J9: 5763.4659 | K9: 5955.4305 | L9: 6177.4577 | M9: 6419.0103 | N9: 6769.2197 | O9: 7358.2203 | P9: 7777.8132 | Q9: 8441.7794 | R9: 8772.0384 | S9: 9126.8071 | T9: 9643.8368 | U9: 10355.164 | V9: 10561.066 | W9: 10683.999 | DA9: NUM.number.LT.Ser.Bld.Thermal.SH.GasTH
A10: Biomass | B10: 2660.8538 | C10: 2695.6318 | D10: 2599.9023 | E10: 2448.8578 | F10: 2330.2148 | G10: 2288.3424 | H10: 2311.4934 | I10: 2445.1876 | J10: 2667.617 | K10: 2873.1016 | L10: 3056.0468 | M10: 3384.156 | N10: 3634.6743 | O10: 3972.1879 | P10: 4113.3386 | Q10: 4101.538 | R10: 3890.1056 | S10: 3544.7936 | T10: 3446.6217 | U10: 3477.4336 | V10: 3500.0345 | W10: 3508.7327 | DA10: NUM.number.LT.Ser.Bld.Thermal.SH.Biomass
A11: Geothermal | B11: 0 | C11: 0 | D11: 0 | E11: 0 | F11: 0 | G11: 0 | H11: 0 | I11: 0 | J11: 0 | K11: 0 | L11: 0 | M11: 0 | N11: 0 | O11: 0 | P11: 0 | Q11: 0 | R11: 0 | S11: 0 | T11: 0 | U11: 0 | V11: 0 | W11: 0 | DA11: NUM.number.LT.Ser.Bld.Thermal.SH.Geo
A12: Distributed heat | B12: 18109.777 | C12: 19216.465 | D12: 19873.084 | E12: 21310.902 | F12: 22124.548 | G12: 23192.17 | H12: 23589.509 | I12: 26666.888 | J12: 27882.12 | K12: 27601.763 | L12: 28051.924 | M12: 28529.591 | N12: 28278.24 | O12: 27999.573 | P12: 28588.681 | Q12: 28767.125 | R12: 29095.73 | S12: 29611.121 | T12: 29225.516 | U12: 28832.505 | V12: 29297.412 | W12: 29399.126 | DA12: NUM.number.LT.Ser.Bld.Thermal.SH.DistrHeat
A13: Advanced electric heating | B13: 1.5999375 | C13: 2.2518791 | D13: 4.2121854 | E13: 6.9390972 | F13: 10.066207 | G13: 13.994538 | H13: 19.826998 | I13: 28.491861 | J13: 40.965419 | K13: 55.644422 | L13: 77.855667 | M13: 122.19358 | N13: 190.9462 | O13: 286.77031 | P13: 396.64879 | Q13: 466.59336 | R13: 492.82094 | S13: 494.64692 | T13: 506.64659 | U13: 578.01833 | V13: 678.24904 | W13: 858.92991 | DA13: NUM.number.LT.Ser.Bld.Thermal.SH.AdvElc
A14: Conventional electric heating | B14: 2431.6451 | C14: 2522.8931 | D14: 2900.9759 | E14: 3421.9668 | F14: 3713.5774 | G14: 3888.2176 | H14: 4129.6274 | I14: 4133.7817 | J14: 3995.1936 | K14: 3428.8112 | L14: 2607.2821 | M14: 2357.8712 | N14: 2374.101 | O14: 2249.5685 | P14: 2120.8349 | Q14: 2072.2939 | R14: 2101.5383 | S14: 2157.4565 | T14: 2667.0383 | U14: 2943.2693 | V14: 3019.9937 | W14: 3013.0684 | DA14: NUM.number.LT.Ser.Bld.Thermal.SH.ConvElc
A15: Circulation, other electricity | B15: =SUM(B5:B12) -> 27013.081 | C15: =SUM(C5:C12) -> 28233.749 | D15: =SUM(D5:D12) -> 29423.908 | E15: =SUM(E5:E12) -> 31271.585 | F15: =SUM(F5:F12) -> 32966.608 | G15: =SUM(G5:G12) -> 35010.045 | H15: =SUM(H5:H12) -> 36326.885 | I15: =SUM(I5:I12) -> 40519.492 | ... W15: =SUM(W5:W12) -> 48023.585
A16: Space cooling | B16: =SUM(B17:B18) -> 1427.396 | C16: =SUM(C17:C18) -> 1586.9907 | D16: =SUM(D17:D18) -> 1785.6245 | E16: =SUM(E17:E18) -> 1999.3926 | F16: =SUM(F17:F18) -> 2239.114 | G16: =SUM(G17:G18) -> 2500.6159 | H16: =SUM(H17:H18) -> 2790.9835 | I16: =SUM(I17:I18) -> 3138.4858 | ... W16: =SUM(W17:W18) -> 5776.5763 | DA16: NUM.number.LT.Ser.Bld.Thermal.SC
A17: Gas heat pumps | B17: 0 | C17: 0 | D17: 0 | E17: 0 | F17: 0 | G17: 0 | H17: 0 | I17: 0 | J17: 0 | K17: 0 | L17: 0 | M17: 0 | N17: 0 | O17: 0 | P17: 0 | Q17: 0 | R17: 0 | S17: 0 | T17: 0 | U17: 0 | V17: 0 | W17: 0 | DA17: NUM.number.LT.Ser.Bld.Thermal.SC.GasHP
A18: Electric space cooling | B18: 1427.396 | C18: 1586.9907 | D18: 1785.6245 | E18: 1999.3926 | F18: 2239.114 | G18: 2500.6159 | H18: 2790.9835 | I18: 3138.4858 | J18: 3453.3559 | K18: 3661.2454 | L18: 3806.2275 | M18: 3975.5391 | N18: 4095.9493 | O18: 4250.2512 | P18: 4451.9628 | Q18: 4625.0074 | R18: 4835.1258 | S18: 4982.522 | T18: 5177.2592 | U18: 5378.5129 | V18: 5580.3326 | W18: 5776.5763 | DA18: NUM.number.LT.Ser.Bld.Thermal.SC.AC
A19: Hot water | B19: =SUM(B20:B26) -> 29446.326 | C19: =SUM(C20:C26) -> 30758.893 | D19: =SUM(D20:D26) -> 32329.096 | E19: =SUM(E20:E26) -> 34700.491 | F19: =SUM(F20:F26) -> 36690.252 | G19: =SUM(G20:G26) -> 38912.258 | H19: =SUM(H20:H26) -> 40476.339 | I19: =SUM(I20:I26) -> 44681.766 | ... W19: =SUM(W20:W26) -> 51895.583 | DA19: NUM.number.LT.Ser.Bld.Thermal.HW
A20: Solids | B20: 0 | C20: 0 | D20: 0 | E20: 0 | F20: 0 | G20: 0 | H20: 0 | I20: 0 | J20: 0 | K20: 0 | L20: 0 | M20: 0 | N20: 0 | O20: 0 | P20: 0 | Q20: 0 | R20: 0 | S20: 0 | T20: 0 | U20: 0 | V20: 0 | W20: 0 | DA20: NUM.number.LT.Ser.Bld.Thermal.HW.Solids
A21: Liquified petroleum gas (LPG) | B21: 0 | C21: 0 | D21: 0 | E21: 0 | F21: 0 | G21: 0 | H21: 0 | I21: 0 | J21: 0 | K21: 0 | L21: 0 | M21: 0 | N21: 0 | O21: 0 | P21: 0 | Q21: 0 | R21: 0 | S21: 0 | T21: 0 | U21: 0 | V21: 0 | W21: 0 | DA21: NUM.number.LT.Ser.Bld.Thermal.HW.LPG
A22: Diesel oil | B22: 1281.3197 | C22: 1007.5476 | D22: 849.92991 | E22: 713.75624 | F22: 683.48239 | G22: 619.51738 | H22: 588.72149 | I22: 540.85143 | J22: 496.5637 | K22: 416.27495 | L22: 351.33307 | M22: 295.70495 | N22: 261.08726 | O22: 250.88964 | P22: 248.5957 | Q22: 251.36217 | R22: 246.72754 | S22: 247.78618 | T22: 244.83236 | U22: 278.42796 | V22: 334.36373 | W22: 365.91127 | DA22: NUM.number.LT.Ser.Bld.Thermal.HW.Oil
A23: Natural gas | B23: 1159.5487 | C23: 1218.8168 | D23: 1353.9885 | E23: 1496.1277 | F23: 1700.1454 | G23: 1982.0384 | H23: 2438.023 | I23: 3085.7682 | J23: 3534.8246 | K23: 3743.1863 | L23: 3793.3401 | M23: 3821.2316 | N23: 3816.5618 | O23: 3835.179 | P23: 3861.477 | Q23: 4023.9201 | R23: 4237.5534 | S23: 4450.1658 | T23: 4770.1048 | U23: 5098.829 | V23: 5571.9466 | W23: 5674.7209 | DA23: NUM.number.LT.Ser.Bld.Thermal.HW.Gas
A24: Biomass | B24: 1124.9776 | C24: 1164.8078 | D24: 1194.161 | E24: 1237.6035 | F24: 1297.4074 | G24: 1360.177 | H24: 1423.2961 | I24: 1475.1885 | J24: 1519.725 | K24: 1555.2832 | L24: 1594.9906 | M24: 1644.5297 | N24: 1689.0027 | O24: 1731.0178 | P24: 1745.2338 | Q24: 1703.4677 | R24: 1606.9231 | S24: 1474.8362 | T24: 1431.758 | U24: 1411.7418 | V24: 1430.706 | W24: 1464.6491 | DA24: NUM.number.LT.Ser.Bld.Thermal.HW.Biomass
A25: Distributed heat | B25: 16032.853 | C25: 16876.76 | D25: 17626.457 | E25: 19308.126 | F25: 20659.641 | G25: 22011.677 | H25: 22667.93 | I25: 24991.204 | J25: 26299.059 | K25: 26552.139 | L25: 27491.442 | M25: 28679.016 | N25: 29272.44 | O25: 30319.79 | P25: 31661.237 | Q25: 32899.413 | R25: 33556.848 | S25: 33923.925 | T25: 33482.785 | U25: 32795.301 | V25: 31896.565 | W25: 31527.309 | DA25: NUM.number.LT.Ser.Bld.Thermal.HW.DistrHeat
A26: Electricity | B26: 9847.6273 | C26: 10490.961 | D26: 11304.559 | E26: 11944.877 | F26: 12349.575 | G26: 12938.848 | H26: 13358.369 | I26: 14588.754 | J26: 14802.501 | K26: 14294.392 | L26: 13752.385 | M26: 13510.682 | N26: 13381.388 | O26: 12886.36 | P26: 12345.525 | Q26: 11371.67 | R26: 10965.789 | S26: 10937.208 | T26: 11465.075 | U26: 12078.489 | V26: 12588.591 | W26: 12862.993 | DA26: NUM.number.LT.Ser.Bld.Thermal.HW.Elc
A27: Solar | B27: 0 | C27: 0 | D27: 0 | E27: 0 | F27: 0 | G27: 0 | H27: 0 | I27: 0 | J27: 0 | K27: 0 | L27: 0 | M27: 0 | N27: 0 | O27: 0 | P27: 0 | Q27: 0 | R27: 0 | S27: 0 | T27: 0 | U27: 0 | V27: 0 | W27: 0 | DA27: NUM.number.LT.Ser.Bld.Thermal.HW.Solar
A28: Solar
A29: Catering | B29: =SUM(B30:B33) -> 29446.326 | C29: =SUM(C30:C33) -> 30758.893 | D29: =SUM(D30:D33) -> 32329.096 | E29: =SUM(E30:E33) -> 34700.491 | F29: =SUM(F30:F33) -> 36690.252 | G29: =SUM(G30:G33) -> 38912.258 | H29: =SUM(H30:H33) -> 40476.339 | I29: =SUM(I30:I33) -> 44681.766 | ... W29: =SUM(W30:W33) -> 51895.583 | DA29: NUM.number.LT.Ser.Bld.Thermal.CA
A30: Liquified petroleum gas (LPG) | B30: 0 | C30: 0 | D30: 0 | E30: 0 | F30: 0 | G30: 0 | H30: 0 | I30: 0 | J30: 0 | K30: 0 | L30: 0 | M30: 0 | N30: 0 | O30: 0 | P30: 0 | Q30: 0 | R30: 0 | S30: 0 | T30: 0 | U30: 0 | V30: 0 | W30: 0 | DA30: NUM.number.LT.Ser.Bld.Thermal.CA.LPG
A31: Natural gas | B31: 6661.0198 | C31: 7197.5736 | D31: 7879.2837 | E31: 8327.6159 | F31: 8441.3457 | G31: 8975.4591 | H31: 9846.8605 | I31: 11464.669 | J31: 12538.425 | K31: 12880.972 | L31: 12429.753 | M31: 11613.242 | N31: 10370.607 | O31: 9414.7549 | P31: 8976.6771 | Q31: 9354.3934 | R31: 9603.675 | S31: 9274.5794 | T31: 8364.5846 | U31: 6624.2326 | V31: 5002.8279 | W31: 4545.795 | DA31: NUM.number.LT.Ser.Bld.Thermal.CA.Gas
A32: Biomass | B32: 0 | C32: 0 | D32: 0 | E32: 0 | F32: 0 | G32: 372.19073 | H32: 547.3892 | I32: 687.89105 | J32: 919.88573 | K32: 951.70083 | L32: 1100.9293 | M32: 1047.2984 | N32: 1052.0751 | O32: 1007.4366 | P32: 1095.3125 | Q32: 1222.4775 | R32: 1422.15 | S32: 1677.2604 | T32: 1901.4179 | U32: 2268.8885 | V32: 2619.343 | W32: 2954.7338 | DA32: NUM.number.LT.Ser.Bld.Thermal.CA.Biomass
A33: Electricity | B33: 22785.306 | C33: 23561.32 | D33: 24449.812 | E33: 26372.875 | F33: 28248.906 | G33: 29564.608 | H33: 30082.09 | I33: 32529.206 | J33: 33194.363 | K33: 32728.602 | L33: 33452.808 | M33: 35290.623 | N33: 36997.799 | O33: 38601.044 | P33: 39790.08 | Q33: 39672.962 | R33: 39588.017 | S33: 40082.082 | T33: 41128.553 | U33: 42769.667 | V33: 44200.001 | W33: 44395.054 | DA33: NUM.number.LT.Ser.Bld.Thermal.CA.Elc

Sheet SER_hh_fec
A1: LT - Final energy consumption | B1: 2000 | C1: 2001 | D1: 2002 | E1: 2003 | F1: 2004 | G1: 2005 | H1: 2006 | I1: 2007 | J1: 2008 | K1: 2009 | L1: 2010 | M1: 2011 | N1: 2012 | O1: 2013 | P1: 2014 | Q1: 2015 | R1: 2016 | S1: 2017 | T1: 2018 | U1: 2019 | V1: 2020 | W1: 2021 | DA1: Code
A3: Final energy consumption (ktoe) | B3: =SUM(B4,B16,B19,B29) -> 363.55794 | C3: =SUM(C4,C16,C19,C29) -> 364.59995 | D3: =SUM(D4,D16,D19,D29) -> 373.92978 | E3: =SUM(E4,E16,E19,E29) -> 387.86885 | F3: =SUM(F4,F16,F19,F29) -> 402.75788 | G3: =SUM(G4,G16,G19,G29) -> 408.5766 | H3: =SUM(H4,H16,H19,H29) -> 444.79778 | I3: =SUM(I4,I16,I19,I29) -> 452.2568 | ... W3: =SUM(W4,W16,W19,W29) -> 414.81236 | DA3: FEC.ktoe.LT.Ser.Bld.Thermal
A4: Space heating | B4: =SUM(B5:B15) -> 298.90577 | C4: =SUM(C5:C15) -> 298.05987 | D4: =SUM(D5:D15) -> 304.33582 | E4: =SUM(E5:E15) -> 315.14549 | F4: =SUM(F5:F15) -> 325.6978 | G4: =SUM(G5:G15) -> 326.52385 | H4: =SUM(H5:H15) -> 356.22845 | I4: =SUM(I5:I15) -> 358.03543 | ... W4: =SUM(W5:W15) -> 311.53321 | DA4: FEC.ktoe.LT.Ser.Bld.Thermal.SH
A5: Solids | B5: 44.818401 | C5: 37.033878 | D5: 43.384007 | E5: 43.926311 | F5: 43.252365 | G5: 50.701978 | H5: 68.093293 | I5: 51.945916 | J5: 39.482717 | K5: 48.63319 | L5: 49.106965 | M5: 58.618143 | N5: 40.98693 | O5: 47.942132 | P5: 41.944626 | Q5: 31.328461 | R5: 38.243508 | S5: 39.788822 | T5: 41.187016 | U5: 34.636113 | V5: 22.883749 | W5: 27.925365 | DA5: FEC.ktoe.LT.Ser.Bld.Thermal.SH.Solids.Solids
A6: Liquified petroleum gas (LPG) | B6: 0 | C6: 0 | D6: 0 | E6: 0 | F6: 0 | G6: 0 | H6: 0 | I6: 0 | J6: 0 | K6: 0 | L6: 0 | M6: 0 | N6: 0 | O6: 0 | P6: 0 | Q6: 0 | R6: 0 | S6: 0 | T6: 0 | U6: 0 | V6: 0 | W6: 0 | DA6: FEC.ktoe.LT.Ser.Bld.Thermal.SH.LPG.LPG
A7: Diesel oil | B7: 17.770031 | C7: 12.821287 | D7: 13.981719 | E7: 8.99804 | F7: 9.048947 | G7: 6.2286778 | H7: 5.1797118 | I7: 5.2098493 | J7: 8.3304366 | K7: 2.4159735 | L7: 3.4993713 | M7: 4.6169813 | N7: 2.7370072 | O7: 2.7328708 | P7: 3.7556309 | Q7: 1.6873406 | R7: 1.6912515 | S7: 1.9715201 | T7: 1.4777364 | U7: 1.9086737 | V7: 2.1666842 | W7: 2.5117831 | DA7: FEC.ktoe.LT.Ser.Bld.Thermal.SH.Oil.Oil_LiqBio
A8: Gas heat pumps | B8: 0 | C8: 0 | D8: 0 | E8: 0 | F8: 0 | G8: 0 | H8: 0 | I8: 0 | J8: 0 | K8: 0 | L8: 0 | M8: 0 | N8: 0 | O8: 0 | P8: 0 | Q8: 0 | R8: 0 | S8: 0 | T8: 0 | U8: 0 | V8: 0 | W8: 0 | DA8: FEC.ktoe.LT.Ser.Bld.Thermal.SH.GasHP.NG_Biogas
A9: Conventional gas heaters | B9: 20.919893 | C9: 23.056154 | D9: 27.018289 | E9: 28.184289 | F9: 39.908319 | G9: 38.012474 | H9: 40.355174 | I9: 53.815055 | J9: 48.947551 | K9: 43.213033 | L9: 49.028723 | M9: 43.598413 | N9: 48.332745 | O9: 50.402535 | P9: 44.799245 | Q9: 50.924807 | R9: 54.621523 | S9: 58.421961 | T9: 62.156117 | U9: 64.834334 | V9: 63.005599 | W9: 66.713613 | DA9: FEC.ktoe.LT.Ser.Bld.Thermal.SH.GasTH.NG_Biogas
A10: Biomass | B10: 38.64172 | C10: 37.917504 | D10: 37.137213 | E10: 31.618266 | F10: 29.02164 | G10: 28.511518 | H10: 27.849901 | I10: 26.329297 | J10: 27.100287 | K10: 26.557056 | L10: 26.442358 | M10: 28.901725 | N10: 30.59925 | O10: 32.377821 | P10: 30.886974 | Q10: 30.043671 | R10: 31.105563 | S10: 27.271511 | T10: 28.078126 | U10: 27.069869 | V10: 29.225866 | W10: 28.251941 | DA10: FEC.ktoe.LT.Ser.Bld.Thermal.SH.Biomass.Biomass_Waste
A11: Geothermal | B11: 0 | C11: 0 | D11: 0 | E11: 0 | F11: 0 | G11: 0 | H11: 0 | I11: 0 | J11: 0 | K11: 0 | L11: 0 | M11: 0 | N11: 0 | O11: 0 | P11: 0 | Q11: 0 | R11: 0 | S11: 0 | T11: 0 | U11: 0 | V11: 0 | W11: 0 | DA11: FEC.ktoe.LT.Ser.Bld.Thermal.SH.Geo.Geo
A12: Distributed heat | B12: 152.91526 | C12: 161.79131 | D12: 158.70176 | E12: 168.67848 | F12: 170.08784 | G12: 169.39747 | H12: 181.17214 | I12: 188.08692 | J12: 154.85962 | K12: 166.12242 | L12: 177.55218 | M12: 142.29499 | N12: 170.45011 | O12: 140.34199 | P12: 138.13289 | Q12: 140.23716 | R12: 138.94426 | S12: 166.40738 | T12: 167.04545 | U12: 141.66972 | V12: 129.26767 | W12: 165.78637 | DA12: FEC.ktoe.LT.Ser.Bld.Thermal.SH.DistrHeat.Steam_Distr
A13: Advanced electric heating | B13: 0.0063935651 | C13: 0.010398374 | D13: 0.014587031 | E13: 0.028252862 | F13: 0.037211192 | G13: 0.050660655 | H13: 0.060958136 | I13: 0.071450737 | J13: 0.11726194 | K13: 0.12385847 | L13: 0.13029503 | M13: 0.22304154 | N13: 0.32371739 | O13: 0.42513806 | P13: 0.65543528 | Q13: 0.70464007 | R13: 0.74345667 | S13: 0.76532215 | T13: 0.79771112 | U13: 0.79227415 | V13: 0.75950933 | W13: 1.5225516 | DA13: FEC.ktoe.LT.Ser.Bld.Thermal.SH.AdvElc.Elec
A14: Conventional electric heating | B14: 22.553871 | C14: 24.193266 | D14: 22.807621 | E14: 32.444372 | F14: 32.975209 | G14: 32.269093 | H14: 32.033814 | I14: 31.028648 | J14: 42.946563 | K14: 19.727561 | L14: 9.6509275 | M14: 14.20473 | N14: 19.166421 | O14: 12.149558 | P14: 12.509763 | Q14: 5.2674508 | R14: 14.593097 | S14: 8.8907347 | T14: 16.628424 | U14: 17.433296 | V14: 12.783265 | W14: 17.287841 | DA14: FEC.ktoe.LT.Ser.Bld.Thermal.SH.ConvElc.Elec
A15: Electricity in circulation and other use | B15: 1.2802021 | C15: 1.2360682 | D15: 1.2906257 | E15: 1.2674815 | F15: 1.3662657 | G15: 1.3519819 | H15: 1.4834531 | I15: 1.5482886 | J15: 1.3532337 | K15: 1.3272807 | L15: 1.4290052 | M15: 1.3316005 | N15: 1.3722721 | O15: 1.3449642 | P15: 1.2525635 | Q15: 1.2467017 | R15: 1.3223136 | S15: 1.4505958 | T15: 1.5090257 | U15: 1.4367538 | V15: 1.341889 | W15: 1.5337397 | DA15: FEC.ktoe.LT.Ser.Bld.Thermal.SH.TotalCirculation.Elec
A16: Space cooling | B16: =SUM(B17:B18) -> 1.1653528 | C16: =SUM(C17:C18) -> 1.2864018 | D16: =SUM(D17:D18) -> 1.468984 | E16: =SUM(E17:E18) -> 1.3959411 | F16: =SUM(F17:F18) -> 1.4727327 | G16: =SUM(G17:G18) -> 1.5635674 | H16: =SUM(H17:H18) -> 1.8294184 | I16: =SUM(I17:I18) -> 1.7999062 | ... W16: =SUM(W17:W18) -> 2.5695617 | DA16: FEC.ktoe.LT.Ser.Bld.Thermal.SC
A17: Gas heat pumps | B17: 0 | C17: 0 | D17: 0 | E17: 0 | F17: 0 | G17: 0 | H17: 0 | I17: 0 | J17: 0 | K17: 0 | L17: 0 | M17: 0 | N17: 0 | O17: 0 | P17: 0 | Q17: 0 | R17: 0 | S17: 0 | T17: 0 | U17: 0 | V17: 0 | W17: 0 | DA17: FEC.ktoe.LT.Ser.Bld.Thermal.SC.GasHP.NG_Biogas
A18: Electric space cooling | B18: 1.1653528 | C18: 1.2864018 | D18: 1.468984 | E18: 1.3959411 | F18: 1.4727327 | G18: 1.5635674 | H18: 1.8294184 | I18: 1.7999062 | J18: 1.8533572 | K18: 1.9351536 | L18: 2.5037096 | M18: 2.0127903 | N18: 2.2016188 | O18: 2.0526802 | P18: 2.2837077 | Q18: 2.212246 | R18: 2.108072 | S18: 2.0847476 | T18: 2.2331341 | U18: 2.2013002 | V18: 2.1547339 | W18: 2.5695617 | DA18: FEC.ktoe.LT.Ser.Bld.Thermal.SC.AC.Elec
A19: Hot water | B19: =SUM(B20:B27) -> 31.374172 | C19: =SUM(C20:C27) -> 32.535269 | D19: =SUM(D20:D27) -> 33.960272 | E19: =SUM(E20:E27) -> 35.773392 | F19: =SUM(F20:F27) -> 38.898523 | G19: =SUM(G20:G27) -> 41.763393 | H19: =SUM(H20:H27) -> 44.839948 | I19: =SUM(I20:I27) -> 47.768453 | ... W19: =SUM(W20:W27) -> 54.261988 | DA19: FEC.ktoe.LT.Ser.Bld.Thermal.HW
A20: Solids | B20: 0 | C20: 0 | D20: 0 | E20: 0 | F20: 0 | G20: 0 | H20: 0 | I20: 0 | J20: 0 | K20: 0 | L20: 0 | M20: 0 | N20: 0 | O20: 0 | P20: 0 | Q20: 0 | R20: 0 | S20: 0 | T20: 0 | U20: 0 | V20: 0 | W20: 0 | DA20: FEC.ktoe.LT.Ser.Bld.Thermal.HW.Solids.Solids
A21: Liquified petroleum gas (LPG) | B21: 0 | C21: 0 | D21: 0 | E21: 0 | F21: 0 | G21: 0 | H21: 0 | I21: 0 | J21: 0 | K21: 0 | L21: 0 | M21: 0 | N21: 0 | O21: 0 | P21: 0 | Q21: 0 | R21: 0 | S21: 0 | T21: 0 | U21: 0 | V21: 0 | W21: 0 | DA21: FEC.ktoe.LT.Ser.Bld.Thermal.HW.LPG.LPG
A22: Diesel oil | B22: 2.1217147 | C22: 1.2393319 | D22: 1.1634227 | E22: 0.91330998 | F22: 1.0941313 | G22: 0.88490775 | H22: 0.91203371 | I22: 0.82084713 | J22: 0.82743102 | K22: 0.59829991 | L22: 0.53665618 | M22: 0.44776505 | N22: 0.34914927 | O22: 0.3532857 | P22: 0.35924444 | Q22: 0.3600369 | R22: 0.35612595 | S22: 0.40001906 | T22: 0.28933149 | U22: 0.36647673 | V22: 0.41766661 | W22: 0.4834877 | DA22: FEC.ktoe.LT.Ser.Bld.Thermal.HW.Oil.Oil_LiqBio
A23: Natural gas | B23: 1.5921388 | C23: 1.6569257 | D23: 1.8299009 | E23: 1.9065625 | F23: 2.3716619 | G23: 2.4659589 | H23: 2.9148999 | I23: 4.3644941 | J23: 4.9410779 | K23: 4.9360991 | L23: 4.9923725 | M23: 5.1071842 | N23: 5.1012818 | O23: 5.1875109 | P23: 4.8915234 | Q23: 5.285076 | R23: 5.6375301 | S23: 5.6273904 | T23: 5.8502593 | U23: 5.9695574 | V23: 6.0308611 | W23: 6.3007517 | DA23: FEC.ktoe.LT.Ser.Bld.Thermal.HW.Gas.NG_Biogas
A24: Biomass | B24: 2.0337747 | C24: 1.7548092 | D24: 1.7946868 | E24: 1.8678906 | F24: 1.9327887 | G24: 2.0129877 | H24: 2.149153 | I24: 2.0694989 | J24: 2.1105475 | K24: 2.1044227 | L24: 2.1235924 | M24: 2.1721357 | N24: 2.1703971 | O24: 2.2070458 | P24: 2.2409713 | Q24: 2.2483328 | R24: 2.1179112 | S24: 1.7960732 | T24: 1.8014958 | U24: 1.663321 | V24: 1.7285622 | W24: 1.6754883 | DA24: FEC.ktoe.LT.Ser.Bld.Thermal.HW.Biomass.Biomass_Waste
A25: Distributed heat | B25: 15.065046 | C25: 15.933882 | D25: 16.228941 | E25: 17.621352 | F25: 19.484128 | G25: 21.464269 | H25: 23.160534 | I25: 22.814024 | J25: 24.059816 | K25: 26.148514 | L25: 27.783677 | M25: 28.336477 | N25: 29.12951 | O25: 30.791114 | P25: 31.447674 | Q25: 34.072559 | R25: 34.768376 | S25: 35.751774 | T25: 34.564351 | U25: 33.452119 | V25: 28.561737 | W25: 31.715259 | DA25: FEC.ktoe.LT.Ser.Bld.Thermal.HW.DistrHeat.Steam_Distr
A26: Electricity | B26: 10.561498 | C26: 11.95032 | D26: 12.943321 | E26: 13.464276 | F26: 14.015813 | G26: 14.93527 | H26: 15.703327 | I26: 17.699589 | J26: 18.338972 | K26: 16.523772 | L26: 15.795391 | M26: 16.39489 | N26: 16.630443 | O26: 15.545133 | P26: 15.810774 | Q26: 13.307054 | R26: 13.193579 | S26: 12.776962 | T26: 13.524071 | U26: 14.098277 | V26: 12.03333 | W26: 14.087001 | DA26: FEC.ktoe.LT.Ser.Bld.Thermal.HW.Elc.Elec
A27: Solar | B27: 0 | C27: 0 | D27: 0 | E27: 0 | F27: 0 | G27: 0 | H27: 0 | I27: 0 | J27: 0 | K27: 0 | L27: 0 | M27: 0 | N27: 0 | O27: 0 | P27: 0 | Q27: 0 | R27: 0 | S27: 0 | T27: 0 | U27: 0 | V27: 0 | W27: 0 | DA27: FEC.ktoe.LT.Ser.Bld.Thermal.HW.TotalSolar.Solar
A28: Solar
A29: Catering | B29: =SUM(B30:B33) -> 32.112639 | C29: =SUM(C30:C33) -> 32.718413 | D29: =SUM(D30:D33) -> 34.164705 | E29: =SUM(E30:E33) -> 35.554027 | F29: =SUM(F30:F33) -> 36.688831 | G29: =SUM(G30:G33) -> 38.725787 | H29: =SUM(H30:H33) -> 41.899967 | I29: =SUM(I30:I33) -> 44.653013 | ... W29: =SUM(W30:W33) -> 46.447606 | DA29: FEC.ktoe.LT.Ser.Bld.Thermal.CA
A30: Liquified petroleum gas (LPG) | B30: 0 | C30: 0 | D30: 0 | E30: 0 | F30: 0 | G30: 0 | H30: 0 | I30: 0 | J30: 0 | K30: 0 | L30: 0 | M30: 0 | N30: 0 | O30: 0 | P30: 0 | Q30: 0 | R30: 0 | S30: 0 | T30: 0 | U30: 0 | V30: 0 | W30: 0 | DA30: FEC.ktoe.LT.Ser.Bld.Thermal.CA.LPG
A31: Natural gas | B31: 8.5928692 | C31: 9.2078144 | D31: 10.441922 | E31: 10.844918 | F31: 9.9436646 | G31: 10.651318 | H31: 11.177218 | I31: 14.527501 | J31: 15.562962 | K31: 15.238142 | L31: 14.052336 | M31: 13.375228 | N31: 11.71593 | O31: 9.7103838 | P31: 8.6664118 | Q31: 9.8525418 | R31: 10.472761 | S31: 9.580571 | T31: 9.9500297 | U31: 6.4713454 | V31: 4.9668072 | W31: 5.2051538 | DA31: FEC.ktoe.LT.Ser.Bld.Thermal.CA.Gas.NG_Biogas
A32: Biomass | B32: 0 | C32: 0 | D32: 0 | E32: 0 | F32: 0 | G32: 0.65081685 | H32: 0.65081685 | I32: 0.65081685 | J32: 1.4712812 | K32: 0.73568358 | L32: 1.4712812 | M32: 1.4712812 | N32: 0.73568358 | O32: 0.73568358 | P32: 0.73568358 | Q32: 1.4712812 | R32: 1.4712812 | S32: 1.6920034 | T32: 1.9126397 | U32: 2.5747206 | V32: 2.5747206 | W32: 3.8253654 | DA32: FEC.ktoe.LT.Ser.Bld.Thermal.CA.Biomass.Biomass_Waste
A33: Electricity | B33: 23.51977 | C33: 23.510599 | D33: 23.722783 | E33: 24.709109 | F33: 26.745167 | G33: 27.423652 | H33: 30.071932 | I33: 29.474694 | J33: 28.413247 | K33: 28.688969 | L33: 28.403884 | M33: 28.938695 | N33: 32.348878 | O33: 32.486909 | P33: 33.375676 | Q33: 29.55034 | R33: 30.799319 | S33: 29.743834 | T33: 31.071346 | U33: 34.654351 | V33: 32.784154 | W33: 37.417087 | DA33: FEC.ktoe.LT.Ser.Bld.Thermal.CA.Elc.Elec

Sheet SER_hh_tes
A1: LT - Thermal energy service | B1: 2000 | C1: 2001 | D1: 2002 | E1: 2003 | F1: 2004 | G1: 2005 | H1: 2006 | I1: 2007 | J1: 2008 | K1: 2009 | L1: 2010 | M1: 2011 | N1: 2012 | O1: 2013 | P1: 2014 | Q1: 2015 | R1: 2016 | S1: 2017 | T1: 2018 | U1: 2019 | V1: 2020 | W1: 2021 | DA1: Code
A3: Thermal energy service (ktoe useful) | B3: =SUM(B4,B16,B19,B29) -> 225.93313 | C3: =SUM(C4,C16,C19,C29) -> 231.33359 | D3: =SUM(D4,D16,D19,D29) -> 237.57271 | E3: =SUM(E4,E16,E19,E29) -> 251.76069 | F3: =SUM(F4,F16,F19,F29) -> 263.3197 | G3: =SUM(G4,G16,G19,G29) -> 269.70784 | H3: =SUM(H4,H16,H19,H29) -> 295.70545 | I3: =SUM(I4,I16,I19,I29) -> 303.94212 | ... W3: =SUM(W4,W16,W19,W29) -> 324.11683 | DA3: TES.ktoe.LT.Ser.Bld.Thermal
A4: Space heating | B4: =SUM(B5:B15) -> 181.92343 | C4: =SUM(C5:C15) -> 185.48942 | D4: =SUM(D5:D15) -> 189.26395 | E4: =SUM(E5:E15) -> 200.98697 | F4: =SUM(F5:F15) -> 208.91141 | G4: =SUM(G5:G15) -> 211.35026 | H4: =SUM(H5:H15) -> 231.85768 | I4: =SUM(I5:I15) -> 236.43297 | ... W4: =SUM(W5:W15) -> 234.18651 | DA4: TES.ktoe.LT.Ser.Bld.Thermal.SH
A5: Solids | B5: 21.939276 | C5: 18.287317 | D5: 21.88943 | E5: 22.605957 | F5: 22.808449 | G5: 27.396865 | H5: 37.419471 | I5: 28.951088 | J5: 22.324563 | K5: 27.996338 | L5: 28.773066 | M5: 34.8593 | N5: 24.750157 | O5: 29.347368 | P5: 25.730389 | Q5: 19.266534 | R5: 23.725612 | S5: 24.984478 | T5: 26.233126 | U5: 22.295208 | V5: 14.852925 | W5: 18.341917 | DA5: TES.ktoe.LT.Ser.Bld.Thermal.SH.Solids.Solids
A6: Liquified petroleum gas (LPG) | B6: 0 | C6: 0 | D6: 0 | E6: 0 | F6: 0 | G6: 0 | H6: 0 | I6: 0 | J6: 0 | K6: 0 | L6: 0 | M6: 0 | N6: 0 | O6: 0 | P6: 0 | Q6: 0 | R6: 0 | S6: 0 | T6: 0 | U6: 0 | V6: 0 | W6: 0 | DA6: TES.ktoe.LT.Ser.Bld.Thermal.SH.LPG.LPG
A7: Diesel oil | B7: 7.5291032 | C7: 5.4323369 | D7: 5.9240081 | E7: 3.8124397 | F7: 3.8340089 | G7: 2.6390702 | H7: 2.1946267 | I7: 2.2073959 | J7: 3.5907581 | K7: 1.0725439 | L7: 1.6251849 | M7: 2.275673 | N7: 1.4416943 | O7: 1.5432692 | P7: 2.1214131 | Q7: 0.953183 | R7: 0.9553923 | S7: 1.1137167 | T7: 0.83477709 | U7: 1.1048661 | V7: 1.2900112 | W7: 1.5094907 | DA7: TES.ktoe.LT.Ser.Bld.Thermal.SH.Oil.Oil_LiqBio
A8: Gas heat pumps | B8: 0 | C8: 0 | D8: 0 | E8: 0 | F8: 0 | G8: 0 | H8: 0 | I8: 0 | J8: 0 | K8: 0 | L8: 0 | M8: 0 | N8: 0 | O8: 0 | P8: 0 | Q8: 0 | R8: 0 | S8: 0 | T8: 0 | U8: 0 | V8: 0 | W8: 0 | DA8: TES.ktoe.LT.Ser.Bld.Thermal.SH.GasHP.NG_Biogas
A9: Conventional gas heaters | B9: 9.7430768 | C9: 11.061608 | D9: 13.443071 | E9: 14.432865 | F9: 20.999175 | G9: 20.399361 | H9: 22.064462 | I9: 29.980406 | J9: 27.632253 | K9: 24.635968 | L9: 28.251811 | M9: 25.418992 | N9: 28.589309 | O9: 30.339195 | P9: 27.274964 | Q9: 31.528022 | R9: 34.298436 | S9: 37.292248 | T9: 40.389876 | U9: 42.884527 | V9: 42.221952 | W9: 45.217922 | DA9: TES.ktoe.LT.Ser.Bld.Thermal.SH.GasTH.NG_Biogas
A10: Biomass | B10: 16.162493 | C10: 16.112822 | D10: 15.912176 | E10: 13.624266 | F10: 12.611216 | G10: 12.562877 | H10: 12.494432 | I10: 12.078794 | J10: 12.727719 | K10: 12.732311 | L10: 12.906256 | M10: 14.353481 | N10: 15.418488 | O10: 16.487489 | P10: 15.731003 | Q10: 15.303606 | R10: 15.846016 | S10: 13.894518 | T10: 14.306654 | U10: 13.798 | V10: 14.903878 | W10: 14.414968 | DA10: TES.ktoe.LT.Ser.Bld.Thermal.SH.Biomass.Biomass_Waste
A11: Geothermal | B11: 0 | C11: 0 | D11: 0 | E11: 0 | F11: 0 | G11: 0 | H11: 0 | I11: 0 | J11: 0 | K11: 0 | L11: 0 | M11: 0 | N11: 0 | O11: 0 | P11: 0 | Q11: 0 | R11: 0 | S11: 0 | T11: 0 | U11: 0 | V11: 0 | W11: 0 | DA11: TES.ktoe.LT.Ser.Bld.Thermal.SH.Geo.Geo
A12: Distributed heat | B12: 110.74816 | C12: 117.68662 | D12: 115.8626 | E12: 123.73954 | F12: 125.26346 | G12: 125.29163 | H12: 134.4856 | I12: 140.51182 | J12: 116.19572 | K12: 125.06136 | L12: 134.25467 | M12: 108.12599 | N12: 130.17661 | O12: 107.75092 | P12: 106.43888 | Q12: 108.53237 | R12: 108.18845 | S12: 130.6347 | T12: 132.02976 | U12: 112.81247 | V12: 103.87288 | W12: 134.37309 | DA12: TES.ktoe.LT.Ser.Bld.Thermal.SH.DistrHeat.Steam_Distr
A13: Advanced electric heating | B13: 0.0080506713 | C13: 0.013228545 | D13: 0.019419682 | E13: 0.0394609 | F13: 0.054304599 | G13: 0.077332631 | H13: 0.097972884 | I13: 0.12128587 | J13: 0.21060143 | K13: 0.23404905 | L13: 0.26017784 | M13: 0.47731781 | N13: 0.74031829 | O13: 1.0319979 | P13: 1.6691565 | Q13: 1.8460129 | R13: 1.9738348 | S13: 2.0471256 | T13: 2.1591041 | U13: 2.2014745 | V13: 2.1687097 | W13: 4.4842025 | DA13: TES.ktoe.LT.Ser.Bld.Thermal.SH.AdvElc.Elec
A14: Conventional electric heating | B14: 14.513068 | C14: 15.65942 | D14: 14.922621 | E14: 21.464962 | F14: 21.97454 | G14: 21.631143 | H14: 21.617664 | I14: 21.033897 | J14: 29.215901 | K14: 13.458169 | L14: 6.5996488 | M14: 9.7329672 | N14: 13.270021 | O14: 8.4657313 | P14: 8.7217729 | Q14: 3.6893713 | R14: 10.402396 | S14: 6.5188983 | T14: 12.83316 | U14: 13.922404 | V14: 10.427246 | W14: 14.31118 | DA14: TES.ktoe.LT.Ser.Bld.Thermal.SH.ConvElc.Elec
A15: Electricity in circulation and other use | B15: 1.2802021 | C15: 1.2360682 | D15: 1.2906257 | E15: 1.2674815 | F15: 1.3662657 | G15: 1.3519819 | H15: 1.4834531 | I15: 1.5482886 | J15: 1.3532337 | K15: 1.3272807 | L15: 1.4290052 | M15: 1.3316005 | N15: 1.3722721 | O15: 1.3449642 | P15: 1.2525635 | Q15: 1.2467017 | R15: 1.3223136 | S15: 1.4505958 | T15: 1.5090257 | U15: 1.4367538 | V15: 1.341889 | W15: 1.5337397 | DA15: TES.ktoe.LT.Ser.Bld.Thermal.SH.TotalCirculation.Elec
A16: Space cooling | B16: =SUM(B17:B18) -> 2.2966788 | C16: =SUM(C17:C18) -> 2.679321 | D16: =SUM(D17:D18) -> 3.2400312 | E16: =SUM(E17:E18) -> 3.2536244 | F16: =SUM(F17:F18) -> 3.6234636 | G16: =SUM(G17:G18) -> 4.0552215 | H16: =SUM(H17:H18) -> 4.9987414 | I16: =SUM(I17:I18) -> 5.1860293 | ... W16: =SUM(W17:W18) -> 11.671754 | DA16: TES.ktoe.LT.Ser.Bld.Thermal.SC
A17: Gas heat pumps | B17: 0 | C17: 0 | D17: 0 | E17: 0 | F17: 0 | G17: 0 | H17: 0 | I17: 0 | J17: 0 | K17: 0 | L17: 0 | M17: 0 | N17: 0 | O17: 0 | P17: 0 | Q17: 0 | R17: 0 | S17: 0 | T17: 0 | U17: 0 | V17: 0 | W17: 0 | DA17: TES.ktoe.LT.Ser.Bld.Thermal.SC.GasHP.NG_Biogas
A18: Electric space cooling | B18: 2.2966788 | C18: 2.679321 | D18: 3.2400312 | E18: 3.2536244 | F18: 3.6234636 | G18: 4.0552215 | H18: 4.9987414 | I18: 5.1860293 | J18: 5.622984 | K18: 5.9746772 | L18: 7.8988728 | M18: 6.5515615 | N18: 7.3959768 | O18: 7.1417318 | P18: 8.2645332 | Q18: 8.3322574 | R18: 8.2672296 | S18: 8.4791328 | T18: 9.3857905 | U18: 9.5058336 | V18: 9.5495783 | W18: 11.671754 | DA18: TES.ktoe.LT.Ser.Bld.Thermal.SC.AC.Elec
A19: Hot water | B19: =SUM(B20:B27) -> 19.787166 | C19: =SUM(C20:C27) -> 20.847708 | D19: =SUM(D20:D27) -> 21.844898 | E19: =SUM(E20:E27) -> 23.273087 | F19: =SUM(F20:F27) -> 25.47338 | G19: =SUM(G20:G27) -> 27.648463 | H19: =SUM(H20:H27) -> 29.861249 | I19: =SUM(I20:I27) -> 31.774468 | ... W19: =SUM(W20:W27) -> 42.559245 | DA19: TES.ktoe.LT.Ser.Bld.Thermal.HW
A20: Solids | B20: 0 | C20: 0 | D20: 0 | E20: 0 | F20: 0 | G20: 0 | H20: 0 | I20: 0 | J20: 0 | K20: 0 | L20: 0 | M20: 0 | N20: 0 | O20: 0 | P20: 0 | Q20: 0 | R20: 0 | S20: 0 | T20: 0 | U20: 0 | V20: 0 | W20: 0 | DA20: TES.ktoe.LT.Ser.Bld.Thermal.HW.Solids.Solids
A21: Liquified petroleum gas (LPG) | B21: 0 | C21: 0 | D21: 0 | E21: 0 | F21: 0 | G21: 0 | H21: 0 | I21: 0 | J21: 0 | K21: 0 | L21: 0 | M21: 0 | N21: 0 | O21: 0 | P21: 0 | Q21: 0 | R21: 0 | S21: 0 | T21: 0 | U21: 0 | V21: 0 | W21: 0 | DA21: TES.ktoe.LT.Ser.Bld.Thermal.HW.LPG.LPG
A22: Diesel oil | B22: 1.0014097 | C22: 0.58494152 | D22: 0.54911376 | E22: 0.43106524 | F22: 0.51640952 | G22: 0.41765992 | H22: 0.43046286 | I22: 0.3874245 | J22: 0.39147808 | K22: 0.28435052 | L22: 0.25785775 | M22: 0.21983023 | N22: 0.17949254 | O22: 0.19404524 | P22: 0.19737047 | Q22: 0.19843748 | R22: 0.19639547 | S22: 0.22179855 | T22: 0.16129765 | U22: 0.21297522 | V22: 0.25576272 | W22: 0.30576013 | DA22: TES.ktoe.LT.Ser.Bld.Thermal.HW.Oil.Oil_LiqBio
A23: Natural gas | B23: 0.76770938 | C23: 0.8086667 | D23: 0.90866677 | E23: 0.96251503 | F23: 1.2194731 | G23: 1.2927036 | H23: 1.5612679 | I23: 2.3873337 | J23: 2.7409235 | K23: 2.7649843 | L23: 2.8181529 | M23: 2.9081497 | N23: 2.9343107 | O23: 3.0215968 | P23: 2.8776389 | Q23: 3.1731334 | R23: 3.4749812 | S23: 3.5744688 | T23: 3.849555 | U23: 4.0668894 | V23: 4.2629226 | W23: 4.5742642 | DA23: TES.ktoe.LT.Ser.Bld.Thermal.HW.Gas.NG_Biogas
A24: Biomass | B24: 0.86303187 | C24: 0.76216563 | D24: 0.79712075 | E24: 0.85109075 | F24: 0.90607943 | G24: 0.97139001 | H24: 1.0677301 | I24: 1.057422 | J24: 1.1091022 | K24: 1.1377525 | L24: 1.183309 | M24: 1.2502026 | N24: 1.2917281 | O24: 1.3529472 | P24: 1.3847224 | Q24: 1.3993355 | R24: 1.3273911 | S24: 1.1352901 | T24: 1.1571407 | U24: 1.0889786 | V24: 1.1573924 | W24: 1.1472006 | DA24: TES.ktoe.LT.Ser.Bld.Thermal.HW.Biomass.Biomass_Waste
A25: Distributed heat | B25: 10.87365 | C25: 11.548889 | D25: 11.810923 | E25: 12.896288 | F25: 14.328976 | G25: 15.860597 | H25: 17.181346 | I25: 17.024069 | J25: 18.037229 | K25: 19.67777 | L25: 21.010064 | M25: 21.548029 | N25: 22.278753 | O25: 23.706492 | P25: 24.327822 | Q25: 26.516583 | R25: 27.23121 | S25: 28.213758 | T25: 27.461619 | U25: 26.767614 | V25: 23.01259 | W25: 25.764659 | DA25: TES.ktoe.LT.Ser.Bld.Thermal.HW.DistrHeat.Steam_Distr
A26: Electricity | B26: 6.2813653 | C26: 7.1430453 | D26: 7.7790737 | E26: 8.1321285 | F26: 8.5024422 | G26: 9.1061128 | H26: 9.6204417 | I26: 10.918219 | J26: 11.365321 | K26: 10.27576 | L26: 9.8629364 | M26: 10.302666 | N26: 10.547194 | O26: 9.9471212 | P26: 10.150458 | Q26: 8.5603575 | R26: 8.5960081 | S26: 8.5496985 | T26: 9.3834506 | U26: 10.13571 | V26: 8.9358338 | W26: 10.767361 | DA26: TES.ktoe.LT.Ser.Bld.Thermal.HW.Elc.Elec
A27: Solar | B27: 0 | C27: 0 | D27: 0 | E27: 0 | F27: 0 | G27: 0 | H27: 0 | I27: 0 | J27: 0 | K27: 0 | L27: 0 | M27: 0 | N27: 0 | O27: 0 | P27: 0 | Q27: 0 | R27: 0 | S27: 0 | T27: 0 | U27: 0 | V27: 0 | W27: 0 | DA27: TES.ktoe.LT.Ser.Bld.Thermal.HW.TotalSolar.Solar
A28: Solar
A29: Catering | B29: =SUM(B30:B33) -> 21.925854 | C29: =SUM(C30:C33) -> 22.317132 | D29: =SUM(D30:D33) -> 23.223825 | E29: =SUM(E30:E33) -> 24.247004 | F29: =SUM(F30:F33) -> 25.311444 | G29: =SUM(G30:G33) -> 26.653902 | H29: =SUM(H30:H33) -> 28.987782 | I29: =SUM(I30:I33) -> 30.548648 | ... W29: =SUM(W30:W33) -> 35.699322 | DA29: TES.ktoe.LT.Ser.Bld.Thermal.CA
A30: Liquified petroleum gas (LPG) | B30: 0 | C30: 0 | D30: 0 | E30: 0 | F30: 0 | G30: 0 | H30: 0 | I30: 0 | J30: 0 | K30: 0 | L30: 0 | M30: 0 | N30: 0 | O30: 0 | P30: 0 | Q30: 0 | R30: 0 | S30: 0 | T30: 0 | U30: 0 | V30: 0 | W30: 0 | DA30: TES.ktoe.LT.Ser.Bld.Thermal.CA.LPG
A31: Natural gas | B31: 4.7967348 | C31: 5.1507353 | D31: 5.854721 | E31: 6.0930764 | F31: 5.596326 | G31: 6.0090283 | H31: 6.3233697 | I31: 8.2459216 | J31: 8.8568347 | K31: 8.6911141 | L31: 8.0253764 | M31: 7.6414999 | N31: 6.6970177 | O31: 5.5551999 | P31: 4.9647722 | Q31: 5.6532255 | R31: 6.0226101 | S31: 5.5258795 | T31: 5.7554554 | U31: 3.7492379 | V31: 2.8808736 | W31: 3.021101 | DA31: TES.ktoe.LT.Ser.Bld.Thermal.CA.Gas.NG_Biogas
A32: Biomass | B32: 0 | C32: 0 | D32: 0 | E32: 0 | F32: 0 | G32: 0.36864708 | H32: 0.36872304 | I32: 0.36880468 | J32: 0.8340608 | K32: 0.41708871 | L32: 0.83441315 | M32: 0.83443301 | N32: 0.4172807 | O32: 0.41732034 | P32: 0.41747781 | Q32: 0.83525435 | R32: 0.83601345 | S32: 0.9630327 | T32: 1.0903533 | U32: 1.4711299 | V32: 1.4743694 | W32: 2.1947903 | DA32: TES.ktoe.LT.Ser.Bld.Thermal.CA.Biomass.Biomass_Waste
A33: Electricity | B33: 17.129119 | C33: 17.166397 | D33: 17.369104 | E33: 18.153927 | F33: 19.715118 | G33: 20.276227 | H33: 22.29569 | I33: 21.933922 | J33: 21.210028 | K33: 21.482434 | L33: 21.330156 | M33: 21.775787 | N33: 24.409997 | O33: 24.61254 | P33: 25.403241 | Q33: 22.601319 | R33: 23.699699 | S33: 23.075589 | T33: 24.365005 | U33: 27.547059 | V33: 26.402502 | W33: 30.483431 | DA33: TES.ktoe.LT.Ser.Bld.Thermal.CA.Elc.Elec

Sheet SER_hh_eff
A1: LT - System efficiency indicator of total stock | B1: 2000 | C1: 2001 | D1: 2002 | E1: 2003 | F1: 2004 | G1: 2005 | H1: 2006 | I1: 2007 | J1: 2008 | K1: 2009 | L1: 2010 | M1: 2011 | N1: 2012 | O1: 2013 | P1: 2014 | Q1: 2015 | R1: 2016 | S1: 2017 | T1: 2018 | U1: 2019 | V1: 2020 | W1: 2021 | DA1: Code
A3: Ratio of energy service to energy consumption | B3: =IF(SER_hh_tes!B3=0,"",SER_hh_tes!B3/SER_hh_fec!B3) -> 0.62145012 | C3: =IF(SER_hh_tes!C3=0,"",SER_hh_tes!C3/SER_hh_fec!C3) -> 0.63448606 | D3: =IF(SER_hh_tes!D3=0,"",SER_hh_tes!D3/SER_hh_fec!D3) -> 0.63534044 | E3: =IF(SER_hh_tes!E3=0,"",SER_hh_tes!E3/SER_hh_fec!E3) -> 0.64908716 | F3: =IF(SER_hh_tes!F3=0,"",SER_hh_tes!F3/SER_hh_fec!F3) -> 0.65379155 | G3: =IF(SER_hh_tes!G3=0,"",SER_hh_tes!G3/SER_hh_fec!G3) -> 0.66011574 | H3: =IF(SER_hh_tes!H3=0,"",SER_hh_tes!H3/SER_hh_fec!H3) -> 0.66480874 | I3: =IF(SER_hh_tes!I3=0,"",SER_hh_tes!I3/SER_hh_fec!I3) -> 0.67205649 | ... W3: =IF(SER_hh_tes!W3=0,"",SER_hh_tes!W3/SER_hh_fec!W3) -> 0.78135768 | DA3: Eff.ratio.LT.Ser.Bld.Thermal
A4: Space heating | B4: =IF(SER_hh_tes!B4=0,"",SER_hh_tes!B4/SER_hh_fec!B4) -> 0.60863136 | C4: =IF(SER_hh_tes!C4=0,"",SER_hh_tes!C4/SER_hh_fec!C4) -> 0.62232271 | D4: =IF(SER_hh_tes!D4=0,"",SER_hh_tes!D4/SER_hh_fec!D4) -> 0.62189182 | E4: =IF(SER_hh_tes!E4=0,"",SER_hh_tes!E4/SER_hh_fec!E4) -> 0.63775933 | F4: =IF(SER_hh_tes!F4=0,"",SER_hh_tes!F4/SER_hh_fec!F4) -> 0.64142717 | G4: =IF(SER_hh_tes!G4=0,"",SER_hh_tes!G4/SER_hh_fec!G4) -> 0.64727356 | H4: =IF(SER_hh_tes!H4=0,"",SER_hh_tes!H4/SER_hh_fec!H4) -> 0.65086795 | I4: =IF(SER_hh_tes!I4=0,"",SER_hh_tes!I4/SER_hh_fec!I4) -> 0.66036195 | ... W4: =IF(SER_hh_tes!W4=0,"",SER_hh_tes!W4/SER_hh_fec!W4) -> 0.75172245 | DA4: Eff.ratio.LT.Ser.Bld.Thermal.SH
A5: Solids | B5: =IF(SER_hh_tes!B5=0,"",SER_hh_tes!B5/SER_hh_fec!B5) -> 0.48951493 | C5: =IF(SER_hh_tes!C5=0,"",SER_hh_tes!C5/SER_hh_fec!C5) -> 0.49379969 | D5: =IF(SER_hh_tes!D5=0,"",SER_hh_tes!D5/SER_hh_fec!D5) -> 0.50455067 | E5: =IF(SER_hh_tes!E5=0,"",SER_hh_tes!E5/SER_hh_fec!E5) -> 0.51463362 | F5: =IF(SER_hh_tes!F5=0,"",SER_hh_tes!F5/SER_hh_fec!F5) -> 0.52733416 | G5: =IF(SER_hh_tes!G5=0,"",SER_hh_tes!G5/SER_hh_fec!G5) -> 0.54035101 | H5: =IF(SER_hh_tes!H5=0,"",SER_hh_tes!H5/SER_hh_fec!H5) -> 0.54953241 | I5: =IF(SER_hh_tes!I5=0,"",SER_hh_tes!I5/SER_hh_fec!I5) -> 0.55733137 | ... W5: =IF(SER_hh_tes!W5=0,"",SER_hh_tes!W5/SER_hh_fec!W5) -> 0.65681922 | DA5: Eff.ratio.LT.Ser.Bld.Thermal.SH.Solids.Solids
